Workbook

Sheet Model
B1: SuperRegion | C1: AT | P1: World_but_AT | AC1: AT | AJ1: World_but_AT | AU1: SuperRegion
A2: SuperRegion | B2: Aggregated_Sector | C2: Plant cultivation | D2: Plant processing | E2: Animal husbandry | F2: Animal processing | G2: Food waste and reuse | H2: Mining and forestry | I2: Manufacturing and construction | J2: Manufacturing fertilisers | K2: Trade, transport and utilities | L2: Services | M2: Waste | N2: Water | O2: Hotels and Resteraunts | P2: Plant cultivation | Q2: Plant processing | R2: Animal husbandry | S2: Animal processing | T2: Food waste and reuse | U2: Mining and forestry | V2: Manufacturing and construction | W2: Manufacturing fertilisers | X2: Trade, transport and utilities | Y2: Services | Z2: Waste | AA2: Water | AB2: Hotels and Resteraunts | AC2: Final consumption expenditure by households | AD2: Final consumption expenditure by non-profit organisations serving households (NPISH) | AE2: Final consumption expenditure by government | AF2: Gross fixed capital formation | AG2: Changes in inventories | AH2: Changes in valuables | AI2: Exports: Total (fob) | AJ2: Final consumption expenditure by households | AK2: Final consumption expenditure by non-profit organisations serving households (NPISH) | AL2: Final consumption expenditure by government | AM2: Gross fixed capital formation | AN2: Changes in inventories | AO2: Changes in valuables | AP2: Exports: Total (fob) | AQ2: Y_Region | AR2: Y_Exports | AS2: Y_Total Demand | AT2: X_Total Output | AU2: Aggregated_Sector | AV2: SuperRegion
A3: AT | B3: Plant cultivation | C3: 230.68256 | D3: 721.39815 | E3: 327.47078 | F3: 0.046542671 | G3: 0.0030308331 | H3: 0.11128201 | I3: 55.343047 | J3: 0.02712636 | K3: 24.388163 | L3: 32.10878 | M3: 0.0055718962 | N3: 0.0082605919 | O3: 78.282097 | P3: 40.307207 | Q3: 486.13516 | R3: 211.88669 | S3: 4.6537656 | T3: 0.67022896 | U3: 17.872029 | V3: 165.13934 | W3: 4.1851572 | X3: 66.780569 | Y3: 195.4649 | Z3: 1.4585388 | AA3: 0.043948306 | AB3: 65.560355 | AC3: 462.26954 | AD3: 0.00073144387 | AE3: 0.045280047 | AF3: 31.993768 | AG3: 7.4191078 | AH3: 2.4113949 | AI3: 0 | AJ3: 636.98651 | AK3: 0.022991753 | AL3: 3.654546 | AM3: 0.76484499 | AN3: 177.98502 | AO3: 0.0477127 | AP3: 0 | AQ3: =SUM(AC3:AI3) -> 504.13983 | AR3: =SUM(AJ3:AP3) -> 819.46162 | AS3: =AQ3+AR3 -> 1323.6014 | AT3: =SUM(C3:AP3) -> 4053.6347 | AU3: Plant cultivation | AV3: AT
B4: Plant processing | C4: 0.70523794 | D4: 1518.7845 | E4: 447.36952 | F4: 47.795143 | G4: 1.9114828 | H4: 0.80313359 | I4: 139.82898 | J4: 0.076573384 | K4: 112.10428 | L4: 352.17042 | M4: 3.7183108 | N4: 0.16543556 | O4: 1038.2685 | P4: 15.269846 | Q4: 1482.9354 | R4: 346.17544 | S4: 244.7059 | T4: 1.0269923 | U4: 62.818045 | V4: 594.5556 | W4: 25.664158 | X4: 381.58302 | Y4: 683.89924 | Z4: 9.9666963 | AA4: 0.85770287 | AB4: 1040.5786 | AC4: 7057.7132 | AD4: 0.043799452 | AE4: 10.967905 | AF4: 51.217926 | AG4: 18.983758 | AH4: 6.1523554 | AI4: 0 | AJ4: 9658.2391 | AK4: 1.6885408 | AL4: 15.745797 | AM4: 8.7352634 | AN4: -12.646635 | AO4: 1.9441007 | AP4: 0 | AQ4: =SUM(AC4:AI4) -> 7145.0789 | AR4: =SUM(AJ4:AP4) -> 9673.7061 | AS4: =AQ4+AR4 -> 16818.785 | AT4: =SUM(C4:AP4) -> 25372.523 | AU4: Plant processing
B5: Animal husbandry | C5: 0.16951039 | D5: 279.17703 | E5: 11.701192 | F5: 844.69137 | G5: 0.19585694 | H5: 0.25300887 | I5: 29.783883 | J5: 4.599802 | K5: 392.25776 | L5: 31.497029 | M5: 0.38282067 | N5: 0.15820829 | O5: 57.455375 | P5: 0.49849758 | Q5: 28.073356 | R5: 12.002778 | S5: 81.237286 | T5: 0.84229498 | U5: 1.897816 | V5: 115.76982 | W5: 8.7120086 | X5: 62.599404 | Y5: 54.234654 | Z5: 3.1133664 | AA5: 0.043859106 | AB5: 12.689872 | AC5: 695.64016 | AD5: 0.09562869 | AE5: 30.245596 | AF5: 1221.9379 | AG5: 9.0957376 | AH5: 2.1483711 | AI5: 0 | AJ5: 197.8533 | AK5: 3.6948703 | AL5: 3.2387618 | AM5: 55.727588 | AN5: 47.227662 | AO5: 6.8573312 | AP5: 0 | AQ5: =SUM(AC5:AI5) -> 1959.1633 | AR5: =SUM(AJ5:AP5) -> 314.59952 | AS5: =AQ5+AR5 -> 2273.7629 | AT5: =SUM(C5:AP5) -> 4307.8007 | AU5: Animal husbandry
B6: Animal processing | C6: 2.831445 | D6: 165.31124 | E6: 53.132147 | F6: 427.50066 | G6: 1.0862806 | H6: 1.7601426 | I6: 126.59791 | J6: 0.42147721 | K6: 112.2109 | L6: 414.2444 | M6: 2.1398329 | N6: 0.41696889 | O6: 459.47672 | P6: 20.745973 | Q6: 278.3262 | R6: 45.197126 | S6: 591.63251 | T6: 1.3018863 | U6: 30.89146 | V6: 267.60628 | W6: 4.7668404 | X6: 169.75706 | Y6: 303.64519 | Z6: 2.3660677 | AA6: 0.54875379 | AB6: 325.11026 | AC6: 1506.4837 | AD6: 0.023250513 | AE6: 24.669192 | AF6: 61.642587 | AG6: 9.4864543 | AH6: 2.4528549 | AI6: 0 | AJ6: 2648.9159 | AK6: 3.6005505 | AL6: 5.1450724 | AM6: 6.8076315 | AN6: -184.64999 | AO6: 6.8672941 | AP6: 0 | AQ6: =SUM(AC6:AI6) -> 1604.758 | AR6: =SUM(AJ6:AP6) -> 2486.6864 | AS6: =AQ6+AR6 -> 4091.4444 | AT6: =SUM(C6:AP6) -> 7900.4702 | AU6: Animal processing
B7: Food waste and reuse | C7: 33.580893 | D7: 8.3511086 | E7: 1.5049304 | F7: 11.56261 | G7: 280.66968 | H7: 3.3331151 | I7: 257.92879 | J7: 0.29149596 | K7: 186.39188 | L7: 904.58648 | M7: 551.72562 | N7: 1.074856 | O7: 22.651083 | P7: 1.4224744 | Q7: 1.6868149 | R7: 2.555742 | S7: 3.9479118 | T7: 1.4111614 | U7: 1.1724963 | V7: 28.279307 | W7: 0.35602924 | X7: 11.060499 | Y7: 11.705756 | Z7: 4.2303619 | AA7: 0.19893767 | AB7: 0.88137436 | AC7: 42.190373 | AD7: 0.033735532 | AE7: 5.5730161 | AF7: 11.550764 | AG7: 2.1513445 | AH7: 0.33941871 | AI7: 0 | AJ7: 5.1613416 | AK7: 0.090433363 | AL7: 0.91856082 | AM7: 1.5380764 | AN7: 0.4359035 | AO7: 0.19434114 | AP7: 0 | AQ7: =SUM(AC7:AI7) -> 61.838653 | AR7: =SUM(AJ7:AP7) -> 8.3386569 | AS7: =AQ7+AR7 -> 70.177309 | AT7: =SUM(C7:AP7) -> 2402.7387 | AU7: Food waste and reuse
B8: Mining and forestry | C8: 45.361313 | D8: 37.018553 | E8: 17.735727 | F8: 16.437473 | G8: 23.138338 | H8: 1030.9495 | I8: 2017.0357 | J8: 19.195376 | K8: 516.3769 | L8: 292.80645 | M8: 43.11903 | N8: 1.6884188 | O8: 158.40092 | P8: 96.461871 | Q8: 45.68226 | R8: 19.950996 | S8: 37.78291 | T8: 2.3553271 | U8: 20.905571 | V8: 579.18291 | W8: 7.2983703 | X8: 193.81848 | Y8: 83.522171 | Z8: 7.487954 | AA8: 2.8386907 | AB8: 60.228544 | AC8: 725.09772 | AD8: 0.019357234 | AE8: 23.700002 | AF8: 134.98622 | AG8: 57.338144 | AH8: -5.5388358 | AI8: 0 | AJ8: 466.45877 | AK8: 0.25295558 | AL8: 3.9632913 | AM8: 12.780987 | AN8: 170.48939 | AO8: 0.30797299 | AP8: 0 | AQ8: =SUM(AC8:AI8) -> 935.6026 | AR8: =SUM(AJ8:AP8) -> 654.25338 | AS8: =AQ8+AR8 -> 1589.856 | AT8: =SUM(C8:AP8) -> 6966.6358 | AU8: Mining and forestry
B9: Manufacturing and construction | C9: 419.08085 | D9: 780.92518 | E9: 329.73639 | F9: 415.89305 | G9: 147.83392 | H9: 426.19599 | I9: 50825.426 | J9: 7.6000216 | K9: 7584.2766 | L9: 20824.427 | M9: 258.64242 | N9: 262.0371 | O9: 1219.6615 | P9: 516.49194 | Q9: 908.115 | R9: 341.39189 | S9: 631.4426 | T9: 48.812765 | U9: 533.20443 | V9: 50558.375 | W9: 249.32204 | X9: 4284.8239 | Y9: 4748.7052 | Z9: 145.14226 | AA9: 39.231757 | AB9: 273.08534 | AC9: 10196.334 | AD9: 2.5313132 | AE9: 3581.5064 | AF9: 52684.799 | AG9: 9.4347446 | AH9: -57.527355 | AI9: 0 | AJ9: 10454.401 | AK9: 31.126184 | AL9: 480.48206 | AM9: 11678.237 | AN9: 1029.7066 | AO9: 2.2216811 | AP9: 0 | AQ9: =SUM(AC9:AI9) -> 66417.078 | AR9: =SUM(AJ9:AP9) -> 23676.174 | AS9: =AQ9+AR9 -> 90093.252 | AT9: =SUM(C9:AP9) -> 236873.13 | AU9: Manufacturing and construction
B10: Manufacturing fertilisers | C10: 4.4397152 | D10: 69.973974 | E10: 47.115817 | F10: 0.18220145 | G10: 2.041242 | H10: 0.30705626 | I10: 13.486772 | J10: 0.005182991 | K10: 4.9582528 | L10: 22.251523 | M10: 3.9434323 | N10: 0.031747225 | O10: 61.424073 | P10: 24.564199 | Q10: 70.884704 | R10: 13.370131 | S10: 4.8643408 | T10: 0.074224764 | U10: 0.59999934 | V10: 44.026467 | W10: 0.60020362 | X10: 6.497883 | Y10: 12.202177 | Z10: 0.12275022 | AA10: 0.012970384 | AB10: 13.483618 | AC10: 33.584643 | AD10: 0.17051901 | AE10: 2.6425581 | AF10: 6.6946927 | AG10: 0.10649594 | AH10: 0.24803853 | AI10: 0 | AJ10: 63.590355 | AK10: 0.080487725 | AL10: 10.093452 | AM10: 0.47861485 | AN10: -2.6254441 | AO10: 0.001951968 | AP10: 0 | AQ10: =SUM(AC10:AI10) -> 43.446947 | AR10: =SUM(AJ10:AP10) -> 71.619418 | AS10: =AQ10+AR10 -> 115.06636 | AT10: =SUM(C10:AP10) -> 536.53102 | AU10: Manufacturing fertilisers
B11: Trade, transport and utilities | C11: 243.71322 | D11: 1153.8821 | E11: 212.4641 | F11: 762.33997 | G11: 135.43199 | H11: 468.37331 | I11: 12367.669 | J11: 34.071041 | K11: 18158.684 | L11: 10886.37 | M11: 234.36081 | N11: 57.489619 | O11: 1662.1633 | P11: 395.61986 | Q11: 822.19184 | R11: 328.6818 | S11: 633.31564 | T11: 150.01656 | U11: 282.16329 | V11: 9778.9744 | W11: 117.14269 | X11: 10068.611 | Y11: 3865.9916 | Z11: 134.6616 | AA11: 47.452909 | AB11: 267.72021 | AC11: 54706.468 | AD11: 2.6791772 | AE11: 6051.9289 | AF11: 4487.799 | AG11: 239.53229 | AH11: 24.522061 | AI11: 0 | AJ11: 6380.5511 | AK11: 32.919032 | AL11: 106.95707 | AM11: 638.08995 | AN11: 142.48308 | AO11: 54.758878 | AP11: 0 | AQ11: =SUM(AC11:AI11) -> 65512.929 | AR11: =SUM(AJ11:AP11) -> 7355.7591 | AS11: =AQ11+AR11 -> 72868.688 | AT11: =SUM(C11:AP11) -> 146138.24 | AU11: Trade, transport and utilities
B12: Services | C12: 311.29306 | D12: 1671.7511 | E12: 314.99661 | F12: 946.01256 | G12: 186.68098 | H12: 284.3616 | I12: 15342.211 | J12: 6.010287 | K12: 19864.123 | L12: 54019.433 | M12: 382.61461 | N12: 82.072232 | O12: 1665.3539 | P12: 143.49939 | Q12: 322.40563 | R12: 100.46284 | S12: 195.83962 | T12: 35.122327 | U12: 207.29103 | V12: 4319.7348 | W12: 50.033946 | X12: 2040.182 | Y12: 5289.566 | Z12: 104.7755 | AA12: 16.486445 | AB12: 156.4923 | AC12: 79893.262 | AD12: 10429.674 | AE12: 67269.722 | AF12: 14375.932 | AG12: 66.680606 | AH12: 17.001163 | AI12: 0 | AJ12: 1580.065 | AK12: 191.5938 | AL12: 504.53434 | AM12: 2003.6778 | AN12: 150.10698 | AO12: 41.674337 | AP12: 0 | AQ12: =SUM(AC12:AI12) -> 172052.27 | AR12: =SUM(AJ12:AP12) -> 4471.6523 | AS12: =AQ12+AR12 -> 176523.92 | AT12: =SUM(C12:AP12) -> 284582.73 | AU12: Services
B13: Waste | C13: 13.746245 | D13: 16.13001 | E13: 3.8815479 | F13: 42.50759 | G13: 543.01996 | H13: 6.6519169 | I13: 639.35057 | J13: 0.5878753 | K13: 371.412 | L13: 1679.0396 | M13: 1073.2294 | N13: 1.8142479 | O13: 41.98349 | P13: 3.3856998 | Q13: 4.0424265 | R13: 5.5174308 | S13: 8.5380765 | T13: 3.9893131 | U13: 2.237714 | V13: 65.502247 | W13: 1.6568757 | X13: 20.551999 | Y13: 27.130856 | Z13: 10.39925 | AA13: 0.46821373 | AB13: 1.7849796 | AC13: 44.65593 | AD13: 0.068046198 | AE13: 8.7955957 | AF13: 23.911059 | AG13: 4.2574479 | AH13: 0.70612918 | AI13: 0 | AJ13: 12.537204 | AK13: 0.2045086 | AL13: 1.4843213 | AM13: 3.2651334 | AN13: 1.0223699 | AO13: 0.31180782 | AP13: 0 | AQ13: =SUM(AC13:AI13) -> 82.394208 | AR13: =SUM(AJ13:AP13) -> 18.825345 | AS13: =AQ13+AR13 -> 101.21955 | AT13: =SUM(C13:AP13) -> 4689.779 | AU13: Waste
B14: Water | C14: 4.6948942 | D14: 19.55543 | E14: 5.4133695 | F14: 3.1222796 | G14: 5.0753002 | H14: 1.5455627 | I14: 100.32612 | J14: 0.18384942 | K14: 93.593226 | L14: 783.85438 | M14: 10.007126 | N14: 22.201018 | O14: 49.201894 | P14: 0.17702877 | Q14: 0.092657988 | R14: 0.034398116 | S14: 0.066599734 | T14: 0.014814003 | U14: 0.03558927 | V14: 1.5237923 | W14: 0.0093182515 | X14: 1.033184 | Y14: 1.3232549 | Z14: 0.038959233 | AA14: 0.031148481 | AB14: 0.038671855 | AC14: 1.365161 | AD14: 0 | AE14: 0.023201697 | AF14: 10.483103 | AG14: 0.032328147 | AH14: 0.0080431782 | AI14: 0 | AJ14: 0.29511264 | AK14: 0.018367011 | AL14: 0.012938802 | AM14: 0.73247332 | AN14: 0.004478121 | AO14: 0.00092277349 | AP14: 0 | AQ14: =SUM(AC14:AI14) -> 11.911837 | AR14: =SUM(AJ14:AP14) -> 1.0642927 | AS14: =AQ14+AR14 -> 12.97613 | AT14: =SUM(C14:AP14) -> 1116.17 | AU14: Water
B15: Hotels and Resteraunts | C15: 5.3136132 | D15: 86.236569 | E15: 5.5976654 | F15: 48.128643 | G15: 4.2654028 | H15: 6.9070914 | I15: 548.14745 | J15: 0.42382406 | K15: 881.71414 | L15: 1074.1298 | M15: 8.4402485 | N15: 3.0628902 | O15: 302.89195 | P15: 32.604482 | Q15: 69.719528 | R15: 26.996196 | S15: 22.313997 | T15: 9.5861026 | U15: 45.973384 | V15: 2852.1642 | W15: 78.942505 | X15: 9260.027 | Y15: 3505.6874 | Z15: 21.250438 | AA15: 4.1547744 | AB15: 157.04745 | AC15: 2664.1669 | AD15: 5.1928534 | AE15: 77.334588 | AF15: 43.502679 | AG15: 1.3423924 | AH15: 0.26979731 | AI15: 0 | AJ15: 1951.7642 | AK15: 554.31663 | AL15: 23.582716 | AM15: 20.344667 | AN15: 4883.7646 | AO15: 1303.9148 | AP15: 0 | AQ15: =SUM(AC15:AI15) -> 2791.8092 | AR15: =SUM(AJ15:AP15) -> 8737.6876 | AS15: =AQ15+AR15 -> 11529.497 | AT15: =SUM(C15:AP15) -> 30591.224 | AU15: Hotels and Resteraunts
A16: World_but_AT | B16: Plant cultivation | C16: 62.865283 | D16: 723.28964 | E16: 468.81003 | F16: 0.63319115 | G16: 0.076480653 | H16: 0.46196787 | I16: 169.97402 | J16: 0.12223681 | K16: 18.996482 | L16: 46.800421 | M16: 0.19162632 | N16: 0.0058187874 | O16: 174.13546 | P16: 716052.2 | Q16: 879752.81 | R16: 87428.008 | S16: 5979.019 | T16: 199.92899 | U16: 22338.447 | V16: 463959.79 | W16: 29676.563 | X16: 48374.116 | Y16: 150225 | Z16: 839.05322 | AA16: 696.78732 | AB16: 47428.826 | AC16: 1263.9151 | AD16: 0 | AE16: 0.18997939 | AF16: 36.48352 | AG16: 3.0654746 | AH16: 0.042705018 | AI16: 0 | AJ16: 904926.91 | AK16: 552.4543 | AL16: 18964.209 | AM16: 63323.495 | AN16: 130813.44 | AO16: -46.807683 | AP16: 0 | AQ16: =SUM(AJ16:AP16) -> 1118533.7 | AR16: =SUM(AC16:AI16) -> 1303.6968 | AS16: =AQ16+AR16 -> 1119837.4 | AT16: =SUM(C16:AP16) -> 3574454.3 | AU16: Plant cultivation | AV16: World_but_AT
B17: Plant processing | C17: 1.5072303 | D17: 924.60947 | E17: 76.2753 | F17: 61.957647 | G17: 0.029647852 | H17: 0.42142129 | I17: 482.41115 | J17: 0.14689252 | K17: 161.92435 | L17: 110.98718 | M17: 0.060103296 | N17: 0.040394068 | O17: 393.07175 | P17: 10099.604 | Q17: 516539.45 | R17: 170085.66 | S17: 89633.188 | T17: 455.08707 | U17: 5814.8969 | V17: 117272.31 | W17: 12725.77 | X17: 84682.068 | Y17: 186015.38 | Z17: 1476.1264 | AA17: 736.81041 | AB17: 316716.06 | AC17: 4982.1696 | AD17: 0 | AE17: 0.2183322 | AF17: 5.8763261 | AG17: 2.0772574 | AH17: 0.010227036 | AI17: 0 | AJ17: 2231723.9 | AK17: 472.37672 | AL17: 17550.844 | AM17: 5956.9743 | AN17: 15760.056 | AO17: 476.26951 | AP17: 0 | AQ17: =SUM(AJ17:AP17) -> 2271940.4 | AR17: =SUM(AC17:AI17) -> 4990.3517 | AS17: =AQ17+AR17 -> 2276930.8 | AT17: =SUM(C17:AP17) -> 3791396.6 | AU17: Plant processing
B18: Animal husbandry | C18: 0.10307963 | D18: 5.0388205 | E18: 2.4728014 | F18: 126.36192 | G18: 0.030665324 | H18: 0.8548333 | I18: 35.078288 | J18: 0.031622784 | K18: 37.099081 | L18: 31.350593 | M18: 0.068501938 | N18: 0.007228604 | O18: 17.423598 | P18: 3827.7336 | Q18: 25754.76 | R18: 153421.23 | S18: 730109.3 | T18: 463.46391 | U18: 5649.1921 | V18: 82247.614 | W18: 9469.9758 | X18: 26223.917 | Y18: 35709.826 | Z18: 377.88882 | AA18: 919.77351 | AB18: 64998.857 | AC18: 109.36556 | AD18: 0 | AE18: 0.27134592 | AF18: 113.83794 | AG18: -0.75228224 | AH18: 0.074549015 | AI18: 0 | AJ18: 591491.84 | AK18: 2517.1973 | AL18: 34496.018 | AM18: 95928.07 | AN18: 261735.58 | AO18: 266.25989 | AP18: 0 | AQ18: =SUM(AJ18:AP18) -> 986434.97 | AR18: =SUM(AC18:AI18) -> 222.79712 | AS18: =AQ18+AR18 -> 986657.76 | AT18: =SUM(C18:AP18) -> 2126087.2 | AU18: Animal husbandry
B19: Animal processing | C19: 0.87368947 | D19: 107.28546 | E19: 87.241239 | F19: 351.09168 | G19: 0.069465587 | H19: 0.72075318 | I19: 197.76009 | J19: 0.27785082 | K19: 572.52544 | L19: 134.15787 | M19: 0.14378785 | N19: 0.031679183 | O19: 293.16561 | P19: 7637.5443 | Q19: 118632.41 | R19: 35153.253 | S19: 179327.06 | T19: 348.3578 | U19: 3477.4633 | V19: 84174.695 | W19: 5557.5714 | X19: 43166.375 | Y19: 143802.53 | Z19: 1439.538 | AA19: 577.88087 | AB19: 182740.95 | AC19: 1277.4471 | AD19: 0 | AE19: 0.3092875 | AF19: 10.997229 | AG19: 5.1922524 | AH19: 0.015729394 | AI19: 0 | AJ19: 1390058.3 | AK19: 16936.941 | AL19: 14125.231 | AM19: 6845.7963 | AN19: 49962.772 | AO19: 348.9897 | AP19: 0 | AQ19: =SUM(AJ19:AP19) -> 1478278.1 | AR19: =SUM(AC19:AI19) -> 1293.9616 | AS19: =AQ19+AR19 -> 1479572 | AT19: =SUM(C19:AP19) -> 2287353 | AU19: Animal processing
B20: Food waste and reuse | C20: 0.12573364 | D20: 1.3723605 | E20: 0.13608307 | F20: 0.54739531 | G20: 2.5568797 | H20: 0.026998352 | I20: 33.851527 | J20: 0.020247936 | K20: 8.501986 | L20: 3.243345 | M20: 4.8490116 | N20: 0.014118374 | O20: 0.24700065 | P20: 760.03301 | Q20: 1577.6522 | R20: 813.7327 | S20: 1430.1795 | T20: 5446.9462 | U20: 1694.7209 | V20: 30546.024 | W20: 300.04443 | X20: 9456.793 | Y20: 26211.784 | Z20: 10921.758 | AA20: 1426.4674 | AB20: 1982.4499 | AC20: 51.968558 | AD20: 0 | AE20: 0.036550747 | AF20: 1.0305962 | AG20: 0.85823896 | AH20: 0.32151922 | AI20: 0 | AJ20: 36987.403 | AK20: 187.40297 | AL20: 15693.765 | AM20: 2207.9711 | AN20: 652.92166 | AO20: 99.631173 | AP20: 0 | AQ20: =SUM(AJ20:AP20) -> 55829.095 | AR20: =SUM(AC20:AI20) -> 54.215463 | AS20: =AQ20+AR20 -> 55883.31 | AT20: =SUM(C20:AP20) -> 148507.39 | AU20: Food waste and reuse
B21: Mining and forestry | C21: 20.093132 | D21: 42.586785 | E21: 80.833401 | F21: 6.6744592 | G21: 0.96118835 | H21: 329.33688 | I21: 6540.6182 | J21: 344.79778 | K21: 718.12919 | L21: 76.752341 | M21: 2.2620695 | N21: 0.13814482 | O21: 19.621946 | P21: 14687.034 | Q21: 17653.876 | R21: 13024.996 | S21: 15589.132 | T21: 784.46181 | U21: 526712.8 | V21: 2941972.4 | W21: 34589.501 | X21: 553260.51 | Y21: 67606.982 | Z21: 3235.5789 | AA21: 2429.4818 | AB21: 6575.5375 | AC21: 52.732562 | AD21: 0 | AE21: 1.4754536 | AF21: 19.540849 | AG21: 124.38046 | AH21: 0.015749385 | AI21: 0 | AJ21: 187013.57 | AK21: 334.51218 | AL21: 15610.209 | AM21: 27480.316 | AN21: 54336.215 | AO21: 91.409291 | AP21: 0 | AQ21: =SUM(AJ21:AP21) -> 284866.23 | AR21: =SUM(AC21:AI21) -> 198.14507 | AS21: =AQ21+AR21 -> 285064.37 | AT21: =SUM(C21:AP21) -> 4491369.5 | AU21: Mining and forestry
B22: Manufacturing and construction | C22: 618.17888 | D22: 756.76687 | E22: 181.10095 | F22: 505.72133 | G22: 22.860637 | H22: 114.0884 | I22: 41525.824 | J22: 10.37789 | K22: 2802.7384 | L22: 6039.0281 | M22: 32.976567 | N22: 10.850518 | O22: 376.46095 | P22: 282819.01 | Q22: 327521.27 | R22: 152714.06 | S22: 222343.72 | T22: 18597.773 | U22: 544153.24 | V22: 20423184 | W22: 173627.04 | X22: 2451611.9 | Y22: 3845384.8 | Z22: 41352.11 | AA22: 26848.343 | AB22: 184857.62 | AC22: 25473.298 | AD22: 0 | AE22: 48.693647 | AF22: 25730.391 | AG22: -3856.3175 | AH22: 2.1910407 | AI22: 0 | AJ22: 5631171.1 | AK22: 21194.941 | AL22: 345242.15 | AM22: 15450900 | AN22: 339885.87 | AO22: 33751.133 | AP22: 0 | AQ22: =SUM(AJ22:AP22) -> 21822145 | AR22: =SUM(AC22:AI22) -> 47398.256 | AS22: =AQ22+AR22 -> 21869543 | AT22: =SUM(C22:AP22) -> 50617555 | AU22: Manufacturing and construction
B23: Manufacturing fertilisers | C23: 12.162535 | D23: 0.8925931 | E23: 1.6656781 | F23: 0.42789537 | G23: 0.1326655 | H23: 0.46277902 | I23: 111.75486 | J23: 0.1853383 | K23: 4.2746904 | L23: 7.7060574 | M23: 0.26635619 | N23: 0.011981261 | O23: 0.66985815 | P23: 229904.38 | Q23: 2279.388 | R23: 6213.5911 | S23: 2496.9045 | T23: 67.068251 | U23: 13897.572 | V23: 68620.429 | W23: 117970.94 | X23: 11692.701 | Y23: 21279.996 | Z23: 135.33964 | AA23: 236.18753 | AB23: 1280.2167 | AC23: 27.843777 | AD23: 0 | AE23: 4.2440125 | AF23: 8.4463037 | AG23: 2.1371508 | AH23: 0.015961425 | AI23: 0 | AJ23: 47836.9 | AK23: 80.066686 | AL23: 215061.42 | AM23: 3610.353 | AN23: 9292.5677 | AO23: 70.449586 | AP23: 0 | AQ23: =SUM(AJ23:AP23) -> 275951.76 | AR23: =SUM(AC23:AI23) -> 42.687206 | AS23: =AQ23+AR23 -> 275994.44 | AT23: =SUM(C23:AP23) -> 752209.76 | AU23: Manufacturing fertilisers
B24: Trade, transport and utilities | C24: 37.773046 | D24: 636.4462 | E24: 93.198803 | F24: 674.34704 | G24: 25.432112 | H24: 178.50676 | I24: 8410.5077 | J24: 47.50907 | K24: 6079.6783 | L24: 1856.4085 | M24: 59.877558 | N24: 14.665921 | O24: 167.77145 | P24: 239401.94 | Q24: 479706.79 | R24: 245596.97 | S24: 302634.8 | T24: 13907.124 | U24: 386960.06 | V24: 5500831.8 | W24: 153703.48 | X24: 4491665.5 | Y24: 3440014.6 | Z24: 31283.527 | AA24: 22070.49 | AB24: 472686.75 | AC24: 1156.6307 | AD24: 0 | AE24: 24.308017 | AF24: 4680.1142 | AG24: -25.009387 | AH24: 8.566634 | AI24: 0 | AJ24: 9724786 | AK24: 12549.976 | AL24: 541122.37 | AM24: 979977.57 | AN24: 108549 | AO24: 11207.68 | AP24: 0 | AQ24: =SUM(AJ24:AP24) -> 11378193 | AR24: =SUM(AC24:AI24) -> 5844.6101 | AS24: =AQ24+AR24 -> 11384037 | AT24: =SUM(C24:AP24) -> 27182783 | AU24: Trade, transport and utilities
B25: Services | C25: 20.629362 | D25: 299.13419 | E25: 24.7553 | F25: 486.8617 | G25: 8.8234549 | H25: 32.521317 | I25: 4134.6513 | J25: 7.1482117 | K25: 2099.3615 | L25: 7508.5326 | M25: 17.482004 | N25: 2.3614905 | O25: 149.59506 | P25: 158442.17 | Q25: 238543.04 | R25: 99539.655 | S25: 113474.59 | T25: 25640.828 | U25: 362121.95 | V25: 3779585.3 | W25: 68545.027 | X25: 2942021.7 | Y25: 11916609 | Z25: 50347.559 | AA25: 28946.109 | AB25: 479283.47 | AC25: 1889.7609 | AD25: 0 | AE25: 126.64854 | AF25: 240.41355 | AG25: -15.828381 | AH25: 4.1058986 | AI25: 0 | AJ25: 19214876 | AK25: 910965.06 | AL25: 11613463 | AM25: 3305544.4 | AN25: 123639.73 | AO25: 2782.1215 | AP25: 0 | AQ25: =SUM(AJ25:AP25) -> 35171271 | AR25: =SUM(AC25:AI25) -> 2245.1005 | AS25: =AQ25+AR25 -> 35173516 | AT25: =SUM(C25:AP25) -> 55451408 | AU25: Services
B26: Waste | C26: 0.08323127 | D26: 2.6066054 | E26: 0.11415432 | F26: 1.3203171 | G26: 5.6502073 | H26: 0.11128268 | I26: 155.88737 | J26: 0.048238612 | K26: 25.124643 | L26: 5.3558641 | M26: 15.343469 | N26: 0.034895282 | O26: 0.51006862 | P26: 2145.9831 | Q26: 4581.8776 | R26: 3015.8632 | S26: 4318.3041 | T26: 11475.426 | U26: 6237.7765 | V26: 66726.377 | W26: 732.8543 | X26: 27381.418 | Y26: 77180.188 | Z26: 27810.595 | AA26: 2770.8195 | AB26: 7535.9973 | AC26: 3.0974458 | AD26: 0 | AE26: 0.062461486 | AF26: 2.4375011 | AG26: 4.8436448 | AH26: 0.89535109 | AI26: 0 | AJ26: 59356.027 | AK26: 433.80322 | AL26: 27888.701 | AM26: 1264.8289 | AN26: 1275.9081 | AO26: 216.18455 | AP26: 0 | AQ26: =SUM(AJ26:AP26) -> 90435.453 | AR26: =SUM(AC26:AI26) -> 11.336404 | AS26: =AQ26+AR26 -> 90446.79 | AT26: =SUM(C26:AP26) -> 332572.46 | AU26: Waste
B27: Water | C27: 0.029321706 | D27: 1.0761934 | E27: 0.05794727 | F27: 0.62694361 | G27: 0.6177587 | H27: 0.14236662 | I27: 14.4574 | J27: 0.026773321 | K27: 20.735972 | L27: 3.2653264 | M27: 1.3377299 | N27: 0.0051090476 | O27: 0.25965814 | P27: 4585.7152 | Q27: 3077.432 | R27: 1267.5794 | S27: 1513.8094 | T27: 1289.1696 | U27: 3367.0214 | V27: 27465.189 | W27: 1112.8647 | X27: 15449.485 | Y27: 42739.893 | Z27: 2611.0164 | AA27: 10850.189 | AB27: 5374.08 | AC27: 2.5958008 | AD27: 0 | AE27: 0.036182476 | AF27: 6.37525 | AG27: 0.064114812 | AH27: 0.11767151 | AI27: 0 | AJ27: 109252.56 | AK27: 58.154509 | AL27: 7502.9376 | AM27: 1778.502 | AN27: -72.780569 | AO27: 50.518496 | AP27: 0 | AQ27: =SUM(AJ27:AP27) -> 118569.9 | AR27: =SUM(AC27:AI27) -> 9.1890196 | AS27: =AQ27+AR27 -> 118579.09 | AT27: =SUM(C27:AP27) -> 239325.17 | AU27: Water
B28: Hotels and Resteraunts | C28: 1.9644419 | D28: 28.795457 | E28: 2.7087439 | F28: 13.914548 | G28: 1.3998804 | H28: 2.6195367 | I28: 372.04637 | J28: 0.35968255 | K28: 1303.9563 | L28: 7248.5005 | M28: 2.7777697 | N28: 0.83069947 | O28: 76.321252 | P28: 7916.9457 | Q28: 12347.911 | R28: 5460.5789 | S28: 11204.756 | T28: 785.48437 | U28: 19200.851 | V28: 266448.04 | W28: 4293.7063 | X28: 275122.4 | Y28: 771357.8 | Z28: 2266.3767 | AA28: 992.65598 | AB28: 40077.983 | AC28: 7.8419532 | AD28: 0 | AE28: 0.12498538 | AF28: 3.7438809 | AG28: -0.30405845 | AH28: 0.052888161 | AI28: 0 | AJ28: 2716276.4 | AK28: 29605.392 | AL28: 76762.719 | AM28: 7526.2057 | AN28: 33012.512 | AO28: 7549.7442 | AP28: 0 | AQ28: =SUM(AJ28:AP28) -> 2870732.9 | AR28: =SUM(AC28:AI28) -> 11.459649 | AS28: =AQ28+AR28 -> 2870744.4 | AT28: =SUM(C28:AP28) -> 4297276.1 | AU28: Hotels and Resteraunts
B29: Value Added | C29: =$AT3-C30 -> 1961.6332 | D29: =$AT4-D30 -> 15314.128 | E29: =$AT5-E30 -> 1510.3105 | F29: =$AT6-F30 -> 2103.764 | G29: =$AT7-G30 -> 1002.7442 | H29: =$AT8-H30 -> 4074.8078 | I29: =$AT9-I30 -> 92225.175 | J29: =$AT10-J30 -> 51.985251 | K29: =$AT11-K30 -> 83982.707 | L29: =$AT12-L30 -> 170193.72 | M29: =$AT13-M30 -> 1979.8133 | N29: =$AT14-N30 -> 654.951 | O29: =$AT15-O30 -> 22104.755 | P29: =$AT16-P30 -> 1894883 | Q29: =$AT17-Q30 -> 1158907.6 | R29: =$AT18-R30 -> 1150897.8 | S29: =$AT19-S30 -> 604837.9 | T29: =$AT20-T30 -> 68791.045 | U29: =$AT21-U30 -> 2588536.4 | V29: =$AT22-V30 -> 16695151 | W29: =$AT23-W30 -> 139355.74 | X29: =$AT24-X30 -> 16176107 | Y29: =$AT25-Y30 -> 34708488 | Z29: =$AT26-Z30 -> 158030.98 | AA29: =$AT27-AA30 -> 139710.8 | AB29: =$AT28-AB30 -> 2483362.6 | AC29: =SUM(C29:AB29) -> 78364219 | AE29: GDP
B30: Sum Inter-Industry Input | C30: =SUM(C3:C28) -> 2092.0015 | D30: =SUM(D3:D28) -> 10058.396 | E30: =SUM(E3:E28) -> 2797.4902 | F30: =SUM(F3:F28) -> 5796.7062 | G30: =SUM(G3:G28) -> 1399.9945 | H30: =SUM(H3:H28) -> 2891.828 | I30: =SUM(I3:I28) -> 144647.96 | J30: =SUM(J3:J28) -> 484.54577 | ... AB30: =SUM(AB3:AB28) -> 1813913.5
B31: X_Total Industry Input (Output) | C31: =SUM(C3:C29) -> 4053.6347 | D31: =SUM(D3:D29) -> 25372.523 | E31: =SUM(E3:E29) -> 4307.8007 | F31: =SUM(F3:F29) -> 7900.4702 | G31: =SUM(G3:G29) -> 2402.7387 | H31: =SUM(H3:H29) -> 6966.6358 | I31: =SUM(I3:I29) -> 236873.13 | J31: =SUM(J3:J29) -> 536.53102 | ... AB31: =SUM(AB3:AB29) -> 4297276.1
B33: Environmental Emissions (scope 1) - M Matrix
B34: SuperRegion | C34: AT | P34: World_but_AT
B35: Aggregated_Sector | C35: Plant cultivation | D35: Plant processing | E35: Animal husbandry | F35: Animal processing | G35: Food waste and reuse | H35: Mining and forestry | I35: Manufacturing and construction | J35: Manufacturing fertilisers | K35: Trade, transport and utilities | L35: Services | M35: Waste | N35: Water | O35: Hotels and Resteraunts | P35: Plant cultivation | Q35: Plant processing | R35: Animal husbandry | S35: Animal processing | T35: Food waste and reuse | U35: Mining and forestry | V35: Manufacturing and construction | W35: Manufacturing fertilisers | X35: Trade, transport and utilities | Y35: Services | Z35: Waste | AA35: Water | AB35: Hotels and Resteraunts
A36: Emissions | B36: CO2 | C36: 1.5993954e+09 | D36: 9.073041e+08 | E36: 1.4220182e+09 | F36: 4.5011202e+08 | G36: 1.9754898e+08 | H36: 1.3488115e+09 | I36: 2.6932982e+10 | J36: 25411300 | K36: 2.4996084e+10 | L36: 5.8123841e+09 | M36: 3.0451057e+08 | N36: 6207549.4 | O36: 1.2695482e+09 | P36: 6.7060212e+11 | Q36: 4.6121887e+11 | R36: 3.5528424e+11 | S36: 5.4085772e+11 | T36: 4.894075e+10 | U36: 1.2681621e+12 | V36: 1.071722e+13 | W36: 3.7243034e+11 | X36: 1.6319027e+13 | Y36: 1.7003088e+12 | Z36: 8.3590785e+10 | AA36: 2.3772825e+10 | AB36: 1.1999837e+11
B37: CH4 Fossil (CO2 eq) | C37: 14564307 | D37: 3263882.7 | E37: 27359991 | F37: 1807094.2 | G37: 1338099.2 | H37: 25384000 | I37: 76396241 | J37: 122854.74 | K37: 88038877 | L37: 19846533 | M37: 2583157.2 | N37: 17230.296 | O37: 13002997 | P37: 8.1658011e+09 | Q37: 2.1504162e+09 | R37: 4.7215396e+09 | S37: 3.2157609e+09 | T37: 1.4800138e+08 | U37: 3.4253158e+09 | V37: 2.6777665e+10 | W37: 9.8360651e+08 | X37: 1.7845257e+10 | Y37: 1.4396815e+10 | Z37: 5.0916709e+08 | AA37: 1.5564108e+08 | AB37: 2.1824001e+09
B38: CH4 non-fossil (CO2 eq) | C38: 0 | D38: 0 | E38: 5.5725996e+09 | F38: 0 | G38: 1.1184879e+09 | H38: 0 | I38: 0 | J38: 0 | K38: 0 | L38: 0 | M38: 1.6439732e+09 | N38: 0 | O38: 0 | P38: 1200539268970 | Q38: 0 | R38: 2.9624865e+12 | S38: 0 | T38: 1.4958422e+12 | U38: 0 | V38: 0 | W38: 0 | X38: 0 | Y38: 0 | Z38: 8.7458692e+11 | AA38: 0 | AB38: 0
B39: NO2 (CO2 eq) | C39: 1.1404979e+09 | D39: 4305058.1 | E39: 1.1685169e+09 | F39: 2387046.6 | G39: 2057895.5 | H39: 10478558 | I39: 1.4776074e+08 | J39: 149676.71 | K39: 1.1932054e+08 | L39: 43919677 | M39: 3256031 | N39: 63616.418 | O39: 14175284 | P39: 8.3230179e+11 | Q39: 3.0940682e+09 | R39: 1.290654e+12 | S39: 3.7403643e+09 | T39: 2.2432258e+08 | U39: 6.9228936e+09 | V39: 5.2859796e+10 | W39: 1.6162448e+09 | X39: 1.0662244e+11 | Y39: 1.49167e+10 | Z39: 3.5217979e+08 | AA39: 1.0552214e+08 | AB39: 1.40177e+09
B40: SF6 (CO2 eq) | C40: 36898335 | D40: 19426185 | E40: 6080196.6 | F40: 3311865.8 | G40: 76966529 | H40: 1.2145736e+08 | I40: 1.1016552e+08 | J40: 1221787 | K40: 0 | L40: 0 | M40: 88602178 | N40: 0 | O40: 0 | P40: 2.1037289e+10 | Q40: 2.7758084e+09 | R40: 2.4974e+09 | S40: 4.9574601e+08 | T40: 3.3242259e+10 | U40: 5.9515744e+10 | V40: 8.0459782e+10 | W40: 6.9019774e+08 | X40: 0 | Y40: 0 | Z40: 1.3386852e+10 | AA40: 0 | AB40: 0
B41: Total (CO2 eq) | C41: 2.7913559e+09 | D41: 9.3429923e+08 | E41: 8.1965748e+09 | F41: 4.5761803e+08 | G41: 1.3963994e+09 | H41: 1.5061314e+09 | I41: 2.7267304e+10 | J41: 26905618 | K41: 2.5203444e+10 | L41: 5.8761503e+09 | M41: 2.0429251e+09 | N41: 6288396.1 | O41: 1.2967265e+09 | P41: 2.7326463e+12 | Q41: 4.6923917e+11 | R41: 4.6156436e+12 | S41: 5.4830959e+11 | T41: 1.5783975e+12 | U41: 1.338026e+12 | V41: 1.0877317e+13 | W41: 3.7572039e+11 | X41: 1.6443495e+13 | Y41: 1.7296223e+12 | Z41: 9.724259e+11 | AA41: 2.4033988e+10 | AB41: 1.2358254e+11 | AC41: =SUM(C41:AB41) -> 41905461533372
...

Sheet Graphs
C1: AT | Q1: World_but_AT
A2: GHG | C2: Plant cultivation | D2: Plant processing | E2: Animal husbandry | F2: Animal processing | G2: Food waste and reuse | H2: Mining and forestry | I2: Manufacturing and construction | J2: Manufacturing fertilisers | K2: Trade, transport and utilities | L2: Services | M2: Waste | N2: Water | O2: Hotels and Resteraunts | Q2: Plant cultivation | R2: Plant processing | S2: Animal husbandry | T2: Animal processing | U2: Food waste and reuse | V2: Mining and forestry | W2: Manufacturing and construction | X2: Manufacturing fertilisers | Y2: Trade, transport and utilities | Z2: Services | AA2: Waste | AB2: Water | AC2: Hotels and Resteraunts | AD2: Total
B3: Footprint | C3: =Model!AF190 -> 1283682643 | D3: =Model!AG190 -> 4478457278 | E3: =Model!AH190 -> 5280562170 | F3: =Model!AI190 -> 2725626509 | G3: =Model!AJ190 -> 69130163 | H3: =Model!AK190 -> 6.2035017e+08 | I3: =Model!AL190 -> 37150056511 | J3: =Model!AM190 -> 65569412 | ... O3: =Model!AR190 -> 1898968295 | P3: Footprint | Q3: =Model!AS190 -> 1365898517746 | R3: =Model!AT190 -> 1749856053387 | S3: =Model!AU190 -> 2638439900707 | T3: =Model!AV190 -> 2146194513020 | U3: =Model!AW190 -> 646786272453 | V3: =Model!AX190 -> 159879684900 | W3: =Model!AY190 -> 14384325506184 | X3: =Model!AZ190 -> 323597418574 | ... AC3: =Model!BE190 -> 1045420573051 | AD3: =SUM(C3:AC3) -> 41905461533372
B4: Direct output | C4: =Model!$BF162 -> 2791355939 | D4: =Model!$BF163 -> 9.3429923e+08 | E4: =Model!$BF164 -> 8196574847 | F4: =Model!$BF165 -> 457618028 | G4: =Model!$BF166 -> 1396399359 | H4: =Model!$BF167 -> 1506131436 | I4: =Model!$BF168 -> 27267304166 | J4: =Model!$BF169 -> 26905618 | K4: =Model!$BF170 -> 25203443673 | L4: =Model!$BF171 -> 5876150331 | M4: =Model!$BF172 -> 2042925110 | N4: =Model!$BF173 -> 6288396.1 | O4: =Model!$BF174 -> 1296726456 | P4: Direct output | Q4: =Model!$BF175 -> 2732646263190 | R4: =Model!$BF176 -> 469239165653 | S4: =Model!$BF177 -> 4615643638264 | T4: =Model!$BF178 -> 548309594787 | U4: =Model!$BF179 -> 1578397521282 | V4: =Model!$BF180 -> 1338026025113 | W4: =Model!$BF181 -> 10877317349483 | X4: =Model!$BF182 -> 375720391671 | Y4: =Model!$BF183 -> 16443494755899 | Z4: =Model!$BF184 -> 1729622271248 | AA4: =Model!$BF185 -> 972425901662 | AB4: =Model!$BF186 -> 24033987911 | AC4: =Model!$BF187 -> 123582544622 | AD4: =SUM(C4:AC4) -> 41905461533372
C26: AT | Q26: World_but_AT
C27: Plant cultivation | D27: Plant processing | E27: Animal husbandry | F27: Animal processing | G27: Food waste and reuse | H27: Mining and forestry | I27: Manufacturing and construction | J27: Manufacturing fertilisers | K27: Trade, transport and utilities | L27: Services | M27: Waste | N27: Water | O27: Hotels and Resteraunts | Q27: Plant cultivation | R27: Plant processing | S27: Animal husbandry | T27: Animal processing | U27: Food waste and reuse | V27: Mining and forestry | W27: Manufacturing and construction | X27: Manufacturing fertilisers | Y27: Trade, transport and utilities | Z27: Services | AA27: Waste | AB27: Water | AC27: Hotels and Resteraunts | AD27: Total
A28: Mat (Plants) | B28: Footprint | C28: =Model!AF222 -> 3494.1688 | D28: =Model!AG222 -> 3869.7637 | E28: =Model!AH222 -> 1398.5748 | F28: =Model!AI222 -> 423.12234 | G28: =Model!AJ222 -> 0.55920507 | H28: =Model!AK222 -> 13.531266 | I28: =Model!AL222 -> 2484.0648 | J28: =Model!AM222 -> 4.0893018 | ... O28: =Model!AR222 -> 621.83979 | P28: Footprint | Q28: =Model!AS222 -> 3702461.6 | R28: =Model!AT222 -> 2069843.8 | S28: =Model!AU222 -> 235621.07 | T28: =Model!AV222 -> 213445.15 | U28: =Model!AW222 -> 1598.6026 | V28: =Model!AX222 -> 10277.983 | W28: =Model!AY222 -> 1496400.1 | X28: =Model!AZ222 -> 57472.056 | ... AC28: =Model!BE222 -> 353955.98 | AD28: =SUM(C28:AC28) -> 9370080
B29: Direct output | C29: =Model!$BF194 -> 9814.9808 | D29: =Model!$BF195 -> 0 | E29: =Model!$BF196 -> 0 | F29: =Model!$BF197 -> 0 | G29: =Model!$BF198 -> 0 | H29: =Model!$BF199 -> 0 | I29: =Model!$BF200 -> 0 | J29: =Model!$BF201 -> 0 | K29: =Model!$BF202 -> 0 | L29: =Model!$BF203 -> 0 | M29: =Model!$BF204 -> 0 | N29: =Model!$BF205 -> 0 | O29: =Model!$BF206 -> 0 | P29: Direct output | Q29: =Model!$BF207 -> 9360265 | R29: =Model!$BF208 -> 0 | S29: =Model!$BF209 -> 0 | T29: =Model!$BF210 -> 0 | U29: =Model!$BF211 -> 0 | V29: =Model!$BF212 -> 0 | W29: =Model!$BF213 -> 0 | X29: =Model!$BF214 -> 0 | Y29: =Model!$BF215 -> 0 | Z29: =Model!$BF216 -> 0 | AA29: =Model!$BF217 -> 0 | AB29: =Model!$BF218 -> 0 | AC29: =Model!$BF219 -> 0 | AD29: =SUM(C29:AC29) -> 9370080
C53: Plant cultivation | D53: Plant processing | E53: Animal husbandry | F53: Animal processing | G53: Food waste and reuse | H53: Mining and forestry | I53: Manufacturing and construction | J53: Manufacturing fertilisers | K53: Trade, transport and utilities | L53: Services | M53: Waste | N53: Water | O53: Hotels and Resteraunts | Q53: Plant cultivation | R53: Plant processing | S53: Animal husbandry | T53: Animal processing | U53: Food waste and reuse | V53: Mining and forestry | W53: Manufacturing and construction | X53: Manufacturing fertilisers | Y53: Trade, transport and utilities | Z53: Services | AA53: Waste | AB53: Water | AC53: Hotels and Resteraunts | AD53: Total
A54: Mat (Feed) | B54: Footprint | C54: =Model!AF254 -> 21.747664 | D54: =Model!AG254 -> 1293.7716 | E54: =Model!AH254 -> 8639.511 | F54: =Model!AI254 -> 2803.7594 | G54: =Model!AJ254 -> 0.73499746 | H54: =Model!AK254 -> 16.30756 | I54: =Model!AL254 -> 1989.382 | J54: =Model!AM254 -> 6.6484638 | ... O54: =Model!AR254 -> 651.44837 | P54: Footprint | Q54: =Model!AS254 -> 42574.949 | R54: =Model!AT254 -> 383541.81 | S54: =Model!AU254 -> 7084977.8 | T54: =Model!AV254 -> 3707389.1 | U54: =Model!AW254 -> 2642.4523 | V54: =Model!AX254 -> 7143.9131 | W54: =Model!AY254 -> 889270.95 | X54: =Model!AZ254 -> 43465.64 | ... AC54: =Model!BE254 -> 682836.69 | AD54: =SUM(C54:AC54) -> 14043340
B55: Direct output | C55: =Model!$BF226 -> 0 | D55: =Model!$BF227 -> 0 | E55: =Model!$BF228 -> 15943.325 | F55: =Model!$BF229 -> 0 | G55: =Model!$BF230 -> 0 | H55: =Model!$BF231 -> 0 | I55: =Model!$BF232 -> 0 | J55: =Model!$BF233 -> 0 | K55: =Model!$BF234 -> 0 | L55: =Model!$BF235 -> 0 | M55: =Model!$BF236 -> 0 | N55: =Model!$BF237 -> 0 | O55: =Model!$BF238 -> 0 | P55: Direct output | Q55: =Model!$BF239 -> 0 | R55: =Model!$BF240 -> 0 | S55: =Model!$BF241 -> 14027397 | T55: =Model!$BF242 -> 0 | U55: =Model!$BF243 -> 0 | V55: =Model!$BF244 -> 0 | W55: =Model!$BF245 -> 0 | X55: =Model!$BF246 -> 0 | Y55: =Model!$BF247 -> 0 | Z55: =Model!$BF248 -> 0 | AA55: =Model!$BF249 -> 0 | AB55: =Model!$BF250 -> 0 | AC55: =Model!$BF251 -> 0 | AD55: =SUM(C55:AC55) -> 14043340
