Workbook

Sheet Model
B1: SuperRegion | C1: AT | Q1: World_but_AT | AE1: AT | AL1: World_but_AT | AW1: SuperRegion
A2: SuperRegion | B2: Aggregated_Sector | C2: Plant cultivation | D2: Plant processing | E2: Animal husbandry | F2: Animal processing | G2: Other food processing | H2: Food waste and reuse | I2: Mining and forestry | J2: Manufacturing and construction | K2: Manufacturing fertilisers | L2: Trade, transport and utilities | M2: Services | N2: Waste | O2: Water | P2: Hotels and Resteraunts | Q2: Plant cultivation | R2: Plant processing | S2: Animal husbandry | T2: Animal processing | U2: Other food processing | V2: Food waste and reuse | W2: Mining and forestry | X2: Manufacturing and construction | Y2: Manufacturing fertilisers | Z2: Trade, transport and utilities | AA2: Services | AB2: Waste | AC2: Water | AD2: Hotels and Resteraunts | AE2: Final consumption expenditure by households | AF2: Final consumption expenditure by non-profit organisations serving households (NPISH) | AG2: Final consumption expenditure by government | AH2: Gross fixed capital formation | AI2: Changes in inventories | AJ2: Changes in valuables | AK2: Exports: Total (fob) | AL2: Final consumption expenditure by households | AM2: Final consumption expenditure by non-profit organisations serving households (NPISH) | AN2: Final consumption expenditure by government | AO2: Gross fixed capital formation | AP2: Changes in inventories | AQ2: Changes in valuables | AR2: Exports: Total (fob) | AS2: Y_Region | AT2: Y_Exports | AU2: Y_Total Demand | AV2: X_Total Output | AW2: Aggregated_Sector | AX2: SuperRegion
A3: AT | B3: Plant cultivation | C3: 230.68256 | D3: 654.34422 | E3: 327.47078 | F3: 0.046542671 | G3: 67.053932 | H3: 0.0030308331 | I3: 0.11128201 | J3: 55.343047 | K3: 0.02712636 | L3: 24.388163 | M3: 32.10878 | N3: 0.0055718962 | O3: 0.0082605919 | P3: 78.282097 | Q3: 40.307207 | R3: 67.663369 | S3: 211.88669 | T3: 4.6537656 | U3: 418.47179 | V3: 0.67022896 | W3: 17.872029 | X3: 165.13934 | Y3: 4.1851572 | Z3: 66.780569 | AA3: 195.4649 | AB3: 1.4585388 | AC3: 0.043948306 | AD3: 65.560355 | AE3: 462.26954 | AF3: 0.00073144387 | AG3: 0.045280047 | AH3: 31.993768 | AI3: 7.4191078 | AJ3: 2.4113949 | AK3: 0 | AL3: 636.98651 | AM3: 0.022991753 | AN3: 3.654546 | AO3: 0.76484499 | AP3: 177.98502 | AQ3: 0.0477127 | AR3: 0 | AS3: =SUM(AE3:AK3) -> 504.13983 | AT3: =SUM(AL3:AR3) -> 819.46162 | AU3: =AS3+AT3 -> 1323.6014 | AV3: =SUM(C3:AR3) -> 4053.6347 | AW3: Plant cultivation | AX3: AT
B4: Plant processing | C4: 0.2117285 | D4: 27.859909 | E4: 107.3157 | F4: 3.952822 | G4: 170.6884 | H4: 1.3555571 | I4: 0.21507678 | J4: 32.191016 | K4: 0.02548544 | L4: 39.602902 | M4: 87.246597 | N4: 2.623549 | O4: 0.044466139 | P4: 288.73451 | Q4: 4.9007479 | R4: 72.058816 | S4: 82.942406 | T4: 30.557941 | U4: 224.58425 | V4: 0.27655886 | W4: 26.554815 | X4: 121.3129 | Y4: 9.3080163 | Z4: 148.80958 | AA4: 203.16102 | AB4: 5.3177026 | AC4: 0.3594507 | AD4: 463.35849 | AE4: 921.34975 | AF4: 0.022144759 | AG4: 2.8117574 | AH4: 10.093957 | AI4: 3.3495938 | AJ4: 1.0187115 | AK4: 0 | AL4: 2553.0318 | AM4: 0.40288885 | AN4: 2.0321675 | AO4: 1.8393076 | AP4: 19.88039 | AQ4: 0.619317 | AR4: 0 | AS4: =SUM(AE4:AK4) -> 938.64592 | AT4: =SUM(AL4:AR4) -> 2577.8058 | AU4: =AS4+AT4 -> 3516.4518 | AV4: =SUM(C4:AR4) -> 5672.0222 | AW4: Plant processing
B5: Animal husbandry | C5: 0.16951039 | D5: 1.444457 | E5: 11.701192 | F5: 844.69137 | G5: 277.73257 | H5: 0.19585694 | I5: 0.25300887 | J5: 29.783883 | K5: 4.599802 | L5: 392.25776 | M5: 31.497029 | N5: 0.38282067 | O5: 0.15820829 | P5: 57.455375 | Q5: 0.49849758 | R5: 2.9325259 | S5: 12.002778 | T5: 81.237286 | U5: 25.14083 | V5: 0.84229498 | W5: 1.897816 | X5: 115.76982 | Y5: 8.7120086 | Z5: 62.599404 | AA5: 54.234654 | AB5: 3.1133664 | AC5: 0.043859106 | AD5: 12.689872 | AE5: 695.64016 | AF5: 0.09562869 | AG5: 30.245596 | AH5: 1221.9379 | AI5: 9.0957376 | AJ5: 2.1483711 | AK5: 0 | AL5: 197.8533 | AM5: 3.6948703 | AN5: 3.2387618 | AO5: 55.727588 | AP5: 47.227662 | AQ5: 6.8573312 | AR5: 0 | AS5: =SUM(AE5:AK5) -> 1959.1633 | AT5: =SUM(AL5:AR5) -> 314.59952 | AU5: =AS5+AT5 -> 2273.7629 | AV5: =SUM(C5:AR5) -> 4307.8007 | AW5: Animal husbandry
B6: Animal processing | C6: 2.831445 | D6: 5.2700527 | E6: 53.132147 | F6: 427.50066 | G6: 160.04119 | H6: 1.0862806 | I6: 1.7601426 | J6: 126.59791 | K6: 0.42147721 | L6: 112.2109 | M6: 414.2444 | N6: 2.1398329 | O6: 0.41696889 | P6: 459.47672 | Q6: 20.745973 | R6: 8.2161597 | S6: 45.197126 | T6: 591.63251 | U6: 270.11004 | V6: 1.3018863 | W6: 30.89146 | X6: 267.60628 | Y6: 4.7668404 | Z6: 169.75706 | AA6: 303.64519 | AB6: 2.3660677 | AC6: 0.54875379 | AD6: 325.11026 | AE6: 1506.4837 | AF6: 0.023250513 | AG6: 24.669192 | AH6: 61.642587 | AI6: 9.4864543 | AJ6: 2.4528549 | AK6: 0 | AL6: 2648.9159 | AM6: 3.6005505 | AN6: 5.1450724 | AO6: 6.8076315 | AP6: -184.64999 | AQ6: 6.8672941 | AR6: 0 | AS6: =SUM(AE6:AK6) -> 1604.758 | AT6: =SUM(AL6:AR6) -> 2486.6864 | AU6: =AS6+AT6 -> 4091.4444 | AV6: =SUM(C6:AR6) -> 7900.4702 | AW6: Animal processing
B7: Other food processing | C7: 0.49350945 | D7: 54.479482 | E7: 340.05382 | F7: 43.842321 | G7: 1265.7567 | H7: 0.55592575 | I7: 0.58805681 | J7: 107.63796 | K7: 0.051087944 | L7: 72.50138 | M7: 264.92382 | N7: 1.0947618 | O7: 0.12096942 | P7: 749.53395 | Q7: 10.369098 | R7: 145.62619 | S7: 263.23303 | T7: 214.14796 | U7: 1040.6661 | V7: 0.75043347 | W7: 36.26323 | X7: 473.2427 | Y7: 16.356142 | Z7: 232.77344 | AA7: 480.73822 | AB7: 4.6489938 | AC7: 0.49825217 | AD7: 577.22008 | AE7: 6136.3634 | AF7: 0.021654692 | AG7: 8.156148 | AH7: 41.123969 | AI7: 15.634165 | AJ7: 5.1336439 | AK7: 0 | AL7: 7105.2073 | AM7: 1.2856519 | AN7: 13.713629 | AO7: 6.8959558 | AP7: -32.527025 | AQ7: 1.3247837 | AR7: 0 | AS7: =SUM(AE7:AK7) -> 6206.433 | AT7: =SUM(AL7:AR7) -> 7095.9003 | AU7: =AS7+AT7 -> 13302.333 | AV7: =SUM(C7:AR7) -> 19700.501 | AW7: Other food processing
B8: Food waste and reuse | C8: 33.580893 | D8: 3.016944 | E8: 1.5049304 | F8: 11.56261 | G8: 5.3341646 | H8: 280.66968 | I8: 3.3331151 | J8: 257.92879 | K8: 0.29149596 | L8: 186.39188 | M8: 904.58648 | N8: 551.72562 | O8: 1.074856 | P8: 22.651083 | Q8: 1.4224744 | R8: 0.7613831 | S8: 2.555742 | T8: 3.9479118 | U8: 0.92543177 | V8: 1.4111614 | W8: 1.1724963 | X8: 28.279307 | Y8: 0.35602924 | Z8: 11.060499 | AA8: 11.705756 | AB8: 4.2303619 | AC8: 0.19893767 | AD8: 0.88137436 | AE8: 42.190373 | AF8: 0.033735532 | AG8: 5.5730161 | AH8: 11.550764 | AI8: 2.1513445 | AJ8: 0.33941871 | AK8: 0 | AL8: 5.1613416 | AM8: 0.090433363 | AN8: 0.91856082 | AO8: 1.5380764 | AP8: 0.4359035 | AQ8: 0.19434114 | AR8: 0 | AS8: =SUM(AE8:AK8) -> 61.838653 | AT8: =SUM(AL8:AR8) -> 8.3386569 | AU8: =AS8+AT8 -> 70.177309 | AV8: =SUM(C8:AR8) -> 2402.7387 | AW8: Food waste and reuse
B9: Mining and forestry | C9: 45.361313 | D9: 22.628952 | E9: 17.735727 | F9: 16.437473 | G9: 14.3896 | H9: 23.138338 | I9: 1030.9495 | J9: 2017.0357 | K9: 19.195376 | L9: 516.3769 | M9: 292.80645 | N9: 43.11903 | O9: 1.6884188 | P9: 158.40092 | Q9: 96.461871 | R9: 16.323161 | S9: 19.950996 | T9: 37.78291 | U9: 29.359099 | V9: 2.3553271 | W9: 20.905571 | X9: 579.18291 | Y9: 7.2983703 | Z9: 193.81848 | AA9: 83.522171 | AB9: 7.487954 | AC9: 2.8386907 | AD9: 60.228544 | AE9: 725.09772 | AF9: 0.019357234 | AG9: 23.700002 | AH9: 134.98622 | AI9: 57.338144 | AJ9: -5.5388358 | AK9: 0 | AL9: 466.45877 | AM9: 0.25295558 | AN9: 3.9632913 | AO9: 12.780987 | AP9: 170.48939 | AQ9: 0.30797299 | AR9: 0 | AS9: =SUM(AE9:AK9) -> 935.6026 | AT9: =SUM(AL9:AR9) -> 654.25338 | AU9: =AS9+AT9 -> 1589.856 | AV9: =SUM(C9:AR9) -> 6966.6358 | AW9: Mining and forestry
B10: Manufacturing and construction | C10: 419.08085 | D10: 448.03051 | E10: 329.73639 | F10: 415.89305 | G10: 332.89467 | H10: 147.83392 | I10: 426.19599 | J10: 50825.426 | K10: 7.6000216 | L10: 7584.2766 | M10: 20824.427 | N10: 258.64242 | O10: 262.0371 | P10: 1219.6615 | Q10: 516.49194 | R10: 424.70747 | S10: 341.39189 | T10: 631.4426 | U10: 483.40753 | V10: 48.812765 | W10: 533.20443 | X10: 50558.375 | Y10: 249.32204 | Z10: 4284.8239 | AA10: 4748.7052 | AB10: 145.14226 | AC10: 39.231757 | AD10: 273.08534 | AE10: 10196.334 | AF10: 2.5313132 | AG10: 3581.5064 | AH10: 52684.799 | AI10: 9.4347446 | AJ10: -57.527355 | AK10: 0 | AL10: 10454.401 | AM10: 31.126184 | AN10: 480.48206 | AO10: 11678.237 | AP10: 1029.7066 | AQ10: 2.2216811 | AR10: 0 | AS10: =SUM(AE10:AK10) -> 66417.078 | AT10: =SUM(AL10:AR10) -> 23676.174 | AU10: =AS10+AT10 -> 90093.252 | AV10: =SUM(C10:AR10) -> 236873.13 | AW10: Manufacturing and construction
B11: Manufacturing fertilisers | C11: 4.4397152 | D11: 0.14370879 | E11: 47.115817 | F11: 0.18220145 | G11: 69.830265 | H11: 2.041242 | I11: 0.30705626 | J11: 13.486772 | K11: 0.005182991 | L11: 4.9582528 | M11: 22.251523 | N11: 3.9434323 | O11: 0.031747225 | P11: 61.424073 | Q11: 24.564199 | R11: 1.451302 | S11: 13.370131 | T11: 4.8643408 | U11: 69.433402 | V11: 0.074224764 | W11: 0.59999934 | X11: 44.026467 | Y11: 0.60020362 | Z11: 6.497883 | AA11: 12.202177 | AB11: 0.12275022 | AC11: 0.012970384 | AD11: 13.483618 | AE11: 33.584643 | AF11: 0.17051901 | AG11: 2.6425581 | AH11: 6.6946927 | AI11: 0.10649594 | AJ11: 0.24803853 | AK11: 0 | AL11: 63.590355 | AM11: 0.080487725 | AN11: 10.093452 | AO11: 0.47861485 | AP11: -2.6254441 | AQ11: 0.001951968 | AR11: 0 | AS11: =SUM(AE11:AK11) -> 43.446947 | AT11: =SUM(AL11:AR11) -> 71.619418 | AU11: =AS11+AT11 -> 115.06636 | AV11: =SUM(C11:AR11) -> 536.53102 | AW11: Manufacturing fertilisers
B12: Trade, transport and utilities | C12: 243.71322 | D12: 511.30458 | E12: 212.4641 | F12: 762.33997 | G12: 642.57753 | H12: 135.43199 | I12: 468.37331 | J12: 12367.669 | K12: 34.071041 | L12: 18158.684 | M12: 10886.37 | N12: 234.36081 | O12: 57.489619 | P12: 1662.1633 | Q12: 395.61986 | R12: 392.11591 | S12: 328.6818 | T12: 633.31564 | U12: 430.07593 | V12: 150.01656 | W12: 282.16329 | X12: 9778.9744 | Y12: 117.14269 | Z12: 10068.611 | AA12: 3865.9916 | AB12: 134.6616 | AC12: 47.452909 | AD12: 267.72021 | AE12: 54706.468 | AF12: 2.6791772 | AG12: 6051.9289 | AH12: 4487.799 | AI12: 239.53229 | AJ12: 24.522061 | AK12: 0 | AL12: 6380.5511 | AM12: 32.919032 | AN12: 106.95707 | AO12: 638.08995 | AP12: 142.48308 | AQ12: 54.758878 | AR12: 0 | AS12: =SUM(AE12:AK12) -> 65512.929 | AT12: =SUM(AL12:AR12) -> 7355.7591 | AU12: =AS12+AT12 -> 72868.688 | AV12: =SUM(C12:AR12) -> 146138.24 | AW12: Trade, transport and utilities
B13: Services | C13: 311.29306 | D13: 742.03922 | E13: 314.99661 | F13: 946.01256 | G13: 929.71186 | H13: 186.68098 | I13: 284.3616 | J13: 15342.211 | K13: 6.010287 | L13: 19864.123 | M13: 54019.433 | N13: 382.61461 | O13: 82.072232 | P13: 1665.3539 | Q13: 143.49939 | R13: 112.03606 | S13: 100.46284 | T13: 195.83962 | U13: 210.36957 | V13: 35.122327 | W13: 207.29103 | X13: 4319.7348 | Y13: 50.033946 | Z13: 2040.182 | AA13: 5289.566 | AB13: 104.7755 | AC13: 16.486445 | AD13: 156.4923 | AE13: 79893.262 | AF13: 10429.674 | AG13: 67269.722 | AH13: 14375.932 | AI13: 66.680606 | AJ13: 17.001163 | AK13: 0 | AL13: 1580.065 | AM13: 191.5938 | AN13: 504.53434 | AO13: 2003.6778 | AP13: 150.10698 | AQ13: 41.674337 | AR13: 0 | AS13: =SUM(AE13:AK13) -> 172052.27 | AT13: =SUM(AL13:AR13) -> 4471.6523 | AU13: =AS13+AT13 -> 176523.92 | AV13: =SUM(C13:AR13) -> 284582.73 | AW13: Services
B14: Waste | C14: 13.746245 | D14: 5.7385564 | E14: 3.8815479 | F14: 42.50759 | G14: 10.391454 | H14: 543.01996 | I14: 6.6519169 | J14: 639.35057 | K14: 0.5878753 | L14: 371.412 | M14: 1679.0396 | N14: 1073.2294 | O14: 1.8142479 | P14: 41.98349 | Q14: 3.3856998 | R14: 2.1623607 | S14: 5.5174308 | T14: 8.5380765 | U14: 1.8800659 | V14: 3.9893131 | W14: 2.237714 | X14: 65.502247 | Y14: 1.6568757 | Z14: 20.551999 | AA14: 27.130856 | AB14: 10.39925 | AC14: 0.46821373 | AD14: 1.7849796 | AE14: 44.65593 | AF14: 0.068046198 | AG14: 8.7955957 | AH14: 23.911059 | AI14: 4.2574479 | AJ14: 0.70612918 | AK14: 0 | AL14: 12.537204 | AM14: 0.2045086 | AN14: 1.4843213 | AO14: 3.2651334 | AP14: 1.0223699 | AQ14: 0.31180782 | AR14: 0 | AS14: =SUM(AE14:AK14) -> 82.394208 | AT14: =SUM(AL14:AR14) -> 18.825345 | AU14: =AS14+AT14 -> 101.21955 | AV14: =SUM(C14:AR14) -> 4689.779 | AW14: Waste
B15: Water | C15: 4.6948942 | D15: 10.77112 | E15: 5.4133695 | F15: 3.1222796 | G15: 8.7843102 | H15: 5.0753002 | I15: 1.5455627 | J15: 100.32612 | K15: 0.18384942 | L15: 93.593226 | M15: 783.85438 | N15: 10.007126 | O15: 22.201018 | P15: 49.201894 | Q15: 0.17702877 | R15: 0.050610067 | S15: 0.034398116 | T15: 0.066599734 | U15: 0.042047921 | V15: 0.014814003 | W15: 0.03558927 | X15: 1.5237923 | Y15: 0.0093182515 | Z15: 1.033184 | AA15: 1.3232549 | AB15: 0.038959233 | AC15: 0.031148481 | AD15: 0.038671855 | AE15: 1.365161 | AF15: 0 | AG15: 0.023201697 | AH15: 10.483103 | AI15: 0.032328147 | AJ15: 0.0080431782 | AK15: 0 | AL15: 0.29511264 | AM15: 0.018367011 | AN15: 0.012938802 | AO15: 0.73247332 | AP15: 0.004478121 | AQ15: 0.00092277349 | AR15: 0 | AS15: =SUM(AE15:AK15) -> 11.911837 | AT15: =SUM(AL15:AR15) -> 1.0642927 | AU15: =AS15+AT15 -> 12.97613 | AV15: =SUM(C15:AR15) -> 1116.17 | AW15: Water
B16: Hotels and Resteraunts | C16: 5.3136132 | D16: 42.063562 | E16: 5.5976654 | F16: 48.128643 | G16: 44.173008 | H16: 4.2654028 | I16: 6.9070914 | J16: 548.14745 | K16: 0.42382406 | L16: 881.71414 | M16: 1074.1298 | N16: 8.4402485 | O16: 3.0628902 | P16: 302.89195 | Q16: 32.604482 | R16: 31.461495 | S16: 26.996196 | T16: 22.313997 | U16: 38.258032 | V16: 9.5861026 | W16: 45.973384 | X16: 2852.1642 | Y16: 78.942505 | Z16: 9260.027 | AA16: 3505.6874 | AB16: 21.250438 | AC16: 4.1547744 | AD16: 157.04745 | AE16: 2664.1669 | AF16: 5.1928534 | AG16: 77.334588 | AH16: 43.502679 | AI16: 1.3423924 | AJ16: 0.26979731 | AK16: 0 | AL16: 1951.7642 | AM16: 554.31663 | AN16: 23.582716 | AO16: 20.344667 | AP16: 4883.7646 | AQ16: 1303.9148 | AR16: 0 | AS16: =SUM(AL16:AR16) -> 8737.6876 | AT16: =SUM(AE16:AK16) -> 2791.8092 | AU16: =AS16+AT16 -> 11529.497 | AV16: =SUM(C16:AR16) -> 30591.224 | AW16: Hotels and Resteraunts
A17: World_but_AT | B17: Plant cultivation | C17: 62.865283 | D17: 174.30867 | E17: 468.81003 | F17: 0.63319115 | G17: 548.98098 | H17: 0.076480653 | I17: 0.46196787 | J17: 169.97402 | K17: 0.12223681 | L17: 18.996482 | M17: 46.800421 | N17: 0.19162632 | O17: 0.0058187874 | P17: 174.13546 | Q17: 716052.2 | R17: 163039.66 | S17: 87428.008 | T17: 5979.019 | U17: 716713.14 | V17: 199.92899 | W17: 22338.447 | X17: 463959.79 | Y17: 29676.563 | Z17: 48374.116 | AA17: 150225 | AB17: 839.05322 | AC17: 696.78732 | AD17: 47428.826 | AE17: 1263.9151 | AF17: 0 | AG17: 0.18997939 | AH17: 36.48352 | AI17: 3.0654746 | AJ17: 0.042705018 | AK17: 0 | AL17: 904926.91 | AM17: 552.4543 | AN17: 18964.209 | AO17: 63323.495 | AP17: 130813.44 | AQ17: -46.807683 | AR17: 0 | AS17: =SUM(AL17:AR17) -> 1118533.7 | AT17: =SUM(AE17:AK17) -> 1303.6968 | AU17: =AS17+AT17 -> 1119837.4 | AV17: =SUM(C17:AR17) -> 3574454.3 | AW17: Plant cultivation | AX17: World_but_AT
B18: Plant processing | C18: 0.84844477 | D18: 10.591117 | E18: 16.765215 | F18: 3.0118201 | G18: 213.07308 | H18: 0.0081686663 | I18: 0.2038661 | J18: 251.09683 | K18: 0.047325772 | L18: 8.1585548 | M18: 30.441065 | N18: 0.016193736 | O18: 0.0099659184 | P18: 122.01518 | Q18: 3680.7401 | R18: 39365.348 | S18: 31082.129 | T18: 26751.831 | U18: 58851.482 | V18: 205.28232 | W18: 1951.8609 | X18: 46145.579 | Y18: 3195.5362 | Z18: 47349.226 | AA18: 56452.966 | AB18: 868.7737 | AC18: 264.01517 | AD18: 125960.29 | AE18: 866.15292 | AF18: 0 | AG18: 0.085924824 | AH18: 2.2848994 | AI18: 0.85168199 | AJ18: 0.0025779918 | AK18: 0 | AL18: 627569.99 | AM18: 120.66456 | AN18: 1658.0311 | AO18: 1813.8306 | AP18: 1979.271 | AQ18: 142.71923 | AR18: 0 | AS18: =SUM(AL18:AR18) -> 633284.51 | AT18: =SUM(AE18:AK18) -> 869.378 | AU18: =AS18+AT18 -> 634153.89 | AV18: =SUM(C18:AR18) -> 1076935.2 | AW18: Plant processing
B19: Animal husbandry | C19: 0.10307963 | D19: 0.50622205 | E19: 2.4728014 | F19: 126.36192 | G19: 4.5325985 | H19: 0.030665324 | I19: 0.8548333 | J19: 35.078288 | K19: 0.031622784 | L19: 37.099081 | M19: 31.350593 | N19: 0.068501938 | O19: 0.007228604 | P19: 17.423598 | Q19: 3827.7336 | R19: 1044.3368 | S19: 153421.23 | T19: 730109.3 | U19: 24710.423 | V19: 463.46391 | W19: 5649.1921 | X19: 82247.614 | Y19: 9469.9758 | Z19: 26223.917 | AA19: 35709.826 | AB19: 377.88882 | AC19: 919.77351 | AD19: 64998.857 | AE19: 109.36556 | AF19: 0 | AG19: 0.27134592 | AH19: 113.83794 | AI19: -0.75228224 | AJ19: 0.074549015 | AK19: 0 | AL19: 591491.84 | AM19: 2517.1973 | AN19: 34496.018 | AO19: 95928.07 | AP19: 261735.58 | AQ19: 266.25989 | AR19: 0 | AS19: =SUM(AL19:AR19) -> 986434.97 | AT19: =SUM(AE19:AK19) -> 222.79712 | AU19: =AS19+AT19 -> 986657.76 | AV19: =SUM(C19:AR19) -> 2126087.2 | AW19: Animal husbandry
B20: Animal processing | C20: 0.87368947 | D20: 2.6332636 | E20: 87.241239 | F20: 351.09168 | G20: 104.65219 | H20: 0.069465587 | I20: 0.72075318 | J20: 197.76009 | K20: 0.27785082 | L20: 572.52544 | M20: 134.15787 | N20: 0.14378785 | O20: 0.031679183 | P20: 293.16561 | Q20: 7637.5443 | R20: 6617.6212 | S20: 35153.253 | T20: 179327.06 | U20: 112014.79 | V20: 348.3578 | W20: 3477.4633 | X20: 84174.695 | Y20: 5557.5714 | Z20: 43166.375 | AA20: 143802.53 | AB20: 1439.538 | AC20: 577.88087 | AD20: 182740.95 | AE20: 1277.4471 | AF20: 0 | AG20: 0.3092875 | AH20: 10.997229 | AI20: 5.1922524 | AJ20: 0.015729394 | AK20: 0 | AL20: 1390058.3 | AM20: 16936.941 | AN20: 14125.231 | AO20: 6845.7963 | AP20: 49962.772 | AQ20: 348.9897 | AR20: 0 | AS20: =SUM(AL20:AR20) -> 1478278.1 | AT20: =SUM(AE20:AK20) -> 1293.9616 | AU20: =AS20+AT20 -> 1479572 | AV20: =SUM(C20:AR20) -> 2287353 | AW20: Animal processing
B21: Other food processing | C21: 0.65878554 | D21: 22.996531 | E21: 59.510085 | F21: 58.945827 | G21: 677.94875 | H21: 0.021479186 | I21: 0.2175552 | J21: 231.31432 | K21: 0.099566753 | L21: 153.76579 | M21: 80.546112 | N21: 0.04390956 | O21: 0.03042815 | P21: 271.05658 | Q21: 6418.8642 | R21: 47810.967 | S21: 139003.53 | T21: 62881.357 | U21: 370511.65 | V21: 249.80475 | W21: 3863.0361 | X21: 71126.733 | Y21: 9530.2337 | Z21: 37332.842 | AA21: 129562.41 | AB21: 607.35267 | AC21: 472.79524 | AD21: 190755.77 | AE21: 4116.0167 | AF21: 0 | AG21: 0.13240738 | AH21: 3.5914267 | AI21: 1.2255754 | AJ21: 0.0076490446 | AK21: 0 | AL21: 1604153.9 | AM21: 351.71215 | AN21: 15892.813 | AO21: 4143.1437 | AP21: 13780.785 | AQ21: 333.55028 | AR21: 0 | AS21: =SUM(AL21:AR21) -> 1638655.9 | AT21: =SUM(AE21:AK21) -> 4120.9737 | AU21: =AS21+AT21 -> 1642776.9 | AV21: =SUM(C21:AR21) -> 2714461.4 | AW21: Other food processing
B22: Food waste and reuse | C22: 0.12573364 | D22: 0.42127208 | E22: 0.13608307 | F22: 0.54739531 | G22: 0.95108838 | H22: 2.5568797 | I22: 0.026998352 | J22: 33.851527 | K22: 0.020247936 | L22: 8.501986 | M22: 3.243345 | N22: 4.8490116 | O22: 0.014118374 | P22: 0.24700065 | Q22: 760.03301 | R22: 546.5386 | S22: 813.7327 | T22: 1430.1795 | U22: 1031.1136 | V22: 5446.9462 | W22: 1694.7209 | X22: 30546.024 | Y22: 300.04443 | Z22: 9456.793 | AA22: 26211.784 | AB22: 10921.758 | AC22: 1426.4674 | AD22: 1982.4499 | AE22: 51.968558 | AF22: 0 | AG22: 0.036550747 | AH22: 1.0305962 | AI22: 0.85823896 | AJ22: 0.32151922 | AK22: 0 | AL22: 36987.403 | AM22: 187.40297 | AN22: 15693.765 | AO22: 2207.9711 | AP22: 652.92166 | AQ22: 99.631173 | AR22: 0 | AS22: =SUM(AL22:AR22) -> 55829.095 | AT22: =SUM(AE22:AK22) -> 54.215463 | AU22: =AS22+AT22 -> 55883.31 | AV22: =SUM(C22:AR22) -> 148507.39 | AW22: Food waste and reuse
B23: Mining and forestry | C23: 20.093132 | D23: 3.1743099 | E23: 80.833401 | F23: 6.6744592 | G23: 39.412476 | H23: 0.96118835 | I23: 329.33688 | J23: 6540.6182 | K23: 344.79778 | L23: 718.12919 | M23: 76.752341 | N23: 2.2620695 | O23: 0.13814482 | P23: 19.621946 | Q23: 14687.034 | R23: 4445.463 | S23: 13024.996 | T23: 15589.132 | U23: 13208.413 | V23: 784.46181 | W23: 526712.8 | X23: 2941972.4 | Y23: 34589.501 | Z23: 553260.51 | AA23: 67606.982 | AB23: 3235.5789 | AC23: 2429.4818 | AD23: 6575.5375 | AE23: 52.732562 | AF23: 0 | AG23: 1.4754536 | AH23: 19.540849 | AI23: 124.38046 | AJ23: 0.015749385 | AK23: 0 | AL23: 187013.57 | AM23: 334.51218 | AN23: 15610.209 | AO23: 27480.316 | AP23: 54336.215 | AQ23: 91.409291 | AR23: 0 | AS23: =SUM(AL23:AR23) -> 284866.23 | AT23: =SUM(AE23:AK23) -> 198.14507 | AU23: =AS23+AT23 -> 285064.37 | AV23: =SUM(C23:AR23) -> 4491369.5 | AW23: Mining and forestry
B24: Manufacturing and construction | C24: 618.17888 | D24: 411.84697 | E24: 181.10095 | F24: 505.72133 | G24: 344.9199 | H24: 22.860637 | I24: 114.0884 | J24: 41525.824 | K24: 10.37789 | L24: 2802.7384 | M24: 6039.0281 | N24: 32.976567 | O24: 10.850518 | P24: 376.46095 | Q24: 282819.01 | R24: 148774.73 | S24: 152714.06 | T24: 222343.72 | U24: 178746.55 | V24: 18597.773 | W24: 544153.24 | X24: 20423184 | Y24: 173627.04 | Z24: 2451611.9 | AA24: 3845384.8 | AB24: 41352.11 | AC24: 26848.343 | AD24: 184857.62 | AE24: 25473.298 | AF24: 0 | AG24: 48.693647 | AH24: 25730.391 | AI24: -3856.3175 | AJ24: 2.1910407 | AK24: 0 | AL24: 5631171.1 | AM24: 21194.941 | AN24: 345242.15 | AO24: 15450900 | AP24: 339885.87 | AQ24: 33751.133 | AR24: 0 | AS24: =SUM(AL24:AR24) -> 21822145 | AT24: =SUM(AE24:AK24) -> 47398.256 | AU24: =AS24+AT24 -> 21869543 | AV24: =SUM(C24:AR24) -> 50617555 | AW24: Manufacturing and construction
B25: Manufacturing fertilisers | C25: 12.162535 | D25: 0.38928906 | E25: 1.6656781 | F25: 0.42789537 | G25: 0.50330404 | H25: 0.1326655 | I25: 0.46277902 | J25: 111.75486 | K25: 0.1853383 | L25: 4.2746904 | M25: 7.7060574 | N25: 0.26635619 | O25: 0.011981261 | P25: 0.66985815 | Q25: 229904.38 | R25: 732.0647 | S25: 6213.5911 | T25: 2496.9045 | U25: 1547.3233 | V25: 67.068251 | W25: 13897.572 | X25: 68620.429 | Y25: 117970.94 | Z25: 11692.701 | AA25: 21279.996 | AB25: 135.33964 | AC25: 236.18753 | AD25: 1280.2167 | AE25: 27.843777 | AF25: 0 | AG25: 4.2440125 | AH25: 8.4463037 | AI25: 2.1371508 | AJ25: 0.015961425 | AK25: 0 | AL25: 47836.9 | AM25: 80.066686 | AN25: 215061.42 | AO25: 3610.353 | AP25: 9292.5677 | AQ25: 70.449586 | AR25: 0 | AS25: =SUM(AL25:AR25) -> 275951.76 | AT25: =SUM(AE25:AK25) -> 42.687206 | AU25: =AS25+AT25 -> 275994.44 | AV25: =SUM(C25:AR25) -> 752209.76 | AW25: Manufacturing fertilisers
B26: Trade, transport and utilities | C26: 37.773046 | D26: 259.13246 | E26: 93.198803 | F26: 674.34704 | G26: 377.31374 | H26: 25.432112 | I26: 178.50676 | J26: 8410.5077 | K26: 47.50907 | L26: 6079.6783 | M26: 1856.4085 | N26: 59.877558 | O26: 14.665921 | P26: 167.77145 | Q26: 239401.94 | R26: 222257.73 | S26: 245596.97 | T26: 302634.8 | U26: 257449.06 | V26: 13907.124 | W26: 386960.06 | X26: 5500831.8 | Y26: 153703.48 | Z26: 4491665.5 | AA26: 3440014.6 | AB26: 31283.527 | AC26: 22070.49 | AD26: 472686.75 | AE26: 1156.6307 | AF26: 0 | AG26: 24.308017 | AH26: 4680.1142 | AI26: -25.009387 | AJ26: 8.566634 | AK26: 0 | AL26: 9724786 | AM26: 12549.976 | AN26: 541122.37 | AO26: 979977.57 | AP26: 108549 | AQ26: 11207.68 | AR26: 0 | AS26: =SUM(AL26:AR26) -> 11378193 | AT26: =SUM(AE26:AK26) -> 5844.6101 | AU26: =AS26+AT26 -> 11384037 | AV26: =SUM(C26:AR26) -> 27182783 | AW26: Trade, transport and utilities
B27: Services | C27: 20.629362 | D27: 150.26079 | E27: 24.7553 | F27: 486.8617 | G27: 148.8734 | H27: 8.8234549 | I27: 32.521317 | J27: 4134.6513 | K27: 7.1482117 | L27: 2099.3615 | M27: 7508.5326 | N27: 17.482004 | O27: 2.3614905 | P27: 149.59506 | Q27: 158442.17 | R27: 91753.888 | S27: 99539.655 | T27: 113474.59 | U27: 146789.15 | V27: 25640.828 | W27: 362121.95 | X27: 3779585.3 | Y27: 68545.027 | Z27: 2942021.7 | AA27: 11916609 | AB27: 50347.559 | AC27: 28946.109 | AD27: 479283.47 | AE27: 1889.7609 | AF27: 0 | AG27: 126.64854 | AH27: 240.41355 | AI27: -15.828381 | AJ27: 4.1058986 | AK27: 0 | AL27: 19214876 | AM27: 910965.06 | AN27: 11613463 | AO27: 3305544.4 | AP27: 123639.73 | AQ27: 2782.1215 | AR27: 0 | AS27: =SUM(AL27:AR27) -> 35171271 | AT27: =SUM(AE27:AK27) -> 2245.1005 | AU27: =AS27+AT27 -> 35173516 | AV27: =SUM(C27:AR27) -> 55451408 | AW27: Services
B28: Waste | C28: 0.08323127 | D28: 0.92838022 | E28: 0.11415432 | F28: 1.3203171 | G28: 1.6782252 | H28: 5.6502073 | I28: 0.11128268 | J28: 155.88737 | K28: 0.048238612 | L28: 25.124643 | M28: 5.3558641 | N28: 15.343469 | O28: 0.034895282 | P28: 0.51006862 | Q28: 2145.9831 | R28: 1669.6799 | S28: 3015.8632 | T28: 4318.3041 | U28: 2912.1977 | V28: 11475.426 | W28: 6237.7765 | X28: 66726.377 | Y28: 732.8543 | Z28: 27381.418 | AA28: 77180.188 | AB28: 27810.595 | AC28: 2770.8195 | AD28: 7535.9973 | AE28: 3.0974458 | AF28: 0 | AG28: 0.062461486 | AH28: 2.4375011 | AI28: 4.8436448 | AJ28: 0.89535109 | AK28: 0 | AL28: 59356.027 | AM28: 433.80322 | AN28: 27888.701 | AO28: 1264.8289 | AP28: 1275.9081 | AQ28: 216.18455 | AR28: 0 | AS28: =SUM(AL28:AR28) -> 90435.453 | AT28: =SUM(AE28:AK28) -> 11.336404 | AU28: =AS28+AT28 -> 90446.79 | AV28: =SUM(C28:AR28) -> 332572.46 | AW28: Waste
B29: Water | C29: 0.029321706 | D29: 0.36929473 | E29: 0.05794727 | F29: 0.62694361 | G29: 0.70689872 | H29: 0.6177587 | I29: 0.14236662 | J29: 14.4574 | K29: 0.026773321 | L29: 20.735972 | M29: 3.2653264 | N29: 1.3377299 | O29: 0.0051090476 | P29: 0.25965814 | Q29: 4585.7152 | R29: 1399.3865 | S29: 1267.5794 | T29: 1513.8094 | U29: 1678.0455 | V29: 1289.1696 | W29: 3367.0214 | X29: 27465.189 | Y29: 1112.8647 | Z29: 15449.485 | AA29: 42739.893 | AB29: 2611.0164 | AC29: 10850.189 | AD29: 5374.08 | AE29: 2.5958008 | AF29: 0 | AG29: 0.036182476 | AH29: 6.37525 | AI29: 0.064114812 | AJ29: 0.11767151 | AK29: 0 | AL29: 109252.56 | AM29: 58.154509 | AN29: 7502.9376 | AO29: 1778.502 | AP29: -72.780569 | AQ29: 50.518496 | AR29: 0 | AS29: =SUM(AL29:AR29) -> 118569.9 | AT29: =SUM(AE29:AK29) -> 9.1890196 | AU29: =AS29+AT29 -> 118579.09 | AV29: =SUM(C29:AR29) -> 239325.17 | AW29: Water
B30: Hotels and Resteraunts | C30: 1.9644419 | D30: 11.888587 | E30: 2.7087439 | F30: 13.914548 | G30: 16.90687 | H30: 1.3998804 | I30: 2.6195367 | J30: 372.04637 | K30: 0.35968255 | L30: 1303.9563 | M30: 7248.5005 | N30: 2.7777697 | O30: 0.83069947 | P30: 76.321252 | Q30: 7916.9457 | R30: 6385.7248 | S30: 5460.5789 | T30: 11204.756 | U30: 5962.1862 | V30: 785.48437 | W30: 19200.851 | X30: 266448.04 | Y30: 4293.7063 | Z30: 275122.4 | AA30: 771357.8 | AB30: 2266.3767 | AC30: 992.65598 | AD30: 40077.983 | AE30: 7.8419532 | AF30: 0 | AG30: 0.12498538 | AH30: 3.7438809 | AI30: -0.30405845 | AJ30: 0.052888161 | AK30: 0 | AL30: 2716276.4 | AM30: 29605.392 | AN30: 76762.719 | AO30: 7526.2057 | AP30: 33012.512 | AQ30: 7549.7442 | AR30: 0 | AS30: =SUM(AL30:AR30) -> 2870732.9 | AT30: =SUM(AE30:AK30) -> 11.459649 | AU30: =AS30+AT30 -> 2870744.4 | AV30: =SUM(C30:AR30) -> 4297276.1 | AW30: Hotels and Resteraunts
B31: Value Added | C31: =$AV3-C32 -> 1961.6332 | D31: =$AV4-D32 -> 2093.4398 | E31: =$AV5-E32 -> 1510.3105 | F31: =$AV6-F32 -> 2103.764 | G31: =$AV7-G32 -> 13220.688 | H31: =$AV8-H32 -> 1002.7442 | I31: =$AV9-I32 -> 4074.8078 | J31: =$AV10-J32 -> 92225.175 | K31: =$AV11-K32 -> 51.985251 | L31: =$AV12-L32 -> 83982.707 | M31: =$AV13-M32 -> 170193.72 | N31: =$AV14-N32 -> 1979.8133 | O31: =$AV15-O32 -> 654.951 | P31: =$AV16-P32 -> 22104.755 | Q31: =$AV17-Q32 -> 1894883 | R31: =$AV18-R32 -> 339814.52 | S31: =$AV19-S32 -> 1150897.8 | T31: =$AV20-T32 -> 604837.9 | U31: =$AV21-U32 -> 819093.13 | V31: =$AV22-V32 -> 68791.045 | W31: =$AV23-W32 -> 2588536.4 | X31: =$AV24-X32 -> 16695151 | Y31: =$AV25-Y32 -> 139355.74 | Z31: =$AV26-Z32 -> 16176107 | AA31: =$AV27-AA32 -> 34708488 | AB31: =$AV28-AB32 -> 158030.98 | AC31: =$AV29-AC32 -> 139710.8 | AD31: =$AV30-AD32 -> 2483362.6 | AE31: =SUM(C31:AD31) -> 78364219 | AF31: GDP
B32: Sum Inter-Industry Input | C32: =SUM(C3:C30) -> 2092.0015 | D32: =SUM(D3:D30) -> 3578.5824 | E32: =SUM(E3:E30) -> 2797.4902 | F32: =SUM(F3:F30) -> 5796.7062 | G32: =SUM(G3:G30) -> 6479.8131 | H32: =SUM(H3:H30) -> 1399.9945 | I32: =SUM(I3:I30) -> 2891.828 | J32: =SUM(J3:J30) -> 144647.96 | ... AD32: =SUM(AD3:AD30) -> 1813913.5
B33: X_Total Industry Input (Output) | C33: =SUM(C3:C31) -> 4053.6347 | D33: =SUM(D3:D31) -> 5672.0222 | E33: =SUM(E3:E31) -> 4307.8007 | F33: =SUM(F3:F31) -> 7900.4702 | G33: =SUM(G3:G31) -> 19700.501 | H33: =SUM(H3:H31) -> 2402.7387 | I33: =SUM(I3:I31) -> 6966.6358 | J33: =SUM(J3:J31) -> 236873.13 | ... AD33: =SUM(AD3:AD31) -> 4297276.1
B35: Environmental Emissions (scope 1) - M Matrix
B36: SuperRegion | C36: AT | Q36: World_but_AT
B37: Aggregated_Sector | C37: Plant cultivation | D37: Plant processing | E37: Animal husbandry | F37: Animal processing | G37: Other food processing | H37: Food waste and reuse | I37: Mining and forestry | J37: Manufacturing and construction | K37: Manufacturing fertilisers | L37: Trade, transport and utilities | M37: Services | N37: Waste | O37: Water | P37: Hotels and Resteraunts | Q37: Plant cultivation | R37: Plant processing | S37: Animal husbandry | T37: Animal processing | U37: Other food processing | V37: Food waste and reuse | W37: Mining and forestry | X37: Manufacturing and construction | Y37: Manufacturing fertilisers | Z37: Trade, transport and utilities | AA37: Services | AB37: Waste | AC37: Water | AD37: Hotels and Resteraunts
A38: Emissions | B38: CO2 | C38: 1599395405 | D38: 3.5876009e+08 | E38: 1422018201 | F38: 4.5011202e+08 | G38: 5.4854401e+08 | H38: 1.9754898e+08 | I38: 1348811516 | J38: 26932981668 | K38: 25411300 | L38: 24996084252 | M38: 5812384122 | N38: 3.0451057e+08 | O38: 6207549.4 | P38: 1269548174 | Q38: 670602115573 | R38: 202554273436 | S38: 355284242092 | T38: 540857723573 | U38: 258664599387 | V38: 48940750472 | W38: 1268162071905 | X38: 10717220105631 | Y38: 372430342643 | Z38: 16319027056517 | AA38: 1700308756206 | AB38: 83590784657 | AC38: 23772824682 | AD38: 119998374518
B39: CH4 Fossil (CO2 eq) | C39: 14564307 | D39: 1537193.9 | E39: 27359991 | F39: 1807094.2 | G39: 1726688.8 | H39: 1338099.2 | I39: 25384000 | J39: 76396241 | K39: 122854.74 | L39: 88038877 | M39: 19846533 | N39: 2583157.2 | O39: 17230.296 | P39: 13002997 | Q39: 8165801132 | R39: 9.1184325e+08 | S39: 4721539586 | T39: 3215760927 | U39: 1238572984 | V39: 1.4800138e+08 | W39: 3425315802 | X39: 26777665280 | Y39: 9.8360651e+08 | Z39: 17845257369 | AA39: 14396814755 | AB39: 5.0916709e+08 | AC39: 1.5564108e+08 | AD39: 2182400095
B40: CH4 non-fossil (CO2 eq) | C40: 0 | D40: 0 | E40: 5572599601 | F40: 0 | G40: 0 | H40: 1118487853 | I40: 0 | J40: 0 | K40: 0 | L40: 0 | M40: 0 | N40: 1643973174 | O40: 0 | P40: 0 | Q40: 1200539268970 | R40: 0 | S40: 2962486480102 | T40: 0 | U40: 0 | V40: 1495842188233 | W40: 0 | X40: 0 | Y40: 0 | Z40: 0 | AA40: 0 | AB40: 874586918021 | AC40: 0 | AD40: 0
B41: NO2 (CO2 eq) | C41: 18104038 | D41: 2151217.2 | E41: 16819401 | F41: 2387046.6 | G41: 2153840.8 | H41: 2057895.5 | I41: 10478558 | J41: 1.4776074e+08 | K41: 149676.71 | L41: 1.1932054e+08 | M41: 43919677 | N41: 3256031 | O41: 63616.418 | P41: 14175284 | Q41: 9849554745 | R41: 1272084202 | S41: 4667887060 | T41: 3740364275 | U41: 1821984025 | V41: 2.2432258e+08 | W41: 6922893579 | X41: 52859796171 | Y41: 1616244777 | Z41: 106622441999 | AA41: 14916700287 | AB41: 3.5217979e+08 | AC41: 1.0552214e+08 | AD41: 1401770009
...

Sheet Graphs
B1: SuperRegion | C1: AT | R1: World_but_AT
A2: GHG | B2: Aggregated_Sector | C2: Plant cultivation | D2: Plant processing | E2: Animal husbandry | F2: Animal processing | G2: Other food processing | H2: Food waste and reuse | I2: Mining and forestry | J2: Manufacturing and construction | K2: Manufacturing fertilisers | L2: Trade, transport and utilities | M2: Services | N2: Waste | O2: Water | P2: Hotels and Resteraunts | R2: Plant cultivation | S2: Plant processing | T2: Animal husbandry | U2: Animal processing | V2: Other food processing | W2: Food waste and reuse | X2: Mining and forestry | Y2: Manufacturing and construction | Z2: Manufacturing fertilisers | AA2: Trade, transport and utilities | AB2: Services | AC2: Waste | AD2: Water | AE2: Hotels and Resteraunts | AF2: Totals
B3: Footprint | C3: =Model!AG200 -> 8.8471293e+08 | D3: =Model!AH200 -> 1259476715 | E3: =Model!AI200 -> 4518129502 | F3: =Model!AJ200 -> 2461614424 | G3: =Model!AK200 -> 2685320394 | H3: =Model!AL200 -> 69023018 | I3: =Model!AM200 -> 6.1771452e+08 | J3: =Model!AN200 -> 36753265098 | ... P3: =Model!AT200 -> 1788105630 | Q3: Footprint | R3: =Model!AU200 -> 1036687414803 | S3: =Model!AV200 -> 442279434505 | T3: =Model!AW200 -> 1967867515855 | U3: =Model!AX200 -> 1787399433217 | V3: =Model!AY200 -> 1088933440650 | W3: =Model!AZ200 -> 646405309465 | X3: =Model!BA200 -> 158324844457 | Y3: =Model!BB200 -> 14171840262290 | ... AE3: =Model!BH200 -> 952462234246 | AF3: =SUM(C3:AE3) -> 39794749118832
B4: Direct output | C4: =Model!$BI170 -> 1668962085 | D4: =Model!$BI171 -> 370000297 | E4: =Model!$BI172 -> 7044877391 | F4: =Model!$BI173 -> 457618028 | G4: =Model!$BI174 -> 5.6429893e+08 | H4: =Model!$BI175 -> 1396399359 | I4: =Model!$BI176 -> 1506131437 | J4: =Model!$BI177 -> 27267304167 | K4: =Model!$BI178 -> 26905618 | L4: =Model!$BI179 -> 25203443673 | M4: =Model!$BI180 -> 5876150331 | N4: =Model!$BI181 -> 2042925110 | O4: =Model!$BI182 -> 6288396.1 | P4: =Model!$BI183 -> 1296726455 | Q4: Direct output | R4: =Model!$BI184 -> 1910194029437 | S4: =Model!$BI185 -> 206513585997 | T4: =Model!$BI186 -> 3329657548812 | U4: =Model!$BI187 -> 548309594788 | V4: =Model!$BI188 -> 262725579656 | W4: =Model!$BI189 -> 1578397521288 | X4: =Model!$BI190 -> 1338026025116 | Y4: =Model!$BI191 -> 10877317349473 | Z4: =Model!$BI192 -> 375720391672 | AA4: =Model!$BI193 -> 16443494755885 | AB4: =Model!$BI194 -> 1729622271248 | AC4: =Model!$BI195 -> 972425901650 | AD4: =Model!$BI196 -> 24033987911 | AE4: =Model!$BI197 -> 123582544622 | AF4: =SUM(C4:AE4) -> 39794749118832
AF7: 4.2053078e+13
B35: SuperRegion | C35: AT | R35: World_but_AT
B36: Aggregated_Sector | C36: Plant cultivation | D36: Plant processing | E36: Animal husbandry | F36: Animal processing | G36: Other food processing | H36: Food waste and reuse | I36: Mining and forestry | J36: Manufacturing and construction | K36: Manufacturing fertilisers | L36: Trade, transport and utilities | M36: Services | N36: Waste | O36: Water | P36: Hotels and Resteraunts | R36: Plant cultivation | S36: Plant processing | T36: Animal husbandry | U36: Animal processing | V36: Other food processing | W36: Food waste and reuse | X36: Mining and forestry | Y36: Manufacturing and construction | Z36: Manufacturing fertilisers | AA36: Trade, transport and utilities | AB36: Services | AC36: Waste | AD36: Water | AE36: Hotels and Resteraunts | AF36: Totals
A37: Mat (Plants) | B37: Footprint | C37: =Model!AG234 -> 3493.9689 | D37: =Model!AH234 -> 1505.2666 | E37: =Model!AI234 -> 1400.7722 | F37: =Model!AJ234 -> 426.62849 | G37: =Model!AK234 -> 2293.2746 | H37: =Model!AL234 -> 0.56519406 | I37: =Model!AM234 -> 13.432015 | J37: =Model!AN234 -> 2450.3079 | ... P37: =Model!AT234 -> 626.27355 | Q37: Footprint | R37: =Model!AU234 -> 3702270.4 | S37: =Model!AV234 -> 372550.48 | T37: =Model!AW234 -> 240053.17 | U37: =Model!AX234 -> 215544.42 | V37: =Model!AY234 -> 1718315.3 | W37: =Model!AZ234 -> 1575.9586 | X37: =Model!BA234 -> 10237.611 | Y37: =Model!BB234 -> 1489517.9 | ... AE37: =Model!BH234 -> 344403.97 | AF37: =SUM(C37:AE37) -> 9370080
B38: Direct output | C38: =Model!$BI204 -> 9814.9808 | D38: =Model!$BI205 -> 0 | E38: =Model!$BI206 -> 0 | F38: =Model!$BI207 -> 0 | G38: =Model!$BI208 -> 0 | H38: =Model!$BI209 -> 0 | I38: =Model!$BI210 -> 0 | J38: =Model!$BI211 -> 0 | K38: =Model!$BI212 -> 0 | L38: =Model!$BI213 -> 0 | M38: =Model!$BI214 -> 0 | N38: =Model!$BI215 -> 0 | O38: =Model!$BI216 -> 0 | P38: =Model!$BI217 -> 0 | Q38: Direct output | R38: =Model!$BI218 -> 9360265 | S38: =Model!$BI219 -> 0 | T38: =Model!$BI220 -> 0 | U38: =Model!$BI221 -> 0 | V38: =Model!$BI222 -> 0 | W38: =Model!$BI223 -> 0 | X38: =Model!$BI224 -> 0 | Y38: =Model!$BI225 -> 0 | Z38: =Model!$BI226 -> 0 | AA38: =Model!$BI227 -> 0 | AB38: =Model!$BI228 -> 0 | AC38: =Model!$BI229 -> 0 | AD38: =Model!$BI230 -> 0 | AE38: =Model!$BI231 -> 0 | AF38: =SUM(C38:AE38) -> 9370080
B69: SuperRegion | C69: AT | R69: World_but_AT
B70: Aggregated_Sector | C70: Plant cultivation | D70: Plant processing | E70: Animal husbandry | F70: Animal processing | G70: Other food processing | H70: Food waste and reuse | I70: Mining and forestry | J70: Manufacturing and construction | K70: Manufacturing fertilisers | L70: Trade, transport and utilities | M70: Services | N70: Waste | O70: Water | P70: Hotels and Resteraunts | R70: Plant cultivation | S70: Plant processing | T70: Animal husbandry | U70: Animal processing | V70: Other food processing | W70: Food waste and reuse | X70: Mining and forestry | Y70: Manufacturing and construction | Z70: Manufacturing fertilisers | AA70: Trade, transport and utilities | AB70: Services | AC70: Waste | AD70: Water | AE70: Hotels and Resteraunts | AF70: Totals
A71: Mat (Feed) | B71: Footprint | C71: =Model!AG268 -> 21.66848 | D71: =Model!AH268 -> 75.689872 | E71: =Model!AI268 -> 8639.8835 | F71: =Model!AJ268 -> 2805.5208 | G71: =Model!AK268 -> 1248.6271 | H71: =Model!AL268 -> 0.73020711 | I71: =Model!AM268 -> 16.266356 | J71: =Model!AN268 -> 1977.0833 | ... P71: =Model!AT268 -> 649.88017 | Q71: Footprint | R71: =Model!AU268 -> 42506.766 | S71: =Model!AV268 -> 34523.358 | T71: =Model!AW268 -> 7086548.8 | U71: =Model!AX268 -> 3708135.9 | V71: =Model!AY268 -> 356475.85 | W71: =Model!AZ268 -> 2634.3971 | X71: =Model!BA268 -> 7129.3986 | Y71: =Model!BB268 -> 886824.49 | ... AE71: =Model!BH268 -> 679425.65 | AF71: =SUM(C71:AE71) -> 14043340
B72: Direct output | C72: =Model!$BI238 -> 0 | D72: =Model!$BI239 -> 0 | E72: =Model!$BI240 -> 15943.325 | F72: =Model!$BI241 -> 0 | G72: =Model!$BI242 -> 0 | H72: =Model!$BI243 -> 0 | I72: =Model!$BI244 -> 0 | J72: =Model!$BI245 -> 0 | K72: =Model!$BI246 -> 0 | L72: =Model!$BI247 -> 0 | M72: =Model!$BI248 -> 0 | N72: =Model!$BI249 -> 0 | O72: =Model!$BI250 -> 0 | P72: =Model!$BI251 -> 0 | Q72: Direct output | R72: =Model!$BI252 -> 0 | S72: =Model!$BI253 -> 0 | T72: =Model!$BI254 -> 14027397 | U72: =Model!$BI255 -> 0 | V72: =Model!$BI256 -> 0 | W72: =Model!$BI257 -> 0 | X72: =Model!$BI258 -> 0 | Y72: =Model!$BI259 -> 0 | Z72: =Model!$BI260 -> 0 | AA72: =Model!$BI261 -> 0 | AB72: =Model!$BI262 -> 0 | AC72: =Model!$BI263 -> 0 | AD72: =Model!$BI264 -> 0 | AE72: =Model!$BI265 -> 0 | AF72: =SUM(C72:AE72) -> 14043340
