Workbook

Sheet Historical-Analysis
A1: Year | B1: GDP | C1: Demand Tofu | D1: Demand Cattle | E1: Demand Beef | F1: Cattle Stock | G1: Cattle Gross Adition | H1: Cattle Outflow | I1: Year
A2: 1990 | B2: =INDIRECT("'" & A2 & "'!F7") -> 16 | C2: =INDIRECT("'" & A2 & "'!H4") -> 3 | D2: =INDIRECT("'" & A2 & "'!H5") -> 2 | E2: =INDIRECT("'" & A2 & "'!H6") -> 11 | F2: {=SUM(INDIRECT("D" & ROW() - 1 + 1 & ":D" & ROW()))*10^6/P$22} -> 1333.3333 | G2: =D2*10^6/P$22 -> 1333.3333 | H2: 0 | I2: 1990 | R2: Cattle Gross Addition
A3: 1991 | B3: =INDIRECT("'" & A3 & "'!F7") -> 17.07 | C3: =INDIRECT("'" & A3 & "'!H4") -> 3.41 | D3: =INDIRECT("'" & A3 & "'!H5") -> 2.33 | E3: =INDIRECT("'" & A3 & "'!H6") -> 11.33 | F3: {=SUM(INDIRECT("D" & ROW() - 2 + 1 & ":D" & ROW()))*10^6/P$22} -> 2886.6667 | G3: =D3*10^6/P$22 -> 1553.3333 | H3: 0 | I3: 1991
A4: 1992 | B4: =INDIRECT("'" & A4 & "'!F7") -> 18.13 | C4: =INDIRECT("'" & A4 & "'!H4") -> 3.76 | D4: =INDIRECT("'" & A4 & "'!H5") -> 2.71 | E4: =INDIRECT("'" & A4 & "'!H6") -> 11.66 | F4: {=SUM(INDIRECT("D" & ROW() - 3 + 1 & ":D" & ROW()))*10^6/P$22} -> 4693.3333 | G4: =D4*10^6/P$22 -> 1806.6667 | H4: 0 | I4: 1992
A5: 1993 | B5: =INDIRECT("'" & A5 & "'!F7") -> 19.07 | C5: =INDIRECT("'" & A5 & "'!H4") -> 4.03 | D5: =INDIRECT("'" & A5 & "'!H5") -> 3.05 | E5: =INDIRECT("'" & A5 & "'!H6") -> 11.99 | F5: =SUM(INDIRECT("D" & ROW() - P$20 + 1 & ":D" & ROW()))*10^6/P$22 -> 6726.6667 | G5: =D5*10^6/P$22 -> 2033.3333 | H5: 0 | I5: 1993
A6: 1994 | B6: =INDIRECT("'" & A6 & "'!F7") -> 20.43 | C6: =INDIRECT("'" & A6 & "'!H4") -> 4.56 | D6: =INDIRECT("'" & A6 & "'!H5") -> 3.33 | E6: =INDIRECT("'" & A6 & "'!H6") -> 12.54 | F6: =SUM(INDIRECT("D" & ROW() - P$20 + 1 & ":D" & ROW()))*10^6/P$22 -> 8946.6667 | G6: =D6*10^6/P$22 -> 2220 | H6: =D2*10^6/P$22 -> 1333.3333 | I6: 1994
A7: 1995 | B7: =INDIRECT("'" & A7 & "'!F7") -> 21.87 | C7: =INDIRECT("'" & A7 & "'!H4") -> 4.98 | D7: =INDIRECT("'" & A7 & "'!H5") -> 3.69 | E7: =INDIRECT("'" & A7 & "'!H6") -> 13.2 | F7: =SUM(INDIRECT("D" & ROW() - P$20 + 1 & ":D" & ROW()))*10^6/P$22 -> 10073.333 | G7: =D7*10^6/P$22 -> 2460 | H7: =D3*10^6/P$22 -> 1553.3333 | I7: 1995
A8: 1996 | B8: =INDIRECT("'" & A8 & "'!F7") -> 23.22 | C8: =INDIRECT("'" & A8 & "'!H4") -> 5.23 | D8: =INDIRECT("'" & A8 & "'!H5") -> 4.02 | E8: =INDIRECT("'" & A8 & "'!H6") -> 13.97 | F8: =SUM(INDIRECT("D" & ROW() - P$20 + 1 & ":D" & ROW()))*10^6/P$22 -> 11200 | G8: =D8*10^6/P$22 -> 2680 | H8: =D4*10^6/P$22 -> 1806.6667 | I8: 1996
A9: 1997 | B9: =INDIRECT("'" & A9 & "'!F7") -> 25.17 | C9: =INDIRECT("'" & A9 & "'!H4") -> 5.88 | D9: =INDIRECT("'" & A9 & "'!H5") -> 4.44 | E9: =INDIRECT("'" & A9 & "'!H6") -> 14.85 | F9: =SUM(INDIRECT("D" & ROW() - P$20 + 1 & ":D" & ROW()))*10^6/P$22 -> 12353.333 | G9: =D9*10^6/P$22 -> 2960 | H9: =D5*10^6/P$22 -> 2033.3333 | I9: 1997
A10: 1998 | B10: =INDIRECT("'" & A10 & "'!F7") -> 26.72 | C10: =INDIRECT("'" & A10 & "'!H4") -> 6.06 | D10: =INDIRECT("'" & A10 & "'!H5") -> 4.93 | E10: =INDIRECT("'" & A10 & "'!H6") -> 15.73 | F10: =SUM(INDIRECT("D" & ROW() - P$20 + 1 & ":D" & ROW()))*10^6/P$22 -> 13606.667 | G10: =D10*10^6/P$22 -> 3286.6667 | H10: =D6*10^6/P$22 -> 2220 | I10: 1998
A11: 1999 | B11: =INDIRECT("'" & A11 & "'!F7") -> 28.71 | C11: =INDIRECT("'" & A11 & "'!H4") -> 6.95 | D11: =INDIRECT("'" & A11 & "'!H5") -> 5.15 | E11: =INDIRECT("'" & A11 & "'!H6") -> 16.61 | F11: =SUM(INDIRECT("D" & ROW() - P$20 + 1 & ":D" & ROW()))*10^6/P$22 -> 14820 | G11: =D11*10^6/P$22 -> 3433.3333 | H11: =D7*10^6/P$22 -> 2460 | I11: 1999
A12: 2000 | B12: =INDIRECT("'" & A12 & "'!F7") -> 30.91 | C12: =INDIRECT("'" & A12 & "'!H4") -> 7.88 | D12: =INDIRECT("'" & A12 & "'!H5") -> 5.65 | E12: =INDIRECT("'" & A12 & "'!H6") -> 17.38 | F12: =SUM(INDIRECT("D" & ROW() - P$20 + 1 & ":D" & ROW()))*10^6/P$22 -> 16126.667 | G12: =D12*10^6/P$22 -> 3766.6667 | H12: =D8*10^6/P$22 -> 2680 | I12: 2000
A13: 2001 | B13: =INDIRECT("'" & A13 & "'!F7") -> 32.61 | C13: =INDIRECT("'" & A13 & "'!H4") -> 8.76 | D13: =INDIRECT("'" & A13 & "'!H5") -> 6.03 | E13: =INDIRECT("'" & A13 & "'!H6") -> 17.82 | F13: =SUM(INDIRECT("D" & ROW() - P$20 + 1 & ":D" & ROW()))*10^6/P$22 -> 17466.667 | G13: =D13*10^6/P$22 -> 4020 | H13: =D9*10^6/P$22 -> 2960 | I13: 2001
A14: 2002 | B14: =INDIRECT("'" & A14 & "'!F7") -> 34.36 | C14: =INDIRECT("'" & A14 & "'!H4") -> 9.45 | D14: =INDIRECT("'" & A14 & "'!H5") -> 6.54 | E14: =INDIRECT("'" & A14 & "'!H6") -> 18.37 | F14: =SUM(INDIRECT("D" & ROW() - P$20 + 1 & ":D" & ROW()))*10^6/P$22 -> 18866.667 | G14: =D14*10^6/P$22 -> 4360 | H14: =D10*10^6/P$22 -> 3286.6667 | I14: 2002
A15: 2003 | B15: =INDIRECT("'" & A15 & "'!F7") -> 36.65 | C15: =INDIRECT("'" & A15 & "'!H4") -> 10.63 | D15: =INDIRECT("'" & A15 & "'!H5") -> 6.99 | E15: =INDIRECT("'" & A15 & "'!H6") -> 19.03 | F15: =SUM(INDIRECT("D" & ROW() - P$20 + 1 & ":D" & ROW()))*10^6/P$22 -> 20240 | G15: =D15*10^6/P$22 -> 4660 | H15: =D11*10^6/P$22 -> 3433.3333 | I15: 2003
A16: 2004 | B16: =INDIRECT("'" & A16 & "'!F7") -> 39.39 | C16: =INDIRECT("'" & A16 & "'!H4") -> 12.04 | D16: =INDIRECT("'" & A16 & "'!H5") -> 7.66 | E16: =INDIRECT("'" & A16 & "'!H6") -> 19.69 | F16: =SUM(INDIRECT("D" & ROW() - P$20 + 1 & ":D" & ROW()))*10^6/P$22 -> 21913.333 | G16: =D16*10^6/P$22 -> 5106.6667 | H16: =D12*10^6/P$22 -> 3766.6667 | I16: 2004
A17: 2005 | B17: =INDIRECT("'" & A17 & "'!F7") -> 40.93 | C17: =INDIRECT("'" & A17 & "'!H4") -> 13.25 | D17: =INDIRECT("'" & A17 & "'!H5") -> 7.33 | E17: =INDIRECT("'" & A17 & "'!H6") -> 20.35 | F17: =SUM(INDIRECT("D" & ROW() - P$20 + 1 & ":D" & ROW()))*10^6/P$22 -> 23033.333 | G17: =D17*10^6/P$22 -> 4886.6667 | H17: =D13*10^6/P$22 -> 4020 | I17: 2005
A18: 2006 | B18: =INDIRECT("'" & A18 & "'!F7") -> 42.23 | C18: =INDIRECT("'" & A18 & "'!H4") -> 14.33 | D18: =INDIRECT("'" & A18 & "'!H5") -> 6.78 | E18: =INDIRECT("'" & A18 & "'!H6") -> 21.12 | F18: =SUM(INDIRECT("D" & ROW() - P$20 + 1 & ":D" & ROW()))*10^6/P$22 -> 23533.333 | G18: =D18*10^6/P$22 -> 4520 | H18: =D14*10^6/P$22 -> 4360 | I18: 2006
A19: 2007 | B19: =INDIRECT("'" & A19 & "'!F7") -> 43.47 | C19: =INDIRECT("'" & A19 & "'!H4") -> 15.47 | D19: =INDIRECT("'" & A19 & "'!H5") -> 6.22 | E19: =INDIRECT("'" & A19 & "'!H6") -> 21.78 | F19: =SUM(INDIRECT("D" & ROW() - P$20 + 1 & ":D" & ROW()))*10^6/P$22 -> 23320 | G19: =D19*10^6/P$22 -> 4146.6667 | H19: =D15*10^6/P$22 -> 4660 | I19: 2007 | M19: Correlations | P19: Lifetime [years]
A20: 2008 | B20: =INDIRECT("'" & A20 & "'!F7") -> 44.54 | C20: =INDIRECT("'" & A20 & "'!H4") -> 16.53 | D20: =INDIRECT("'" & A20 & "'!H5") -> 5.57 | E20: =INDIRECT("'" & A20 & "'!H6") -> 22.44 | F20: =SUM(INDIRECT("D" & ROW() - P$20 + 1 & ":D" & ROW()))*10^6/P$22 -> 22373.333 | G20: =D20*10^6/P$22 -> 3713.3333 | H20: =D16*10^6/P$22 -> 5106.6667 | I20: 2008 | M20: GDP-Beef | N20: =CORREL(B1:B36, E1:E36) -> 0.83254193 | P20: 5
A21: 2009 | B21: =INDIRECT("'" & A21 & "'!F7") -> 39 | C21: =INDIRECT("'" & A21 & "'!H4") -> 15 | D21: =INDIRECT("'" & A21 & "'!H5") -> 3 | E21: =INDIRECT("'" & A21 & "'!H6") -> 21 | F21: =SUM(INDIRECT("D" & ROW() - P$20 + 1 & ":D" & ROW()))*10^6/P$22 -> 19266.667 | G21: =D21*10^6/P$22 -> 2000 | H21: =D17*10^6/P$22 -> 4886.6667 | I21: 2009 | M21: Tofu-Cattle | N21: =CORREL(C2:C37, D2:D37) -> -0.12749938 | P21: Cost Cattle [$]
A22: 2010 | B22: =INDIRECT("'" & A22 & "'!F7") -> 44.89 | C22: =INDIRECT("'" & A22 & "'!H4") -> 18.89 | D22: =INDIRECT("'" & A22 & "'!H5") -> 4 | E22: =INDIRECT("'" & A22 & "'!H6") -> 22 | F22: =SUM(INDIRECT("D" & ROW() - P$20 + 1 & ":D" & ROW()))*10^6/P$22 -> 17046.667 | G22: =D22*10^6/P$22 -> 2666.6667 | H22: =D18*10^6/P$22 -> 4520 | I22: 2010 | M22: Tofu-Beef | N22: =CORREL(C2:C37, E2:E37) -> 0.48728763 | P22: =1500 -> 1500
A23: 2011 | B23: =INDIRECT("'" & A23 & "'!F7") -> 48.09 | C23: =INDIRECT("'" & A23 & "'!H4") -> 20.02 | D23: =INDIRECT("'" & A23 & "'!H5") -> 4.53 | E23: =INDIRECT("'" & A23 & "'!H6") -> 23.54 | F23: =SUM(INDIRECT("D" & ROW() - P$20 + 1 & ":D" & ROW()))*10^6/P$22 -> 15546.667 | G23: =D23*10^6/P$22 -> 3020 | H23: =D19*10^6/P$22 -> 4146.6667 | I23: 2011 | M23: Cattle-Beef | N23: =CORREL(D2:D37, E2:E37) -> 0.13731857
A24: 2012 | B24: =INDIRECT("'" & A24 & "'!F7") -> 49.75 | C24: =INDIRECT("'" & A24 & "'!H4") -> 21.33 | D24: =INDIRECT("'" & A24 & "'!H5") -> 4.22 | E24: =INDIRECT("'" & A24 & "'!H6") -> 24.2 | F24: =SUM(INDIRECT("D" & ROW() - P$20 + 1 & ":D" & ROW()))*10^6/P$22 -> 14213.333 | G24: =D24*10^6/P$22 -> 2813.3333 | H24: =D20*10^6/P$22 -> 3713.3333 | I24: 2012
A25: 2013 | B25: =INDIRECT("'" & A25 & "'!F7") -> 52.04 | C25: =INDIRECT("'" & A25 & "'!H4") -> 22.85 | D25: =INDIRECT("'" & A25 & "'!H5") -> 4.11 | E25: =INDIRECT("'" & A25 & "'!H6") -> 25.08 | F25: =SUM(INDIRECT("D" & ROW() - P$20 + 1 & ":D" & ROW()))*10^6/P$22 -> 13240 | G25: =D25*10^6/P$22 -> 2740 | H25: =D21*10^6/P$22 -> 2000 | I25: 2013
A26: 2014 | B26: =INDIRECT("'" & A26 & "'!F7") -> 53.87 | C26: =INDIRECT("'" & A26 & "'!H4") -> 24.03 | D26: =INDIRECT("'" & A26 & "'!H5") -> 3.99 | E26: =INDIRECT("'" & A26 & "'!H6") -> 25.85 | F26: =SUM(INDIRECT("D" & ROW() - P$20 + 1 & ":D" & ROW()))*10^6/P$22 -> 13900 | G26: =D26*10^6/P$22 -> 2660 | H26: =D22*10^6/P$22 -> 2666.6667 | I26: 2014
A27: 2015 | B27: =INDIRECT("'" & A27 & "'!F7") -> 56.72 | C27: =INDIRECT("'" & A27 & "'!H4") -> 25.99 | D27: =INDIRECT("'" & A27 & "'!H5") -> 3.78 | E27: =INDIRECT("'" & A27 & "'!H6") -> 26.95 | F27: =SUM(INDIRECT("D" & ROW() - P$20 + 1 & ":D" & ROW()))*10^6/P$22 -> 13753.333 | G27: =D27*10^6/P$22 -> 2520 | H27: =D23*10^6/P$22 -> 3020 | I27: 2015
A28: 2016 | B28: =INDIRECT("'" & A28 & "'!F7") -> 58.95 | C28: =INDIRECT("'" & A28 & "'!H4") -> 27.24 | D28: =INDIRECT("'" & A28 & "'!H5") -> 3.66 | E28: =INDIRECT("'" & A28 & "'!H6") -> 28.05 | F28: =SUM(INDIRECT("D" & ROW() - P$20 + 1 & ":D" & ROW()))*10^6/P$22 -> 13173.333 | G28: =D28*10^6/P$22 -> 2440 | H28: =D24*10^6/P$22 -> 2813.3333 | I28: 2016
A29: 2017 | B29: =INDIRECT("'" & A29 & "'!F7") -> 61.24 | C29: =INDIRECT("'" & A29 & "'!H4") -> 28.55 | D29: =INDIRECT("'" & A29 & "'!H5") -> 3.54 | E29: =INDIRECT("'" & A29 & "'!H6") -> 29.15 | F29: =SUM(INDIRECT("D" & ROW() - P$20 + 1 & ":D" & ROW()))*10^6/P$22 -> 12720 | G29: =D29*10^6/P$22 -> 2360 | H29: =D25*10^6/P$22 -> 2740 | I29: 2017
A30: 2018 | B30: =INDIRECT("'" & A30 & "'!F7") -> 63.73 | C30: =INDIRECT("'" & A30 & "'!H4") -> 29.61 | D30: =INDIRECT("'" & A30 & "'!H5") -> 3.87 | E30: =INDIRECT("'" & A30 & "'!H6") -> 30.25 | F30: =SUM(INDIRECT("D" & ROW() - P$20 + 1 & ":D" & ROW()))*10^6/P$22 -> 12560 | G30: =D30*10^6/P$22 -> 2580 | H30: =D26*10^6/P$22 -> 2660 | I30: 2018
A31: 2019 | B31: =INDIRECT("'" & A31 & "'!F7") -> 63.8 | C31: =INDIRECT("'" & A31 & "'!H4") -> 30.77 | D31: =INDIRECT("'" & A31 & "'!H5") -> 4.03 | E31: =INDIRECT("'" & A31 & "'!H6") -> 29 | F31: =SUM(INDIRECT("D" & ROW() - P$20 + 1 & ":D" & ROW()))*10^6/P$22 -> 12586.667 | G31: =D31*10^6/P$22 -> 2686.6667 | H31: =D27*10^6/P$22 -> 2520 | I31: 2019
A32: 2020 | B32: =INDIRECT("'" & A32 & "'!F7") -> 63.36 | C32: =INDIRECT("'" & A32 & "'!H4") -> 32.87 | D32: =INDIRECT("'" & A32 & "'!H5") -> 3.94 | E32: =INDIRECT("'" & A32 & "'!H6") -> 26.55 | F32: =SUM(INDIRECT("D" & ROW() - P$20 + 1 & ":D" & ROW()))*10^6/P$22 -> 12693.333 | G32: =D32*10^6/P$22 -> 2626.6667 | H32: =D28*10^6/P$22 -> 2440 | I32: 2020
A33: 2021 | B33: =INDIRECT("'" & A33 & "'!F7") -> 60.8 | C33: =INDIRECT("'" & A33 & "'!H4") -> 35.03 | D33: =INDIRECT("'" & A33 & "'!H5") -> 3.77 | E33: =INDIRECT("'" & A33 & "'!H6") -> 22 | F33: =SUM(INDIRECT("D" & ROW() - P$20 + 1 & ":D" & ROW()))*10^6/P$22 -> 12766.667 | G33: =D33*10^6/P$22 -> 2513.3333 | H33: =D29*10^6/P$22 -> 2360 | I33: 2021
A34: 2022 | B34: =INDIRECT("'" & A34 & "'!F7") -> 63.43 | C34: =INDIRECT("'" & A34 & "'!H4") -> 38.55 | D34: =INDIRECT("'" & A34 & "'!H5") -> 3.88 | E34: =INDIRECT("'" & A34 & "'!H6") -> 21 | F34: =SUM(INDIRECT("D" & ROW() - P$20 + 1 & ":D" & ROW()))*10^6/P$22 -> 12993.333 | G34: =D34*10^6/P$22 -> 2586.6667 | H34: =D30*10^6/P$22 -> 2580 | I34: 2022
A35: 2023 | B35: =INDIRECT("'" & A35 & "'!F7") -> 64.13 | C35: =INDIRECT("'" & A35 & "'!H4") -> 42.02 | D35: =INDIRECT("'" & A35 & "'!H5") -> 4.11 | E35: =INDIRECT("'" & A35 & "'!H6") -> 18 | F35: =SUM(INDIRECT("D" & ROW() - P$20 + 1 & ":D" & ROW()))*10^6/P$22 -> 13153.333 | G35: =D35*10^6/P$22 -> 2740 | H35: =D31*10^6/P$22 -> 2686.6667 | I35: 2023
... A37: 2025 | B37: =INDIRECT("'" & A37 & "'!F7") -> 67.79 | C37: =INDIRECT("'" & A37 & "'!H4") -> 50.74 | D37: =INDIRECT("'" & A37 & "'!H5") -> 4.05 | E37: =INDIRECT("'" & A37 & "'!H6") -> 13 | F37: =SUM(INDIRECT("D" & ROW() - P$20 + 1 & ":D" & ROW()))*10^6/P$22 -> 13200 | G37: =D37*10^6/P$22 -> 2700 | H37: =D33*10^6/P$22 -> 2513.3333 | I37: 2025
B39: Direct Input Mass [mio t] | H39: Environmental Footprint Mass [mio t]
A40: Year | B40: Soy Agriculture | C40: Tofu Production | D40: Cow Farming | E40: Beef Processing | G40: Year | H40: Soy Agriculture | I40: Tofu Production | J40: Cow Farming | K40: Beef Processing
A41: 1990 | B41: =INDIRECT("'" & A2 & "'!B15") -> 21.428571 | C41: =INDIRECT("'" & A2 & "'!C15") -> 2 | D41: =INDIRECT("'" & A2 & "'!D15") -> 2.4 | E41: =INDIRECT("'" & A2 & "'!E15") -> 0.875 | G41: 1990 | H41: =INDIRECT("'" & A2 & "'!B42") -> 0 | I41: =INDIRECT("'" & A2 & "'!C42") -> 5.8853032 | J41: =INDIRECT("'" & A2 & "'!D42") -> 3.995889 | K41: =INDIRECT("'" & A2 & "'!E42") -> 16.822379
A42: 1991 | B42: =INDIRECT("'" & A3 & "'!B15") -> 22.071429 | C42: =INDIRECT("'" & A3 & "'!C15") -> 2.1666667 | D42: =INDIRECT("'" & A3 & "'!D15") -> 2.526 | E42: =INDIRECT("'" & A3 & "'!E15") -> 0.90125 | G42: 1991 | H42: =INDIRECT("'" & A3 & "'!B42") -> 0 | I42: =INDIRECT("'" & A3 & "'!C42") -> 6.3520536 | J42: =INDIRECT("'" & A3 & "'!D42") -> 4.5167285 | K42: =INDIRECT("'" & A3 & "'!E42") -> 16.796563
...

Sheet 1990_2025_Value_Added_Flow
A1: 1990
A2: Supply Sector | B2: Value Added Flow | C2: Demand Sector | E2: Create Sankey Diagramm:
A3: Soy Agriculture | B3: ='1990'!B55 -> 0 | C3: Soy Agriculture | E3: https://sankeymatic.com/build/?i=MoewngtAgg5gTgSwMYFcA2AXFcCmFgoAOhaYABANoAMAumaJLIqptjgFDsAqIAZihAAKcEABMUSDAhAA7fERLlqdBtHjJ0WXJwDCIAO4QAYgEM4AWwQyY84qWWqmG1tvYAhHDl5CRSHAGd%2DKxsCOzAHcDVmTTZOR3UWLTxQxUoAJgA6AGYAdgAWAEYqKhyCgE46Hn4fMQkpWU4qgWFayWk5FNJKKgyANio8rILegFY83oAOSr5mkXE2ht0DYzNLa1tFagyqNIKRibScrKyJgpommvn6mU4PLxq%2DQOCN%2B1oLlqv2uMinRLYX8IFDL5Iolcp5Gh6QymCzBRozS51doArYDIajcY5XpZSHLGFrGBLaGrZ6dcI9Xb7Q7HU644mw6y3TzeFqPILrMkASGUnKhKwZhPi0RcyQUpG5vQyEwmeQmZTSVAmvRonLuLN8AXZhO4CI%2BSNkAO62RGaRGBRyZQmI2VZDVD01cPYfPxpLFYG5PSxprl8tptuZ9qejPcAdZDo5bu5ONVoY1QcJQQAXjgyPoyP0qOwyGQABbp4rscxmGBWMhoMgTLNkOBkTPZjBkAqV7MAIzICvYLZgZCQIDQIBrAGJeCPR1WMHATDJ%2DIQzDgZA2AHLsGRiFNpgppKt5kZ1sgzkxIYJkHIjKstgeiHA1vcYHM4cwpkxV3v9ofSj%2DNsggWdHjDkAp2F4fs01QOAADcTCSWsMjPbMrHvRAMF4ERzH3EBsD8F8%2BwHMhBzKAjCKrH9DwQf8YLyM80BMMAMIbS9rzIEwUAwEAiykJAqwAKxQfwpF4WjEBLacyGXbMeL4hABPnUR%2DFEqtcHA69%2DBweATEIPMxKYjAMEPHMrF7cwSBwDAAlYsgZBwOc%2BPYaiWxwNA5NfXDB2KNy930q95OzfSYBzNAED8htPTgsheFkZDDxTfwp38CAVMQXgqwCyyDyPawYK3bNcGoqQlKTFMCiKKsixgGQpIAgs7IcmQTEfJjiCsuA5IATSrArGyyWCq30HBApzBs8iqkx7LQSC0BQJ9GrMVqq34NA0EIXAjyCWQyDa7NCBAIJrjIUaDB6vqgrIIbM2qxbtrI9omJYkATACsra3apB73q5jWLmhBmobezwu0VtcBMABrLarAbLJ2HGyawoHdiyAAcgAGgyeGqyWrwEAADwR1Hs38FARyxnH2DvB8cD4XgVIbEwK3PJ7syQE8q1EJ7H10shHwXdoYpkIGcDAdjkHW5KEEk8wW3uqdHmF8wQCU%2BgfgSGJcENCAemKIYskRmC3MmQs5ZTd45n1Do3R1koZW1tXtl6C1K1l%2BXnRJCMwjIa3ihGAirfVi19flu0w3jQ0qG9jICmOXo8j9w3dWNhYZHNzXtaoIA
A4: Tofu Production | B4: ='1990'!B56 -> 0 | C4: Soy Agriculture
A5: Cow Farming | B5: ='1990'!B57 -> 0 | C5: Soy Agriculture
A6: Beef Processing | B6: ='1990'!B58 -> 0 | C6: Soy Agriculture
A7: Soy Agriculture | B7: ='1990'!C55 -> 2.3741007 | C7: Tofu Production
A8: Tofu Production | B8: ='1990'!C56 -> 0.60431655 | C8: Tofu Production
A9: Cow Farming | B9: ='1990'!C57 -> 0.021582734 | C9: Tofu Production
A10: Beef Processing | B10: ='1990'!C58 -> 0 | C10: Tofu Production
A11: Soy Agriculture | B11: ='1990'!D55 -> 1.7410072 | C11: Cow Farming
A12: Tofu Production | B12: ='1990'!D56 -> 0.043165468 | C12: Cow Farming
A13: Cow Farming | B13: ='1990'!D57 -> 0.21582734 | C13: Cow Farming
A14: Beef Processing | B14: ='1990'!D58 -> 0 | C14: Cow Farming
A15: Soy Agriculture | B15: ='1990'!E55 -> 6.8848921 | C15: Beef Processing
A16: Tofu Production | B16: ='1990'!E56 -> 0.35251799 | C16: Beef Processing
A17: Cow Farming | B17: ='1990'!E57 -> 0.76258993 | C17: Beef Processing
A18: Beef Processing | B18: ='1990'!E58 -> 3 | C18: Beef Processing
G25: 1990 | L25: 2025
A26: 2025
A27: Supply Sector | B27: Value Added Flow | C27: Demand Sector
A28: Soy Agriculture | B28: ='2025'!B55 -> 0 | C28: Soy Agriculture
A29: Tofu Production | B29: ='2025'!B56 -> 0 | C29: Soy Agriculture
A30: Cow Farming | B30: ='2025'!B57 -> 0 | C30: Soy Agriculture
A31: Beef Processing | B31: ='2025'!B58 -> 0 | C31: Soy Agriculture
A32: Soy Agriculture | B32: ='2025'!C55 -> 12.841536 | C32: Tofu Production
A33: Tofu Production | B33: ='2025'!C56 -> 37.288779 | C33: Tofu Production
A34: Cow Farming | B34: ='2025'!C57 -> 0.60968459 | C34: Tofu Production
A35: Beef Processing | B35: ='2025'!C58 -> 0 | C35: Tofu Production
A36: Soy Agriculture | B36: ='2025'!D55 -> 2.582705 | C36: Cow Farming
A37: Tofu Production | B37: ='2025'!D56 -> 0.19616708 | C37: Cow Farming
A38: Cow Farming | B38: ='2025'!D57 -> 1.271128 | C38: Cow Farming
A39: Beef Processing | B39: ='2025'!D58 -> 0 | C39: Cow Farming
A40: Soy Agriculture | B40: ='2025'!E55 -> 6.6757591 | C40: Beef Processing
A41: Tofu Production | B41: ='2025'!E56 -> 3.1550535 | C41: Beef Processing
A42: Cow Farming | B42: ='2025'!E57 -> 2.8691875 | C42: Beef Processing
A43: Beef Processing | B43: ='2025'!E58 -> 0.3 | C43: Beef Processing

Sheet 1990_2025_GHG_Flow
A1: 1990 | E1: Create Sankey Diagramm:
A2: Supply Sector | B2: Value Added Flow | C2: Demand Sector | E2: https://sankeymatic.com/build/?i=MoewngtAgg5gTgSwMYFcA2AXFcCmFgoAOhaYABANoAMAumaJLIqptjgFDsAqIAZihAAKcEABMUSDAhAA7fERLlqdBtHjJ0WXJwDCIAO4QAYgEM4AWwQyY84qWWqmG1tvYAhHDl5CRSHAGd%2DKxsCOzAHcDVmTTZOR3UWLTxQxUoAJgA6AGYAdgAWAEYqKhyCgE46Hn4fMQkpWU4qgWFayWk5FNJKKgyANio8rILegFY83oAOSr5mkXE2ht0DYzNLa1tFagyqNIKRibScrKyJgpommvn6mU4PLxq%2DQOCN%2B1oLlqv2uMinRLYX8IFDL5Iolcp5Gh6QymCzBRozS51doArYDIajcY5XpZSHLGFrGBLaGrZ6dcI9Xb7Q7HU644mw6y3TzeFqPILrMkASGUnKhKwZhPi0RcyQUpG5vQyEwmeQmZTSVAmvRonLuLN8AXZhO4CI%2BSNkAO62RGaRGBRyZQmI2VZDVD01cPYfPxpLFYG5PSxprl8tptuZ9qejPcAdZDo5bu5ONVoY1QcJQQAXjgyPoyP0qOwyGQABbp4rscxmGBWMhoMgTLNkOBkTPZjBkAqV7MAIzICvYLZgZCQIDQIBrAGJeCPR1WMHATDJ%2DIQzDgZA2AHLsGRiFNpgppKt5kZ1sgzkxIYJkHIjKstgeiHA1vcYHM4cwpkxV3v9ofSj%2DNsggWdHjDkAp2F4fs01QOAADcTCSWsMjPbMrHvRAMF4ERzH3EBsD8F8%2BwHMhBzKAjCKrH9DwQf8YLyM80BMMAMIbS9rzIEwUAwEAiykJAqwAKxQfwpF4WjEBLacyGXbMeL4hABPnUR%2DFEqtcHA69%2DBweATEIPMxKYjAMEPHMrF7cwSBwDAAlYsgZBwOc%2BPYaiWxwNA5NfXDB2KNy930q95OzfSYBzNAED8htPTgsheFkZDDxTfwp38CAVMQXgqwCyyDyPawYK3bNcGoqQlKTFMCiKKsixgGQpIAgs7IcmQTEfJjiCsuA5IATSrArGyyWCq30HBApzBs8iqkx7LQSC0BQJ9GrMVqq34NA0EIXAjyCWQyDa7NCBAIJrjIUaDB6vqgrIIbM2qxbtrI9omJYkATACsra3apB73q5jWLmhBmobezwu0VtcBMABrLarAbLJ2HGyawoHdiyAAcgAGgyeGqyWrwEAADwR1Hs38FARyxnH2DvB8cD4XgVIbEwK3PJ7syQE8q1EJ7H10shHwXdoYpkIGcDAdjkHW5KEEk8wW3uqdHmF8wQCU%2BgfgSGJcENCAemKIYskRmC3MmQs5ZTd45n1Do3R1koZW1tXtl6C1K1l%2BXnRJCMwjIa3ihGAirfVi19flu0w3jQ0qG9jICmOXo8j9w3dWNhYZHNzXtaoIA
A3: Soy Agriculture | B3: ='1990'!M53 -> 0 | C3: Soy Agriculture
A4: Tofu Production | B4: ='1990'!M54 -> 0 | C4: Soy Agriculture
A5: Cow Farming | B5: ='1990'!M55 -> 0 | C5: Soy Agriculture
A6: Beef Processing | B6: ='1990'!M56 -> 0 | C6: Soy Agriculture
A7: Soy Agriculture | B7: ='1990'!N53 -> 1.3874615 | C7: Tofu Production
A8: Tofu Production | B8: ='1990'!N54 -> 0.24172662 | C8: Tofu Production
A9: Cow Farming | B9: ='1990'!N55 -> 0.98417266 | C9: Tofu Production
A10: Beef Processing | B10: ='1990'!N56 -> 0 | C10: Tofu Production | G10: 1990 | K10: 2025
A11: Soy Agriculture | B11: ='1990'!O53 -> 1.0174717 | C11: Cow Farming
A12: Tofu Production | B12: ='1990'!O54 -> 0.017266187 | C12: Cow Farming
A13: Cow Farming | B13: ='1990'!O55 -> 9.8417266 | C13: Cow Farming
A14: Beef Processing | B14: ='1990'!O56 -> 0 | C14: Cow Farming
A15: Soy Agriculture | B15: ='1990'!P53 -> 4.0236382 | C15: Beef Processing
A16: Tofu Production | B16: ='1990'!P54 -> 0.14100719 | C16: Beef Processing
A17: Cow Farming | B17: ='1990'!P55 -> 34.774101 | C17: Beef Processing
A18: Beef Processing | B18: ='1990'!P56 -> 0.875 | C18: Beef Processing
A26: 2025
A27: Supply Sector | B27: Value Added Flow | C27: Demand Sector
A28: Soy Agriculture | B28: ='2025'!M53 -> 0 | C28: Soy Agriculture
A29: Tofu Production | B29: ='2025'!M54 -> 0 | C29: Soy Agriculture
A30: Cow Farming | B30: ='2025'!M55 -> 0 | C30: Soy Agriculture
A31: Beef Processing | B31: ='2025'!M56 -> 0 | C31: Soy Agriculture
A32: Soy Agriculture | B32: ='2025'!N53 -> 9.1891275 | C32: Tofu Production
A33: Tofu Production | B33: ='2025'!N54 -> 3.6175499 | C33: Tofu Production
A34: Cow Farming | B34: ='2025'!N55 -> 9.1452689 | C34: Tofu Production
A35: Beef Processing | B35: ='2025'!N56 -> 0 | C35: Tofu Production
A36: Soy Agriculture | B36: ='2025'!O53 -> 1.8481282 | C36: Cow Farming
A37: Tofu Production | B37: ='2025'!O54 -> 0.019031039 | C37: Cow Farming
A38: Cow Farming | B38: ='2025'!O55 -> 19.066919 | C38: Cow Farming
A39: Beef Processing | B39: ='2025'!O56 -> 0 | C39: Cow Farming
A40: Soy Agriculture | B40: ='2025'!P53 -> 4.7770299 | C40: Beef Processing
A41: Tofu Production | B41: ='2025'!P54 -> 0.30608573 | C41: Beef Processing
A42: Cow Farming | B42: ='2025'!P55 -> 43.037812 | C42: Beef Processing
A43: Beef Processing | B43: ='2025'!P56 -> 1.1875 | C43: Beef Processing

Sheet 1990
B1: Input-Output Table
A2: 1990 [Mio $] | B2: Soy Agriculture | C2: Tofu Production | D2: Cow Farming | E2: Beef Processing | F2: Y_Houshold | G2: Y_Government | H2: Y_Total_Demand | I2: X_Total Output
A3: Soy Agriculture | B3: 3 | C3: 4 | D3: 8 | E3: 0 | F3: 0 | G3: 0 | H3: =SUM(F3:G3) -> 0 | I3: =SUM(B3:G3) -> 15
A4: Tofu Production | B4: 0 | C4: 1 | D4: 1 | E4: 1 | F4: 3 | G4: 0 | H4: =SUM(F4:G4) -> 3 | I4: =SUM(B4:G4) -> 6
A5: Cow Farming | B5: 1 | C5: 0 | D5: 2 | E5: 7 | F5: 0 | G5: 2 | H5: =SUM(F5:G5) -> 2 | I5: =SUM(B5:G5) -> 12
A6: Beef Processing | B6: 0 | C6: 0 | D6: 0 | E6: 3 | F6: 11 | G6: 0 | H6: =SUM(F6:G6) -> 11 | I6: =SUM(B6:G6) -> 14
A7: Value Added | B7: =I3-B8 -> 11 | C7: =I4-C8 -> 1 | D7: =I5-D8 -> 1 | E7: =I6-E8 -> 3 | F7: =SUM(B7:E7) -> 16 | G7: GDP
A8: Sum Inter Industry Input | B8: =SUM(B2:B6) -> 4 | C8: =SUM(C2:C6) -> 5 | D8: =SUM(D2:D6) -> 11 | E8: =SUM(E2:E6) -> 11
A9: X_Total_Industry_Input (Output) | B9: =SUM(B3:B7) -> 15 | C9: =SUM(C3:C7) -> 6 | D9: =SUM(D3:D7) -> 12 | E9: =SUM(E3:E7) -> 14
B10: Environmental Multiplyers
A11: Mass Multiplyer [$/kg] | B11: 0.7 | C11: 3 | D11: 5 | E11: 16
A12: GHG Multiplyer [CO2e kg /kg] | B12: 0.3 | C12: 0.2 | D12: 19 | E12: 1
A13: Land Use Multiplyer [m^2*year/kg] | B13: 0.9 | C13: 2.6 | D13: 35 | E13: 57
B14: Environmental Extensions (scope 1) - M Matrix
A15: Mass [Mio t] | B15: =B9/B11 -> 21.428571 | C15: =C9/C11 -> 2 | D15: =D9/D11 -> 2.4 | E15: =E9/E11 -> 0.875
A16: GHG Emmisons [Mio t] | B16: =B15*B12 -> 6.4285714 | C16: =C15*C12 -> 0.4 | D16: =D15*D12 -> 45.6 | E16: =E15*E12 -> 0.875
A17: Land Use [Mio m^2*year] | B17: =B15*B13 -> 19.285714 | C17: =C15*C13 -> 5.2 | D17: =D15*D13 -> 84 | E17: =E15*E13 -> 49.875
B18: Soy Agriculture | C18: Tofu Production | D18: Cow Farming | E18: Beef Processing
B22: 1/x hat Matrix [1/ Mio $]
B23: =1/I3 -> 0.066666667 | C23: 0 | D23: 0 | E23: 0
B24: 0 | C24: =1/I4 -> 0.16666667 | D24: 0 | E24: 0
B25: 0 | C25: 0 | D25: =1/I5 -> 0.083333333 | E25: 0
B26: 0 | C26: 0 | D26: 0 | E26: =1/I6 -> 0.071428571
B27: Technical Coeficient Matrix A [no dim]
B28: {=MMULT(B3:E6, B23:E26)} -> 0.2 | C28: 0.66666667 | D28: 0.66666667 | E28: 0
B29: 0 | C29: 0.16666667 | D29: 0.083333333 | E29: 0.071428571
B30: 0.066666667 | C30: 0 | D30: 0.16666667 | E30: 0.5
B31: 0 | C31: 0 | D31: 0 | E31: 0.21428571
B32: Leonthief Inverse Matrix L [no dim]
B33: {=MINVERSE(G42:J45)} -> 1.3489209 | C33: 1.0791367 | D33: 1.1870504 | E33: 0.85349902
B34: 0.010791367 | C34: 1.2086331 | D34: 0.1294964 | E34: 0.19228254
B35: 0.10791367 | C35: 0.086330935 | D35: 1.294964 | E35: 0.83191629
B36: 0 | C36: 0 | D36: 0 | E36: 1.2727273 | G36: Identity Matrix 1
B37: Environmental Coeficient Matrix F [mio (t,t,m^2)/ mio $] | G37: 1 | H37: 0 | I37: 0 | J37: 0
A38: Mass [Mio t/ mio $] | B38: {=MMULT(B15:E17, B23:E26)} -> 1.4285714 | C38: 0.33333333 | D38: 0.2 | E38: 0.0625 | G38: 0 | H38: 1 | I38: 0 | J38: 0
A39: GHG Emmisons [Mio t/ mio$] | B39: 0.42857143 | C39: 0.066666667 | D39: 3.8 | E39: 0.0625 | G39: 0 | H39: 0 | I39: 1 | J39: 0
A40: Land Use [Mio m^2*year/ mio$] | B40: 1.2857143 | C40: 0.86666667 | D40: 7 | E40: 3.5625 | G40: 0 | H40: 0 | I40: 0 | J40: 1
B41: Environmental Footprint (F*L*y-hat) | G41: 1-A
A42: Mass [Mio t] | B42: {=MMULT(MMULT(B38:E40, B33:E36),G47:J50)} -> 0 | C42: 5.8853032 | D42: 3.995889 | E42: 16.822379 | G42: =G37-B28 -> 0.8 | H42: =H37-C28 -> -0.66666667 | I42: =I37-D28 -> -0.66666667 | J42: =J37-E28 -> 0
A43: GHG Emmisons [Mio t] | B43: 0 | C43: 2.6133607 | D43: 10.876465 | E43: 39.813746 | G43: =G38-B29 -> 0 | H43: =H38-C29 -> 0.83333333 | I43: =I38-D29 -> -0.083333333 | J43: =J38-E29 -> -0.071428571
...

Sheet 1991
B1: Input-Output Table
A2: 1991 [Mio $] | B2: Soy Agriculture | C2: Tofu Production | D2: Cow Farming | E2: Beef Processing | F2: Y_Houshold | G2: Y_Government | H2: Y_Total_Demand | I2: X_Total Output
A3: Soy Agriculture | B3: 3.09 | C3: 4.12 | D3: 8.24 | E3: 0 | F3: 0 | G3: 0 | H3: =SUM(F3:G3) -> 0 | I3: =SUM(B3:G3) -> 15.45 | O3: Mass [Mio t] | P3: 22.071429 | Q3: 2.1666667 | R3: 2.526 | S3: 0.90125
A4: Tofu Production | B4: 0 | C4: 1.03 | D4: 1.03 | E4: 1.03 | F4: 3.41 | G4: 0 | H4: =SUM(F4:G4) -> 3.41 | I4: =SUM(B4:G4) -> 6.5 | O4: GHG Emmisons [Mio t] | P4: 6.6214286 | Q4: 0.43333333 | R4: 47.994 | S4: 0.90125
A5: Cow Farming | B5: 1.03 | C5: 0 | D5: 2.06 | E5: 7.21 | F5: 0 | G5: 2.33 | H5: =SUM(F5:G5) -> 2.33 | I5: =SUM(B5:G5) -> 12.63 | P5: Soy Agriculture | Q5: Tofu Production | R5: Cow Farming | S5: Beef Processing
A6: Beef Processing | B6: 0 | C6: 0 | D6: 0 | E6: 3.09 | F6: 11.33 | G6: 0 | H6: =SUM(F6:G6) -> 11.33 | I6: =SUM(B6:G6) -> 14.42
A7: Value Added | B7: =I3-B8 -> 11.33 | C7: =I4-C8 -> 1.35 | D7: =I5-D8 -> 1.3 | E7: =I6-E8 -> 3.09 | F7: =SUM(B7:E7) -> 17.07 | G7: GDP
A8: Sum Inter Industry Input | B8: =SUM(B2:B6) -> 4.12 | C8: =SUM(C2:C6) -> 5.15 | D8: =SUM(D2:D6) -> 11.33 | E8: =SUM(E2:E6) -> 11.33
A9: X_Total_Industry_Input | B9: =SUM(B3:B7) -> 15.45 | C9: =SUM(C3:C7) -> 6.5 | D9: =SUM(D3:D7) -> 12.63 | E9: =SUM(E3:E7) -> 14.42
B10: Environmental Multiplyers
A11: Mass Multiplyer [$/kg] | B11: 0.7 | C11: 3 | D11: 5 | E11: 16
A12: GHG Multiplyer [CO2e kg /kg] | B12: 0.3 | C12: 0.2 | D12: 19 | E12: 1
A13: Land Use Multiplyer [m^2*year/kg] | B13: 0.9 | C13: 2.6 | D13: 35 | E13: 57
B14: Environmental Extensions (scope 1) - M Matrix
A15: Mass [Mio t] | B15: =B9/B11 -> 22.071429 | C15: =C9/C11 -> 2.1666667 | D15: =D9/D11 -> 2.526 | E15: =E9/E11 -> 0.90125
A16: GHG Emmisons [Mio t] | B16: =B15*B12 -> 6.6214286 | C16: =C15*C12 -> 0.43333333 | D16: =D15*D12 -> 47.994 | E16: =E15*E12 -> 0.90125
A17: Land Use [Mio m^2*year] | B17: =B15*B13 -> 19.864286 | C17: =C15*C13 -> 5.6333333 | D17: =D15*D13 -> 88.41 | E17: =E15*E13 -> 51.37125
B18: Soy Agriculture | C18: Tofu Production | D18: Cow Farming | E18: Beef Processing
B22: 1/x hat Matrix [1/ Mio $]
B23: =1/I3 -> 0.064724919 | C23: 0 | D23: 0 | E23: 0
B24: 0 | C24: =1/I4 -> 0.15384615 | D24: 0 | E24: 0
B25: 0 | C25: 0 | D25: =1/I5 -> 0.079176564 | E25: 0
B26: 0 | C26: 0 | D26: 0 | E26: =1/I6 -> 0.069348128
B27: Technical Coeficient Matrix A [no dim]
B28: {=MMULT(B3:E6, B23:E26)} -> 0.2 | C28: 0.63384615 | D28: 0.65241489 | E28: 0
B29: 0 | C29: 0.15846154 | D29: 0.081551861 | E29: 0.071428571
B30: 0.066666667 | C30: 0 | D30: 0.16310372 | E30: 0.5
B31: 0 | C31: 0 | D31: 0 | E31: 0.21428571
B32: Leonthief Inverse Matrix L [no dim]
B33: {=MINVERSE(G42:J45)} -> 1.3456488 | C33: 1.0135417 | D33: 1.1477856 | E33: 0.82254919
B34: 0.010387923 | C34: 1.196124 | D34: 0.12465508 | E34: 0.18806451
B35: 0.10719359 | C35: 0.080738137 | D35: 1.2863231 | E35: 0.8259091
B36: 0 | C36: 0 | D36: 0 | E36: 1.2727273 | G36: Identity Matrix 1
B37: Environmental Coeficient Matrix F [mio (t,t,m^2)/ mio $] | G37: 1 | H37: 0 | I37: 0 | J37: 0
A38: Mass [Mio t/ mio $] | B38: {=MMULT(B15:E17, B23:E26)} -> 1.4285714 | C38: 0.33333333 | D38: 0.2 | E38: 0.0625 | G38: 0 | H38: 1 | I38: 0 | J38: 0
A39: GHG Emmisons [Mio t/ mio$] | B39: 0.42857143 | C39: 0.066666667 | D39: 3.8 | E39: 0.0625 | G39: 0 | H39: 0 | I39: 1 | J39: 0
A40: Land Use [Mio m^2*year/ mio$] | B40: 1.2857143 | C40: 0.86666667 | D40: 7 | E40: 3.5625 | G40: 0 | H40: 0 | I40: 0 | J40: 1
B41: Environmental Footprint (F*L*y-hat) | G41: 1-A
A42: Mass [Mio t] | B42: {=MMULT(MMULT(B38:E40, B33:E36),G47:J50)} -> 0 | C42: 6.3520536 | D42: 4.5167285 | E42: 16.796563 | G42: =G37-B28 -> 0.8 | H42: =H37-C28 -> -0.63384615 | I42: =I37-D28 -> -0.65241489 | J42: =J37-E28 -> 0
A43: GHG Emmisons [Mio t] | B43: 0 | C43: 2.7993424 | D43: 12.554614 | E43: 40.596055 | G43: =G38-B29 -> 0 | H43: =H38-C29 -> 0.84153846 | I43: =I38-D29 -> -0.081551861 | J43: =J38-E29 -> -0.071428571
...

Sheet 1992
B1: Input-Output Table
A2: 1992 [Mio $] | B2: Soy Agriculture | C2: Tofu Production | D2: Cow Farming | E2: Beef Processing | F2: Y_Houshold | G2: Y_Government | H2: Y_Total_Demand | I2: X_Total Output
A3: Soy Agriculture | B3: 3.18 | C3: 4.24 | D3: 8.48 | E3: 0 | F3: 0 | G3: 0 | H3: =SUM(F3:G3) -> 0 | I3: =SUM(B3:G3) -> 15.9
A4: Tofu Production | B4: 0 | C4: 1.06 | D4: 1.06 | E4: 1.06 | F4: 3.76 | G4: 0 | H4: =SUM(F4:G4) -> 3.76 | I4: =SUM(B4:G4) -> 6.94
A5: Cow Farming | B5: 1.06 | C5: 0 | D5: 2.12 | E5: 7.42 | F5: 0 | G5: 2.71 | H5: =SUM(F5:G5) -> 2.71 | I5: =SUM(B5:G5) -> 13.31
A6: Beef Processing | B6: 0 | C6: 0 | D6: 0 | E6: 3.18 | F6: 11.66 | G6: 0 | H6: =SUM(F6:G6) -> 11.66 | I6: =SUM(B6:G6) -> 14.84
A7: Value Added | B7: =I3-B8 -> 11.66 | C7: =I4-C8 -> 1.64 | D7: =I5-D8 -> 1.65 | E7: =I6-E8 -> 3.18 | F7: =SUM(B7:E7) -> 18.13 | G7: GDP
A8: Sum Inter Industry Input | B8: =SUM(B2:B6) -> 4.24 | C8: =SUM(C2:C6) -> 5.3 | D8: =SUM(D2:D6) -> 11.66 | E8: =SUM(E2:E6) -> 11.66
A9: X_Total_Industry_Input | B9: =SUM(B3:B7) -> 15.9 | C9: =SUM(C3:C7) -> 6.94 | D9: =SUM(D3:D7) -> 13.31 | E9: =SUM(E3:E7) -> 14.84
B10: Environmental Multiplyers
A11: Mass Multiplyer [$/kg] | B11: 0.7 | C11: 3 | D11: 5 | E11: 16
A12: GHG Multiplyer [CO2e kg /kg] | B12: 0.3 | C12: 0.2 | D12: 19 | E12: 1
A13: Land Use Multiplyer [m^2*year/kg] | B13: 0.9 | C13: 2.6 | D13: 35 | E13: 57
B14: Environmental Extensions (scope 1) - M Matrix
A15: Mass [Mio t] | B15: =B9/B11 -> 22.714286 | C15: =C9/C11 -> 2.3133333 | D15: =D9/D11 -> 2.662 | E15: =E9/E11 -> 0.9275
A16: GHG Emmisons [Mio t] | B16: =B15*B12 -> 6.8142857 | C16: =C15*C12 -> 0.46266667 | D16: =D15*D12 -> 50.578 | E16: =E15*E12 -> 0.9275
A17: Land Use [Mio m^2*year] | B17: =B15*B13 -> 20.442857 | C17: =C15*C13 -> 6.0146667 | D17: =D15*D13 -> 93.17 | E17: =E15*E13 -> 52.8675
B18: Soy Agriculture | C18: Tofu Production | D18: Cow Farming | E18: Beef Processing
B22: 1/x hat Matrix [1/ Mio $]
B23: =1/I3 -> 0.062893082 | C23: 0 | D23: 0 | E23: 0
B24: 0 | C24: =1/I4 -> 0.14409222 | D24: 0 | E24: 0
B25: 0 | C25: 0 | D25: =1/I5 -> 0.07513148 | E25: 0
B26: 0 | C26: 0 | D26: 0 | E26: =1/I6 -> 0.067385445
B27: Technical Coeficient Matrix A [no dim]
B28: {=MMULT(B3:E6, B23:E26)} -> 0.2 | C28: 0.61095101 | D28: 0.63711495 | E28: 0
B29: 0 | C29: 0.15273775 | D29: 0.079639369 | E29: 0.071428571
B30: 0.066666667 | C30: 0 | D30: 0.15927874 | E30: 0.5
B31: 0 | C31: 0 | D31: 0 | E31: 0.21428571
B32: Leonthief Inverse Matrix L [no dim]
B33: {=MINVERSE(G42:J45)} -> 1.3424172 | C33: 0.96800151 | D33: 1.1090062 | E33: 0.79373135
B34: 0.010005854 | C34: 1.1874872 | D34: 0.12007025 | E34: 0.18436172
B35: 0.10644964 | C35: 0.076759607 | D35: 1.2773957 | E35: 0.81986633
B36: 0 | C36: 0 | D36: 0 | E36: 1.2727273 | G36: Identity Matrix 1
B37: Environmental Coeficient Matrix F [mio (t,t,m^2)/ mio $] | G37: 1 | H37: 0 | I37: 0 | J37: 0
A38: Mass [Mio t/ mio $] | B38: {=MMULT(B15:E17, B23:E26)} -> 1.4285714 | C38: 0.33333333 | D38: 0.2 | E38: 0.0625 | G38: 0 | H38: 1 | I38: 0 | J38: 0
A39: GHG Emmisons [Mio t/ mio$] | B39: 0.42857143 | C39: 0.066666667 | D39: 3.8 | E39: 0.0625 | G39: 0 | H39: 0 | I39: 1 | J39: 0
A40: Land Use [Mio m^2*year/ mio$] | B40: 1.2857143 | C40: 0.86666667 | D40: 7 | E40: 3.5625 | G40: 0 | H40: 0 | I40: 0 | J40: 1
B41: Environmental Footprint (F*L*y-hat) | G41: 1-A
A42: Mass [Mio t] | B42: {=MMULT(MMULT(B38:E40, B33:E36),G47:J50)} -> 0 | C42: 6.7455915 | D42: 5.0942502 | E42: 16.777277 | G42: =G37-B28 -> 0.8 | H42: =H37-C28 -> -0.61095101 | I42: =I37-D28 -> -0.63711495 | J42: =J37-E28 -> 0
A43: GHG Emmisons [Mio t] | B43: 0 | C43: 2.95427 | D43: 14.464345 | E43: 41.363837 | G43: =G38-B29 -> 0 | H43: =H38-C29 -> 0.84726225 | I43: =I38-D29 -> -0.079639369 | J43: =J38-E29 -> -0.071428571
...

Sheet 1993
B1: Input-Output Table
A2: 1993 [Mio $] | B2: Soy Agriculture | C2: Tofu Production | D2: Cow Farming | E2: Beef Processing | F2: Y_Houshold | G2: Y_Government | H2: Y_Total_Demand | I2: X_Total Output
A3: Soy Agriculture | B3: 3.27 | C3: 4.36 | D3: 8.72 | E3: 0 | F3: 0 | G3: 0 | H3: =SUM(F3:G3) -> 0 | I3: =SUM(B3:G3) -> 16.35
A4: Tofu Production | B4: 0 | C4: 1.09 | D4: 1.09 | E4: 1.09 | F4: 4.03 | G4: 0 | H4: =SUM(F4:G4) -> 4.03 | I4: =SUM(B4:G4) -> 7.3
A5: Cow Farming | B5: 1.09 | C5: 0 | D5: 2.18 | E5: 7.63 | F5: 0 | G5: 3.05 | H5: =SUM(F5:G5) -> 3.05 | I5: =SUM(B5:G5) -> 13.95
A6: Beef Processing | B6: 0 | C6: 0 | D6: 0 | E6: 3.27 | F6: 11.99 | G6: 0 | H6: =SUM(F6:G6) -> 11.99 | I6: =SUM(B6:G6) -> 15.26
A7: Value Added | B7: =I3-B8 -> 11.99 | C7: =I4-C8 -> 1.85 | D7: =I5-D8 -> 1.96 | E7: =I6-E8 -> 3.27 | F7: =SUM(B7:E7) -> 19.07 | G7: GDP
A8: Sum Inter Industry Input | B8: =SUM(B2:B6) -> 4.36 | C8: =SUM(C2:C6) -> 5.45 | D8: =SUM(D2:D6) -> 11.99 | E8: =SUM(E2:E6) -> 11.99
A9: X_Total_Industry_Input | B9: =SUM(B3:B7) -> 16.35 | C9: =SUM(C3:C7) -> 7.3 | D9: =SUM(D3:D7) -> 13.95 | E9: =SUM(E3:E7) -> 15.26
B10: Environmental Multiplyers
A11: Mass Multiplyer [$/kg] | B11: 0.7 | C11: 3 | D11: 5 | E11: 16
A12: GHG Multiplyer [CO2e kg /kg] | B12: 0.3 | C12: 0.2 | D12: 19 | E12: 1
A13: Land Use Multiplyer [m^2*year/kg] | B13: 0.9 | C13: 2.6 | D13: 35 | E13: 57
B14: Environmental Extensions (scope 1) - M Matrix
A15: Mass [Mio t] | B15: =B9/B11 -> 23.357143 | C15: =C9/C11 -> 2.4333333 | D15: =D9/D11 -> 2.79 | E15: =E9/E11 -> 0.95375
A16: GHG Emmisons [Mio t] | B16: =B15*B12 -> 7.0071429 | C16: =C15*C12 -> 0.48666667 | D16: =D15*D12 -> 53.01 | E16: =E15*E12 -> 0.95375
A17: Land Use [Mio m^2*year] | B17: =B15*B13 -> 21.021429 | C17: =C15*C13 -> 6.3266667 | D17: =D15*D13 -> 97.65 | E17: =E15*E13 -> 54.36375
B18: Soy Agriculture | C18: Tofu Production | D18: Cow Farming | E18: Beef Processing
B22: 1/x hat Matrix [1/ Mio $]
B23: =1/I3 -> 0.06116208 | C23: 0 | D23: 0 | E23: 0
B24: 0 | C24: =1/I4 -> 0.1369863 | D24: 0 | E24: 0
B25: 0 | C25: 0 | D25: =1/I5 -> 0.071684588 | E25: 0
B26: 0 | C26: 0 | D26: 0 | E26: =1/I6 -> 0.065530799
B27: Technical Coeficient Matrix A [no dim]
B28: {=MMULT(B3:E6, B23:E26)} -> 0.2 | C28: 0.59726027 | D28: 0.62508961 | E28: 0
B29: 0 | C29: 0.14931507 | D29: 0.078136201 | E29: 0.071428571
B30: 0.066666667 | C30: 0 | D30: 0.1562724 | E30: 0.5
B31: 0 | C31: 0 | D31: 0 | E31: 0.21428571
B32: Leonthief Inverse Matrix L [no dim]
B33: {=MINVERSE(G42:J45)} -> 1.33999 | C33: 0.94079811 | D33: 1.0798796 | E33: 0.77272318
B34: 0.0097250441 | C34: 1.1823512 | D34: 0.11670053 | E34: 0.18175045
B35: 0.10587856 | C35: 0.074336639 | D35: 1.2705427 | E35: 0.81528507
B36: 0 | C36: 0 | D36: 0 | E36: 1.2727273 | G36: Identity Matrix 1
B37: Environmental Coeficient Matrix F [mio (t,t,m^2)/ mio $] | G37: 1 | H37: 0 | I37: 0 | J37: 0
A38: Mass [Mio t/ mio $] | B38: {=MMULT(B15:E17, B23:E26)} -> 1.4285714 | C38: 0.33333333 | D38: 0.2 | E38: 0.0625 | G38: 0 | H38: 1 | I38: 0 | J38: 0
A39: GHG Emmisons [Mio t/ mio$] | B39: 0.42857143 | C39: 0.066666667 | D39: 3.8 | E39: 0.0625 | G39: 0 | H39: 0 | I39: 1 | J39: 0
A40: Land Use [Mio m^2*year/ mio$] | B40: 1.2857143 | C40: 0.86666667 | D40: 7 | E40: 3.5625 | G40: 0 | H40: 0 | I40: 0 | J40: 1
B41: Environmental Footprint (F*L*y-hat) | G41: 1-A
A42: Mass [Mio t] | B42: {=MMULT(MMULT(B38:E40, B33:E36),G47:J50)} -> 0 | C42: 7.0645163 | D42: 5.5988661 | E42: 16.870844 | G42: =G37-B28 -> 0.8 | H42: =H37-C28 -> -0.59726027 | I42: =I37-D28 -> -0.62508961 | J42: =J37-E28 -> 0
A43: GHG Emmisons [Mio t] | B43: 0 | C43: 3.0809424 | D43: 16.160876 | E43: 42.215741 | G43: =G38-B29 -> 0 | H43: =H38-C29 -> 0.85068493 | I43: =I38-D29 -> -0.078136201 | J43: =J38-E29 -> -0.071428571
...

Sheet 1994
B1: Input-Output Table
A2: 1994 [Mio $] | B2: Soy Agriculture | C2: Tofu Production | D2: Cow Farming | E2: Beef Processing | F2: Y_Houshold | G2: Y_Government | H2: Y_Total_Demand | I2: X_Total Output
A3: Soy Agriculture | B3: 3.42 | C3: 4.56 | D3: 9.12 | E3: 0 | F3: 0 | G3: 0 | H3: =SUM(F3:G3) -> 0 | I3: =SUM(B3:G3) -> 17.1
A4: Tofu Production | B4: 0 | C4: 1.14 | D4: 1.14 | E4: 1.14 | F4: 4.56 | G4: 0 | H4: =SUM(F4:G4) -> 4.56 | I4: =SUM(B4:G4) -> 7.98
A5: Cow Farming | B5: 1.14 | C5: 0 | D5: 2.28 | E5: 7.98 | F5: 0 | G5: 3.33 | H5: =SUM(F5:G5) -> 3.33 | I5: =SUM(B5:G5) -> 14.73
A6: Beef Processing | B6: 0 | C6: 0 | D6: 0 | E6: 3.42 | F6: 12.54 | G6: 0 | H6: =SUM(F6:G6) -> 12.54 | I6: =SUM(B6:G6) -> 15.96
A7: Value Added | B7: =I3-B8 -> 12.54 | C7: =I4-C8 -> 2.28 | D7: =I5-D8 -> 2.19 | E7: =I6-E8 -> 3.42 | F7: =SUM(B7:E7) -> 20.43 | G7: GDP
A8: Sum Inter Industry Input | B8: =SUM(B2:B6) -> 4.56 | C8: =SUM(C2:C6) -> 5.7 | D8: =SUM(D2:D6) -> 12.54 | E8: =SUM(E2:E6) -> 12.54
A9: X_Total_Industry_Input | B9: =SUM(B3:B7) -> 17.1 | C9: =SUM(C3:C7) -> 7.98 | D9: =SUM(D3:D7) -> 14.73 | E9: =SUM(E3:E7) -> 15.96
B10: Environmental Multiplyers
A11: Mass Multiplyer [$/kg] | B11: 0.7 | C11: 3 | D11: 5 | E11: 16
A12: GHG Multiplyer [CO2e kg /kg] | B12: 0.3 | C12: 0.2 | D12: 19 | E12: 1
A13: Land Use Multiplyer [m^2*year/kg] | B13: 0.9 | C13: 2.6 | D13: 35 | E13: 57
B14: Environmental Extensions (scope 1) - M Matrix
A15: Mass [Mio t] | B15: =B9/B11 -> 24.428571 | C15: =C9/C11 -> 2.66 | D15: =D9/D11 -> 2.946 | E15: =E9/E11 -> 0.9975
A16: GHG Emmisons [Mio t] | B16: =B15*B12 -> 7.3285714 | C16: =C15*C12 -> 0.532 | D16: =D15*D12 -> 55.974 | E16: =E15*E12 -> 0.9975
A17: Land Use [Mio m^2*year] | B17: =B15*B13 -> 21.985714 | C17: =C15*C13 -> 6.916 | D17: =D15*D13 -> 103.11 | E17: =E15*E13 -> 56.8575
B18: Soy Agriculture | C18: Tofu Production | D18: Cow Farming | E18: Beef Processing
B22: 1/x hat Matrix [1/ Mio $]
B23: =1/I3 -> 0.058479532 | C23: 0 | D23: 0 | E23: 0
B24: 0 | C24: =1/I4 -> 0.12531328 | D24: 0 | E24: 0
B25: 0 | C25: 0 | D25: =1/I5 -> 0.067888663 | E25: 0
B26: 0 | C26: 0 | D26: 0 | E26: =1/I6 -> 0.062656642
B27: Technical Coeficient Matrix A [no dim]
B28: {=MMULT(B3:E6, B23:E26)} -> 0.2 | C28: 0.57142857 | D28: 0.6191446 | E28: 0
B29: 0 | C29: 0.14285714 | D29: 0.077393075 | E29: 0.071428571
B30: 0.066666667 | C30: 0 | D30: 0.15478615 | E30: 0.5
B31: 0 | C31: 0 | D31: 0 | E31: 0.21428571
B32: Leonthief Inverse Matrix L [no dim]
B33: {=MINVERSE(G42:J45)} -> 1.3385178 | C33: 0.89234518 | D33: 1.0622133 | E33: 0.75707621
B34: 0.0095326835 | C34: 1.1730218 | D34: 0.1143922 | E34: 0.17943338
B35: 0.10557626 | C35: 0.070384174 | D35: 1.2669151 | E35: 0.81261729
B36: 0 | C36: 0 | D36: 0 | E36: 1.2727273 | G36: Identity Matrix 1
B37: Environmental Coeficient Matrix F [mio (t,t,m^2)/ mio $] | G37: 1 | H37: 0 | I37: 0 | J37: 0
A38: Mass [Mio t/ mio $] | B38: {=MMULT(B15:E17, B23:E26)} -> 1.4285714 | C38: 0.33333333 | D38: 0.2 | E38: 0.0625 | G38: 0 | H38: 1 | I38: 0 | J38: 0
A39: GHG Emmisons [Mio t/ mio$] | B39: 0.42857143 | C39: 0.066666667 | D39: 3.8 | E39: 0.0625 | G39: 0 | H39: 0 | I39: 1 | J39: 0
A40: Land Use [Mio m^2*year/ mio$] | B40: 1.2857143 | C40: 0.86666667 | D40: 7 | E40: 3.5625 | G40: 0 | H40: 0 | I40: 0 | J40: 1
B41: Environmental Footprint (F*L*y-hat) | G41: 1-A
A42: Mass [Mio t] | B42: {=MMULT(MMULT(B38:E40, B33:E36),G47:J50)} -> 0 | C42: 7.660175 | D42: 6.0238413 | E42: 17.348055 | G42: =G37-B28 -> 0.8 | H42: =H37-C28 -> -0.57142857 | I42: =I37-D28 -> -0.6191446 | J42: =J37-E28 -> 0
A43: GHG Emmisons [Mio t] | B43: 0 | C43: 3.320113 | D43: 17.572869 | E43: 43.939089 | G43: =G38-B29 -> 0 | H43: =H38-C29 -> 0.85714286 | I43: =I38-D29 -> -0.077393075 | J43: =J38-E29 -> -0.071428571
...

Sheet 1995
B1: Input-Output Table
A2: 1995 [Mio $] | B2: Soy Agriculture | C2: Tofu Production | D2: Cow Farming | E2: Beef Processing | F2: Y_Houshold | G2: Y_Government | H2: Y_Total_Demand | I2: X_Total Output
A3: Soy Agriculture | B3: 3.6 | C3: 4.8 | D3: 9.6 | E3: 0 | F3: 0 | G3: 0 | H3: =SUM(F3:G3) -> 0 | I3: =SUM(B3:G3) -> 18
A4: Tofu Production | B4: 0 | C4: 1.2 | D4: 1.2 | E4: 1.2 | F4: 4.98 | G4: 0 | H4: =SUM(F4:G4) -> 4.98 | I4: =SUM(B4:G4) -> 8.58
A5: Cow Farming | B5: 1.2 | C5: 0 | D5: 2.4 | E5: 8.4 | F5: 0 | G5: 3.69 | H5: =SUM(F5:G5) -> 3.69 | I5: =SUM(B5:G5) -> 15.69
A6: Beef Processing | B6: 0 | C6: 0 | D6: 0 | E6: 3.6 | F6: 13.2 | G6: 0 | H6: =SUM(F6:G6) -> 13.2 | I6: =SUM(B6:G6) -> 16.8
A7: Value Added | B7: =I3-B8 -> 13.2 | C7: =I4-C8 -> 2.58 | D7: =I5-D8 -> 2.49 | E7: =I6-E8 -> 3.6 | F7: =SUM(B7:E7) -> 21.87 | G7: GDP
A8: Sum Inter Industry Input | B8: =SUM(B2:B6) -> 4.8 | C8: =SUM(C2:C6) -> 6 | D8: =SUM(D2:D6) -> 13.2 | E8: =SUM(E2:E6) -> 13.2
A9: X_Total_Industry_Input | B9: =SUM(B3:B7) -> 18 | C9: =SUM(C3:C7) -> 8.58 | D9: =SUM(D3:D7) -> 15.69 | E9: =SUM(E3:E7) -> 16.8
B10: Environmental Multiplyers
A11: Mass Multiplyer [$/kg] | B11: 0.7 | C11: 3 | D11: 5 | E11: 16
A12: GHG Multiplyer [CO2e kg /kg] | B12: 0.3 | C12: 0.2 | D12: 19 | E12: 1
A13: Land Use Multiplyer [m^2*year/kg] | B13: 0.9 | C13: 2.6 | D13: 35 | E13: 57
B14: Environmental Extensions (scope 1) - M Matrix
A15: Mass [Mio t] | B15: =B9/B11 -> 25.714286 | C15: =C9/C11 -> 2.86 | D15: =D9/D11 -> 3.138 | E15: =E9/E11 -> 1.05
A16: GHG Emmisons [Mio t] | B16: =B15*B12 -> 7.7142857 | C16: =C15*C12 -> 0.572 | D16: =D15*D12 -> 59.622 | E16: =E15*E12 -> 1.05
A17: Land Use [Mio m^2*year] | B17: =B15*B13 -> 23.142857 | C17: =C15*C13 -> 7.436 | D17: =D15*D13 -> 109.83 | E17: =E15*E13 -> 59.85
B18: Soy Agriculture | C18: Tofu Production | D18: Cow Farming | E18: Beef Processing
B22: 1/x hat Matrix [1/ Mio $]
B23: =1/I3 -> 0.055555556 | C23: 0 | D23: 0 | E23: 0
B24: 0 | C24: =1/I4 -> 0.11655012 | D24: 0 | E24: 0
B25: 0 | C25: 0 | D25: =1/I5 -> 0.063734863 | E25: 0
B26: 0 | C26: 0 | D26: 0 | E26: =1/I6 -> 0.05952381
B27: Technical Coeficient Matrix A [no dim]
B28: {=MMULT(B3:E6, B23:E26)} -> 0.2 | C28: 0.55944056 | D28: 0.61185468 | E28: 0
B29: 0 | C29: 0.13986014 | D29: 0.076481836 | E29: 0.071428571
B30: 0.066666667 | C30: 0 | D30: 0.15296367 | E30: 0.5
B31: 0 | C31: 0 | D31: 0 | E31: 0.21428571
B32: Leonthief Inverse Matrix L [no dim]
B33: {=MINVERSE(G42:J45)} -> 1.3370265 | C33: 0.86961074 | D33: 1.0443181 | E33: 0.74362158
B34: 0.0093569853 | C34: 1.1686875 | D34: 0.11228382 | E34: 0.17769766
B35: 0.10523173 | C35: 0.068443403 | D35: 1.2627808 | E35: 0.8098099
B36: 0 | C36: 0 | D36: 0 | E36: 1.2727273 | G36: Identity Matrix 1
B37: Environmental Coeficient Matrix F [mio (t,t,m^2)/ mio $] | G37: 1 | H37: 0 | I37: 0 | J37: 0
A38: Mass [Mio t/ mio $] | B38: {=MMULT(B15:E17, B23:E26)} -> 1.4285714 | C38: 0.33333333 | D38: 0.2 | E38: 0.0625 | G38: 0 | H38: 1 | I38: 0 | J38: 0
A39: GHG Emmisons [Mio t/ mio$] | B39: 0.42857143 | C39: 0.066666667 | D39: 3.8 | E39: 0.0625 | G39: 0 | H39: 0 | I39: 1 | J39: 0
A40: Land Use [Mio m^2*year/ mio$] | B40: 1.2857143 | C40: 0.86666667 | D40: 7 | E40: 3.5625 | G40: 0 | H40: 0 | I40: 0 | J40: 1
B41: Environmental Footprint (F*L*y-hat) | G41: 1-A
A42: Mass [Mio t] | B42: {=MMULT(MMULT(B38:E40, B33:E36),G47:J50)} -> 0 | C42: 8.1948501 | D42: 6.5750895 | E42: 17.992346 | G42: =G37-B28 -> 0.8 | H42: =H37-C28 -> -0.55944056 | I42: =I37-D28 -> -0.61185468 | J42: =J37-E28 -> 0
A43: GHG Emmisons [Mio t] | B43: 0 | C43: 3.539225 | D43: 19.385849 | E43: 46.033212 | G43: =G38-B29 -> 0 | H43: =H38-C29 -> 0.86013986 | I43: =I38-D29 -> -0.076481836 | J43: =J38-E29 -> -0.071428571
...

Sheet 1996
B1: Input-Output Table
A2: 1996 [Mio $] | B2: Soy Agriculture | C2: Tofu Production | D2: Cow Farming | E2: Beef Processing | F2: Y_Houshold | G2: Y_Government | H2: Y_Total_Demand | I2: X_Total Output
A3: Soy Agriculture | B3: 3.81 | C3: 5.08 | D3: 10.16 | E3: 0 | F3: 0 | G3: 0 | H3: =SUM(F3:G3) -> 0 | I3: =SUM(B3:G3) -> 19.05
A4: Tofu Production | B4: 0 | C4: 1.27 | D4: 1.27 | E4: 1.27 | F4: 5.23 | G4: 0 | H4: =SUM(F4:G4) -> 5.23 | I4: =SUM(B4:G4) -> 9.04
A5: Cow Farming | B5: 1.27 | C5: 0 | D5: 2.54 | E5: 8.89 | F5: 0 | G5: 4.02 | H5: =SUM(F5:G5) -> 4.02 | I5: =SUM(B5:G5) -> 16.72
A6: Beef Processing | B6: 0 | C6: 0 | D6: 0 | E6: 3.81 | F6: 13.97 | G6: 0 | H6: =SUM(F6:G6) -> 13.97 | I6: =SUM(B6:G6) -> 17.78
A7: Value Added | B7: =I3-B8 -> 13.97 | C7: =I4-C8 -> 2.69 | D7: =I5-D8 -> 2.75 | E7: =I6-E8 -> 3.81 | F7: =SUM(B7:E7) -> 23.22 | G7: GDP
A8: Sum Inter Industry Input | B8: =SUM(B2:B6) -> 5.08 | C8: =SUM(C2:C6) -> 6.35 | D8: =SUM(D2:D6) -> 13.97 | E8: =SUM(E2:E6) -> 13.97
A9: X_Total_Industry_Input | B9: =SUM(B3:B7) -> 19.05 | C9: =SUM(C3:C7) -> 9.04 | D9: =SUM(D3:D7) -> 16.72 | E9: =SUM(E3:E7) -> 17.78
B10: Environmental Multiplyers
A11: Mass Multiplyer [$/kg] | B11: 0.7 | C11: 3 | D11: 5 | E11: 16
A12: GHG Multiplyer [CO2e kg /kg] | B12: 0.3 | C12: 0.2 | D12: 19 | E12: 1
A13: Land Use Multiplyer [m^2*year/kg] | B13: 0.9 | C13: 2.6 | D13: 35 | E13: 57
B14: Environmental Extensions (scope 1) - M Matrix
A15: Mass [Mio t] | B15: =B9/B11 -> 27.214286 | C15: =C9/C11 -> 3.0133333 | D15: =D9/D11 -> 3.344 | E15: =E9/E11 -> 1.11125
A16: GHG Emmisons [Mio t] | B16: =B15*B12 -> 8.1642857 | C16: =C15*C12 -> 0.60266667 | D16: =D15*D12 -> 63.536 | E16: =E15*E12 -> 1.11125
A17: Land Use [Mio m^2*year] | B17: =B15*B13 -> 24.492857 | C17: =C15*C13 -> 7.8346667 | D17: =D15*D13 -> 117.04 | E17: =E15*E13 -> 63.34125
B18: Soy Agriculture | C18: Tofu Production | D18: Cow Farming | E18: Beef Processing
B22: 1/x hat Matrix [1/ Mio $]
B23: =1/I3 -> 0.052493438 | C23: 0 | D23: 0 | E23: 0
B24: 0 | C24: =1/I4 -> 0.11061947 | D24: 0 | E24: 0
B25: 0 | C25: 0 | D25: =1/I5 -> 0.059808612 | E25: 0
B26: 0 | C26: 0 | D26: 0 | E26: =1/I6 -> 0.05624297
B27: Technical Coeficient Matrix A [no dim]
B28: {=MMULT(B3:E6, B23:E26)} -> 0.2 | C28: 0.5619469 | D28: 0.6076555 | E28: 0
B29: 0 | C29: 0.14048673 | D29: 0.075956938 | E29: 0.071428571
B30: 0.066666667 | C30: 0 | D30: 0.15191388 | E30: 0.5
B31: 0 | C31: 0 | D31: 0 | E31: 0.21428571
B32: Leonthief Inverse Matrix L [no dim]
B33: {=MINVERSE(G42:J45)} -> 1.3363098 | C33: 0.87367487 | D33: 1.0357175 | E33: 0.73851796
B34: 0.0092830522 | C34: 1.1695184 | D34: 0.11139663 | E34: 0.17720862
B35: 0.10504513 | C35: 0.068678156 | D35: 1.2605416 | E35: 0.8084063
B36: 0 | C36: 0 | D36: 0 | E36: 1.2727273 | G36: Identity Matrix 1
B37: Environmental Coeficient Matrix F [mio (t,t,m^2)/ mio $] | G37: 1 | H37: 0 | I37: 0 | J37: 0
A38: Mass [Mio t/ mio $] | B38: {=MMULT(B15:E17, B23:E26)} -> 1.4285714 | C38: 0.33333333 | D38: 0.2 | E38: 0.0625 | G38: 0 | H38: 1 | I38: 0 | J38: 0
A39: GHG Emmisons [Mio t/ mio$] | B39: 0.42857143 | C39: 0.066666667 | D39: 3.8 | E39: 0.0625 | G39: 0 | H39: 0 | I39: 1 | J39: 0
A40: Land Use [Mio m^2*year/ mio$] | B40: 1.2857143 | C40: 0.86666667 | D40: 7 | E40: 3.5625 | G40: 0 | H40: 0 | I40: 0 | J40: 1
B41: Environmental Footprint (F*L*y-hat) | G41: 1-A
A42: Mass [Mio t] | B42: {=MMULT(MMULT(B38:E40, B33:E36),G47:J50)} -> 0 | C42: 8.6382971 | D42: 7.1107247 | E42: 18.933847 | G42: =G37-B28 -> 0.8 | H42: =H37-C28 -> -0.5619469 | I42: =I37-D28 -> -0.6076555 | J42: =J37-E28 -> 0
A43: GHG Emmisons [Mio t] | B43: 0 | C43: 3.7309616 | D43: 21.070281 | E43: 48.61296 | G43: =G38-B29 -> 0 | H43: =H38-C29 -> 0.85951327 | I43: =I38-D29 -> -0.075956938 | J43: =J38-E29 -> -0.071428571
...

Sheet 1997
B1: Input-Output Table
A2: 1997 [Mio $] | B2: Soy Agriculture | C2: Tofu Production | D2: Cow Farming | E2: Beef Processing | F2: Y_Houshold | G2: Y_Government | H2: Y_Total_Demand | I2: X_Total Output
A3: Soy Agriculture | B3: 4.05 | C3: 5.4 | D3: 10.8 | E3: 0 | F3: 0 | G3: 0 | H3: =SUM(F3:G3) -> 0 | I3: =SUM(B3:G3) -> 20.25
A4: Tofu Production | B4: 0 | C4: 1.35 | D4: 1.35 | E4: 1.35 | F4: 5.88 | G4: 0 | H4: =SUM(F4:G4) -> 5.88 | I4: =SUM(B4:G4) -> 9.93
A5: Cow Farming | B5: 1.35 | C5: 0 | D5: 2.7 | E5: 9.45 | F5: 0 | G5: 4.44 | H5: =SUM(F5:G5) -> 4.44 | I5: =SUM(B5:G5) -> 17.94
A6: Beef Processing | B6: 0 | C6: 0 | D6: 0 | E6: 4.05 | F6: 14.85 | G6: 0 | H6: =SUM(F6:G6) -> 14.85 | I6: =SUM(B6:G6) -> 18.9
A7: Value Added | B7: =I3-B8 -> 14.85 | C7: =I4-C8 -> 3.18 | D7: =I5-D8 -> 3.09 | E7: =I6-E8 -> 4.05 | F7: =SUM(B7:E7) -> 25.17 | G7: GDP
A8: Sum Inter Industry Input | B8: =SUM(B2:B6) -> 5.4 | C8: =SUM(C2:C6) -> 6.75 | D8: =SUM(D2:D6) -> 14.85 | E8: =SUM(E2:E6) -> 14.85
A9: X_Total_Industry_Input | B9: =SUM(B3:B7) -> 20.25 | C9: =SUM(C3:C7) -> 9.93 | D9: =SUM(D3:D7) -> 17.94 | E9: =SUM(E3:E7) -> 18.9
B10: Environmental Multiplyers
A11: Mass Multiplyer [$/kg] | B11: 0.7 | C11: 3 | D11: 5 | E11: 16
A12: GHG Multiplyer [CO2e kg /kg] | B12: 0.3 | C12: 0.2 | D12: 19 | E12: 1
A13: Land Use Multiplyer [m^2*year/kg] | B13: 0.9 | C13: 2.6 | D13: 35 | E13: 57
B14: Environmental Extensions (scope 1) - M Matrix
A15: Mass [Mio t] | B15: =B9/B11 -> 28.928571 | C15: =C9/C11 -> 3.31 | D15: =D9/D11 -> 3.588 | E15: =E9/E11 -> 1.18125
A16: GHG Emmisons [Mio t] | B16: =B15*B12 -> 8.6785714 | C16: =C15*C12 -> 0.662 | D16: =D15*D12 -> 68.172 | E16: =E15*E12 -> 1.18125
A17: Land Use [Mio m^2*year] | B17: =B15*B13 -> 26.035714 | C17: =C15*C13 -> 8.606 | D17: =D15*D13 -> 125.58 | E17: =E15*E13 -> 67.33125
B18: Soy Agriculture | C18: Tofu Production | D18: Cow Farming | E18: Beef Processing
B22: 1/x hat Matrix [1/ Mio $]
B23: =1/I3 -> 0.049382716 | C23: 0 | D23: 0 | E23: 0
B24: 0 | C24: =1/I4 -> 0.10070493 | D24: 0 | E24: 0
B25: 0 | C25: 0 | D25: =1/I5 -> 0.05574136 | E25: 0
B26: 0 | C26: 0 | D26: 0 | E26: =1/I6 -> 0.052910053
B27: Technical Coeficient Matrix A [no dim]
B28: {=MMULT(B3:E6, B23:E26)} -> 0.2 | C28: 0.54380665 | D28: 0.60200669 | E28: 0
B29: 0 | C29: 0.13595166 | D29: 0.075250836 | E29: 0.071428571
B30: 0.066666667 | C30: 0 | D30: 0.15050167 | E30: 0.5
B31: 0 | C31: 0 | D31: 0 | E31: 0.21428571
B32: Leonthief Inverse Matrix L [no dim]
B33: {=MINVERSE(G42:J45)} -> 1.3350437 | C33: 0.8402373 | D33: 1.0205244 | E33: 0.72580985
B34: 0.0091246242 | C34: 1.1630854 | D34: 0.10949549 | E34: 0.17541399
B35: 0.10477115 | C35: 0.065939882 | D35: 1.2572538 | E35: 0.80606511
B36: 0 | C36: 0 | D36: 0 | E36: 1.2727273 | G36: Identity Matrix 1
B37: Environmental Coeficient Matrix F [mio (t,t,m^2)/ mio $] | G37: 1 | H37: 0 | I37: 0 | J37: 0
A38: Mass [Mio t/ mio $] | B38: {=MMULT(B15:E17, B23:E26)} -> 1.4285714 | C38: 0.33333333 | D38: 0.2 | E38: 0.0625 | G38: 0 | H38: 1 | I38: 0 | J38: 0
A39: GHG Emmisons [Mio t/ mio$] | B39: 0.42857143 | C39: 0.066666667 | D39: 3.8 | E39: 0.0625 | G39: 0 | H39: 0 | I39: 1 | J39: 0
A40: Land Use [Mio m^2*year/ mio$] | B40: 1.2857143 | C40: 0.86666667 | D40: 7 | E40: 3.5625 | G40: 0 | H40: 0 | I40: 0 | J40: 1
B41: Environmental Footprint (F*L*y-hat) | G41: 1-A
A42: Mass [Mio t] | B42: {=MMULT(MMULT(B38:E40, B33:E36),G47:J50)} -> 0 | C42: 9.415186 | D42: 7.7515353 | E42: 19.8411 | G42: =G37-B28 -> 0.8 | H42: =H37-C28 -> -0.54380665 | I42: =I37-D28 -> -0.60200669 | J42: =J37-E28 -> 0
A43: GHG Emmisons [Mio t] | B43: 0 | C43: 4.0466882 | D43: 23.186708 | E43: 51.460425 | G43: =G38-B29 -> 0 | H43: =H38-C29 -> 0.86404834 | I43: =I38-D29 -> -0.075250836 | J43: =J38-E29 -> -0.071428571
...

Sheet 1998
B1: Input-Output Table
A2: 1998 [Mio $] | B2: Soy Agriculture | C2: Tofu Production | D2: Cow Farming | E2: Beef Processing | F2: Y_Houshold | G2: Y_Government | H2: Y_Total_Demand | I2: X_Total Output
A3: Soy Agriculture | B3: 4.29 | C3: 5.72 | D3: 11.44 | E3: 0 | F3: 0 | G3: 0 | H3: =SUM(F3:G3) -> 0 | I3: =SUM(B3:G3) -> 21.45
A4: Tofu Production | B4: 0 | C4: 1.43 | D4: 1.43 | E4: 1.43 | F4: 6.06 | G4: 0 | H4: =SUM(F4:G4) -> 6.06 | I4: =SUM(B4:G4) -> 10.35
A5: Cow Farming | B5: 1.43 | C5: 0 | D5: 2.86 | E5: 10.01 | F5: 0 | G5: 4.93 | H5: =SUM(F5:G5) -> 4.93 | I5: =SUM(B5:G5) -> 19.23
A6: Beef Processing | B6: 0 | C6: 0 | D6: 0 | E6: 4.29 | F6: 15.73 | G6: 0 | H6: =SUM(F6:G6) -> 15.73 | I6: =SUM(B6:G6) -> 20.02
A7: Value Added | B7: =I3-B8 -> 15.73 | C7: =I4-C8 -> 3.2 | D7: =I5-D8 -> 3.5 | E7: =I6-E8 -> 4.29 | F7: =SUM(B7:E7) -> 26.72 | G7: GDP
A8: Sum Inter Industry Input | B8: =SUM(B2:B6) -> 5.72 | C8: =SUM(C2:C6) -> 7.15 | D8: =SUM(D2:D6) -> 15.73 | E8: =SUM(E2:E6) -> 15.73
A9: X_Total_Industry_Input | B9: =SUM(B3:B7) -> 21.45 | C9: =SUM(C3:C7) -> 10.35 | D9: =SUM(D3:D7) -> 19.23 | E9: =SUM(E3:E7) -> 20.02
B10: Environmental Multiplyers
A11: Mass Multiplyer [$/kg] | B11: 0.7 | C11: 3 | D11: 5 | E11: 16
A12: GHG Multiplyer [CO2e kg /kg] | B12: 0.3 | C12: 0.2 | D12: 19 | E12: 1
A13: Land Use Multiplyer [m^2*year/kg] | B13: 0.9 | C13: 2.6 | D13: 35 | E13: 57
B14: Environmental Extensions (scope 1) - M Matrix
A15: Mass [Mio t] | B15: =B9/B11 -> 30.642857 | C15: =C9/C11 -> 3.45 | D15: =D9/D11 -> 3.846 | E15: =E9/E11 -> 1.25125
A16: GHG Emmisons [Mio t] | B16: =B15*B12 -> 9.1928571 | C16: =C15*C12 -> 0.69 | D16: =D15*D12 -> 73.074 | E16: =E15*E12 -> 1.25125
A17: Land Use [Mio m^2*year] | B17: =B15*B13 -> 27.578571 | C17: =C15*C13 -> 8.97 | D17: =D15*D13 -> 134.61 | E17: =E15*E13 -> 71.32125
B18: Soy Agriculture | C18: Tofu Production | D18: Cow Farming | E18: Beef Processing
B22: 1/x hat Matrix [1/ Mio $]
B23: =1/I3 -> 0.046620047 | C23: 0 | D23: 0 | E23: 0
B24: 0 | C24: =1/I4 -> 0.096618357 | D24: 0 | E24: 0
B25: 0 | C25: 0 | D25: =1/I5 -> 0.05200208 | E25: 0
B26: 0 | C26: 0 | D26: 0 | E26: =1/I6 -> 0.04995005
B27: Technical Coeficient Matrix A [no dim]
B28: {=MMULT(B3:E6, B23:E26)} -> 0.2 | C28: 0.552657 | D28: 0.5949038 | E28: 0
B29: 0 | C29: 0.13816425 | D29: 0.074362975 | E29: 0.071428571
B30: 0.066666667 | C30: 0 | D30: 0.14872595 | E30: 0.5
B31: 0 | C31: 0 | D31: 0 | E31: 0.21428571
B32: Leonthief Inverse Matrix L [no dim]
B33: {=MINVERSE(G42:J45)} -> 1.3339091 | C33: 0.85537671 | D33: 1.0069095 | E33: 0.71852213
B34: 0.0090135908 | C34: 1.1660939 | D34: 0.10816309 | E34: 0.1748396
B35: 0.10446374 | C35: 0.066987962 | D35: 1.2535649 | E35: 0.80381296
B36: 0 | C36: 0 | D36: 0 | E36: 1.2727273 | G36: Identity Matrix 1
B37: Environmental Coeficient Matrix F [mio (t,t,m^2)/ mio $] | G37: 1 | H37: 0 | I37: 0 | J37: 0
A38: Mass [Mio t/ mio $] | B38: {=MMULT(B15:E17, B23:E26)} -> 1.4285714 | C38: 0.33333333 | D38: 0.2 | E38: 0.0625 | G38: 0 | H38: 1 | I38: 0 | J38: 0
A39: GHG Emmisons [Mio t/ mio$] | B39: 0.42857143 | C39: 0.066666667 | D39: 3.8 | E39: 0.0625 | G39: 0 | H39: 0 | I39: 1 | J39: 0
A40: Land Use [Mio m^2*year/ mio$] | B40: 1.2857143 | C40: 0.86666667 | D40: 7 | E40: 3.5625 | G40: 0 | H40: 0 | I40: 0 | J40: 1
B41: Environmental Footprint (F*L*y-hat) | G41: 1-A
A42: Mass [Mio t] | B42: {=MMULT(MMULT(B38:E40, B33:E36),G47:J50)} -> 0 | C42: 9.8418175 | D42: 8.5052831 | E42: 20.843007 | G42: =G37-B28 -> 0.8 | H42: =H37-C28 -> -0.552657 | I42: =I37-D28 -> -0.5949038 | J42: =J37-E28 -> 0
A43: GHG Emmisons [Mio t] | B43: 0 | C43: 4.2352362 | D43: 25.647291 | E43: 54.32558 | G43: =G38-B29 -> 0 | H43: =H38-C29 -> 0.86183575 | I43: =I38-D29 -> -0.074362975 | J43: =J38-E29 -> -0.071428571
...

Sheet 1999
B1: Input-Output Table
A2: 1999 [Mio $] | B2: Soy Agriculture | C2: Tofu Production | D2: Cow Farming | E2: Beef Processing | F2: Y_Houshold | G2: Y_Government | H2: Y_Total_Demand | I2: X_Total Output
A3: Soy Agriculture | B3: 4.53 | C3: 6.04 | D3: 12.08 | E3: 0 | F3: 0 | G3: 0 | H3: =SUM(F3:G3) -> 0 | I3: =SUM(B3:G3) -> 22.65
A4: Tofu Production | B4: 0 | C4: 1.51 | D4: 1.51 | E4: 1.51 | F4: 6.95 | G4: 0 | H4: =SUM(F4:G4) -> 6.95 | I4: =SUM(B4:G4) -> 11.48
A5: Cow Farming | B5: 1.51 | C5: 0 | D5: 3.02 | E5: 10.57 | F5: 0 | G5: 5.15 | H5: =SUM(F5:G5) -> 5.15 | I5: =SUM(B5:G5) -> 20.25
A6: Beef Processing | B6: 0 | C6: 0 | D6: 0 | E6: 4.53 | F6: 16.61 | G6: 0 | H6: =SUM(F6:G6) -> 16.61 | I6: =SUM(B6:G6) -> 21.14
A7: Value Added | B7: =I3-B8 -> 16.61 | C7: =I4-C8 -> 3.93 | D7: =I5-D8 -> 3.64 | E7: =I6-E8 -> 4.53 | F7: =SUM(B7:E7) -> 28.71 | G7: GDP
A8: Sum Inter Industry Input | B8: =SUM(B2:B6) -> 6.04 | C8: =SUM(C2:C6) -> 7.55 | D8: =SUM(D2:D6) -> 16.61 | E8: =SUM(E2:E6) -> 16.61
A9: X_Total_Industry_Input | B9: =SUM(B3:B7) -> 22.65 | C9: =SUM(C3:C7) -> 11.48 | D9: =SUM(D3:D7) -> 20.25 | E9: =SUM(E3:E7) -> 21.14
B10: Environmental Multiplyers
A11: Mass Multiplyer [$/kg] | B11: 0.7 | C11: 3 | D11: 5 | E11: 16
A12: GHG Multiplyer [CO2e kg /kg] | B12: 0.3 | C12: 0.2 | D12: 19 | E12: 1
A13: Land Use Multiplyer [m^2*year/kg] | B13: 0.9 | C13: 2.6 | D13: 35 | E13: 57
B14: Environmental Extensions (scope 1) - M Matrix
A15: Mass [Mio t] | B15: =B9/B11 -> 32.357143 | C15: =C9/C11 -> 3.8266667 | D15: =D9/D11 -> 4.05 | E15: =E9/E11 -> 1.32125
A16: GHG Emmisons [Mio t] | B16: =B15*B12 -> 9.7071429 | C16: =C15*C12 -> 0.76533333 | D16: =D15*D12 -> 76.95 | E16: =E15*E12 -> 1.32125
A17: Land Use [Mio m^2*year] | B17: =B15*B13 -> 29.121429 | C17: =C15*C13 -> 9.9493333 | D17: =D15*D13 -> 141.75 | E17: =E15*E13 -> 75.31125
B18: Soy Agriculture | C18: Tofu Production | D18: Cow Farming | E18: Beef Processing
B22: 1/x hat Matrix [1/ Mio $]
B23: =1/I3 -> 0.04415011 | C23: 0 | D23: 0 | E23: 0
B24: 0 | C24: =1/I4 -> 0.087108014 | D24: 0 | E24: 0
B25: 0 | C25: 0 | D25: =1/I5 -> 0.049382716 | E25: 0
B26: 0 | C26: 0 | D26: 0 | E26: =1/I6 -> 0.04730369
B27: Technical Coeficient Matrix A [no dim]
B28: {=MMULT(B3:E6, B23:E26)} -> 0.2 | C28: 0.5261324 | D28: 0.59654321 | E28: 0
B29: 0 | C29: 0.1315331 | D29: 0.074567901 | E29: 0.071428571
B30: 0.066666667 | C30: 0 | D30: 0.1491358 | E30: 0.5
B31: 0 | C31: 0 | D31: 0 | E31: 0.21428571
B32: Leonthief Inverse Matrix L [no dim]
B33: {=MINVERSE(G42:J45)} -> 1.3338307 | C33: 0.80805794 | D33: 1.0059688 | E33: 0.71362179
B34: 0.0089732106 | C34: 1.1568905 | D34: 0.10767853 | E34: 0.17369456
B35: 0.10450792 | C35: 0.063312723 | D35: 1.2540951 | E35: 0.8038162
B36: 0 | C36: 0 | D36: 0 | E36: 1.2727273 | G36: Identity Matrix 1
B37: Environmental Coeficient Matrix F [mio (t,t,m^2)/ mio $] | G37: 1 | H37: 0 | I37: 0 | J37: 0
A38: Mass [Mio t/ mio $] | B38: {=MMULT(B15:E17, B23:E26)} -> 1.4285714 | C38: 0.33333333 | D38: 0.2 | E38: 0.0625 | G38: 0 | H38: 1 | I38: 0 | J38: 0
A39: GHG Emmisons [Mio t/ mio$] | B39: 0.42857143 | C39: 0.066666667 | D39: 3.8 | E39: 0.0625 | G39: 0 | H39: 0 | I39: 1 | J39: 0
A40: Land Use [Mio m^2*year/ mio$] | B40: 1.2857143 | C40: 0.86666667 | D40: 7 | E40: 3.5625 | G40: 0 | H40: 0 | I40: 0 | J40: 1
B41: Environmental Footprint (F*L*y-hat) | G41: 1-A
A42: Mass [Mio t] | B42: {=MMULT(MMULT(B38:E40, B33:E36),G47:J50)} -> 0 | C42: 10.790995 | D42: 8.8776224 | E42: 21.886442 | G42: =G37-B28 -> 0.8 | H42: =H37-C28 -> -0.5261324 | I42: =I37-D28 -> -0.59654321 | J42: =J37-E28 -> 0
A43: GHG Emmisons [Mio t] | B43: 0 | C43: 4.6149732 | D43: 26.799927 | E43: 57.328826 | G43: =G38-B29 -> 0 | H43: =H38-C29 -> 0.8684669 | I43: =I38-D29 -> -0.074567901 | J43: =J38-E29 -> -0.071428571
...

Sheet 2000
B1: Input-Output Table
A2: 2000 [Mio $] | B2: Soy Agriculture | C2: Tofu Production | D2: Cow Farming | E2: Beef Processing | F2: Y_Houshold | G2: Y_Government | H2: Y_Total_Demand | I2: X_Total Output
A3: Soy Agriculture | B3: 4.74 | C3: 6.32 | D3: 12.64 | E3: 0 | F3: 0 | G3: 0 | H3: =SUM(F3:G3) -> 0 | I3: =SUM(B3:G3) -> 23.7
A4: Tofu Production | B4: 0 | C4: 1.58 | D4: 1.58 | E4: 1.58 | F4: 7.88 | G4: 0 | H4: =SUM(F4:G4) -> 7.88 | I4: =SUM(B4:G4) -> 12.62
